Workbook

Sheet Forecast
A2: Loan From BOB | B2: 1500000 | D2: Dharmesh Loan | H2: 80000
D3: Cred | E3: 320000 | H3: 70000
D4: Bajaj | E4: 125000 | H4: 60000
D5: Early Salary | E5: =17800*5 -> 89000
D6: Navi | E6: 280000 | H6: =SUM(H2:H5) -> 210000
D7: Axis | E7: 271000 | F7: Credit card
D8: Axis | E8: 271000 | F8: Credit card
D9: Hdfc | E9: 273000
D10: Citi | E10: 78000
D11: SBI | E11: 69000
D12: SBI | E12: 75000
D13: SBI | E13: 25000
D14: RBL | E14: 20000
E16: =SUM(E3:E15) -> 1896000

Sheet Diwali 2025
A1: Diwali 2025(01-Sept-2025 to 22-Oct-2025)
A2: Income
A3: 01-Sept-25 to 30-Sept-25 | B3: 956793
A4: Oct 2025 Sale | B4: 4652048
A5: Total Sale | B5: =SUM(B3:B4) -> 5608841
A10: Expense
A11: 01-Sept-25 to 30-Sept-25 | B11: 105202
A12: Oct 2025 Cash | B12: 170930
A13: Oct 2025 Online | B13: 365012.56
A14: Gold Loan Closure | B14: 1238266
A15: Gold Loan Closure | B15: 1253049
A16: Sept 2025 Rent | B16: 110000
A17: Oct 2025 Rent | B17: 110000
A18: Sept Mul Bhag | B18: =B3*0.1 -> 95679.3
A19: Oct Mul Bhag | B19: =B4*0.1 -> 465204.8

Sheet EMI
A1: EMI Chart Ocotober 2025 | I1: Income | O1: Daily Payment System
A2: Owner | B2: Type | C2: Bank | D2: EMI Date | E2: Amount | F2: Outstanding | G2: Status | I2: Month | J2: Mulbhag | K2: Profit | L2: Actual | M2: Total | O2: Date | P2: Home | Q2: Mulbhag | R2: Bank | S2: Salary | T2: Vendor
A3: Dharmesh | B3: CC | C3: HDFC CC | D3: 45956 | E3: =F3*0.022 -> 6006 | F3: 273000 | G3: PAID | H3: =SUMIFS(E3:E24,D3:D24,TODAY(),G3:G24,"") -> 0 | I3: 45597 | J3: 74746.2 | K3: 224238.6 | L3: 523223.4 | M3: 747462 | O3: Amount--> | P3: 2000 | Q3: 10000 | R3: 1000 | S3: 2000 | T3: 5000 | U3: =SUM(P3:T3) -> 20000
A4: Dharmesh | B4: CC | C4: Tata Card CC | D4: 45960 | E4: =F4*0.0215 -> 537.5 | F4: 25000 | G4: PAID | I4: 45627 | J4: 81472.1 | K4: 244416.3 | L4: 244416.3 | M4: 814721 | O4: 45942
A5: Vinod | B5: CC | C5: SBI CC | D5: 45962 | E5: =F5*0.025 -> 9375 | F5: 375000 | G5: PAID | I5: 45658 | J5: 65232.5 | K5: 195697.5 | L5: 195697.5 | M5: 652325 | O5: 45943
A6: Yagnesh | B6: CC | C6: RBL | D6: 45963 | E6: 9823 | F6: 200000 | G6: PAID | I6: 45689 | J6: 55399.5 | K6: 166198.5 | L6: 166198.5 | M6: 553995 | O6: 45944
A7: Chetan SIP | B7: CC | C7: IDFC | D7: 45965 | E7: 20000 | F7: 360000 | G7: paid | I7: 45809 | J7: 62522.8 | K7: 187568.4 | L7: 187568.4 | M7: 561037 | O7: 45945
A8: Dharmesh | B8: CC | C8: SBI CC | D8: 45965 | E8: =F8*0.025 -> 1725 | F8: 69000 | G8: PAID | I8: 45748 | J8: =K8/3 -> 54742.7 | K8: 164228.1 | L8: 164228.1 | M8: 547427 | O8: 45946
A9: Dharmesh | B9: CC | C9: Bajaj | D9: 45965 | E9: 18600 | F9: 450000 | G9: paid | M9: =SUM(M3:M8) -> 3876967 | O9: 45947
A10: Arun | B10: EMI | C10: ICICI ML | D10: 45966 | E10: 37000 | F10: 2368000 | G10: paid | O10: 45948
A11: Vinod | B11: CC | C11: HDFC Jumbo | D11: 45966 | E11: =6538+8530 -> 15068 | F11: 250000 | G11: paid | I11: Balance | L11: =TODAY() -> 45983 | O11: 45949
A12: Chetan HDFC | B12: EMI | C12: HDFC | D12: 45967 | E12: 12900 | F12: 750000 | G12: paid | H12: 12900 | I12: BOB | J12: 31170 | O12: 45950
A13: Dharmesh | B13: EMI | C13: HDFC PL | D13: 45967 | E13: 59663 | F13: 2800000 | G13: PAID | I13: Cash | J13: 5000 | O13: 45951
A14: Vinod | B14: CC | C14: HDFC CC | D14: 45967 | E14: =F14*0.0215 -> 14663 | F14: 682000 | G14: PAID | I14: BOB | O14: 45952
A15: Dharmesh | B15: CC | C15: Axis Priveldege | D15: 45968 | E15: =F15*0.025 -> 6143.275 | F15: 245731 | G15: PAID | I15: =L11 -> 45983 | J15: 0 | O15: 45953
A16: Dharmesh | B16: CC | C16: RBL CC | D16: 45968 | E16: 1100 | F16: 17000 | G16: PAID | I16: =$L$11+1 -> 45984 | J16: 20000 | O16: 45954
A17: Yagnesh | B17: CC | C17: HSBC CC | D17: 45968 | E17: 13185 | F17: 217000 | G17: PAID | I17: =$L$11+2 -> 45985 | J17: 20000 | O17: 45955
A18: Yagnesh | B18: CC | C18: HDFC CC | D18: 45970 | E18: 11532 | F18: 205000 | G18: PAID | I18: =$L$11+3 -> 45986 | J18: 20000 | O18: 45956
A19: Arun | B19: Credit card Repayment | C19: ALL CC | D19: 45971 | E19: 70000 | F19: 500000 | G19: PAID | I19: =$L$11+4 -> 45987 | P19: =COUNTA(P4:P18)*P3 -> 0 | Q19: =COUNTA(Q4:Q18)*Q3 -> 0 | R19: =COUNTA(R4:R18)*R3 -> 0 | S19: =COUNTA(S4:S18)*S3 -> 0 | T19: =COUNTA(T4:T18)*T3 -> 0 | U19: =COUNTA(U4:U18)*U3 -> 0
A20: Arun | B20: EMI | C20: ICICI | D20: 45971 | E20: 35000 | F20: 608000 | G20: Paid | I20: =$L$11+5 -> 45988
A21: Dharmesh | B21: CC | C21: SBI CC | D21: 45971 | E21: =F21*0.0218 -> 1635 | F21: 75000 | G21: Paid | I21: =$L$11+6 -> 45989
A22: Dharmesh | B22: CC | C22: Citi -Axis | D22: 45971 | E22: 3891 | F22: 31800 | G22: Paid | I22: =$L$11+7 -> 45990
A23: Dharmesh | B23: CC | C23: Axis MM | D23: 45971 | E23: =F23*0.025 -> 6825 | F23: 273000 | G23: Paid | I23: udhar | J23: =N28 -> 0
A24: Narottam | B24: EMI | C24: Bharat bank | D24: 45971 | E24: 35000 | F24: 3400000 | G24: Paid | I24: Total | J24: =SUM(J12:J23) -> 96170
A25: Yagnesh | B25: CC | C25: AXIS Citi | D25: 45971 | E25: 6500 | F25: 108000 | G25: Paid | I25: EMI | J25: =SUMIF(G3:G24,"",E3:E24) -> 0
A26: Total | E26: =SUM(E3:E25) -> 396171.78 | F26: =SUM(F3:F25) -> 14282531 | I26: Balance | J26: =J24-J25 -> 96170
E27: =SUMIF(G3:G25,"",E3:E25) -> 0 | F27: =400000-E27 -> 400000 | K27: =SUM(K14:K26) -> 0
E28: 133164 | J28: =N32-K27 -> 0
E29: =E27-E28 -> -133164

Sheet Forecast 2025
A1: Vendor Name | B1: Balance Amount | C1: Payment Amount | D1: Balance Amount | E1: Payment Date | F1: Actual Payment | G1: Remarks | H1: Expense | J1: Income | L1: As on 18-05-25 | M1: =TODAY() -> 45983
A2: Raju kaka | B2: 3040 | D2: =B2-C2 -> 3040 | J2: Balance | L2: 45838
A3: Hareshbhai Than | B3: 39900 | D3: =B3-C3 -> 39900 | H3: Vendor Payment | I3: 148000 | J3: Daily Sales(01Nov to 30Nov) | K3: =20000*9 -> 180000 | L3: =L2-M1 -> -145
A4: HP | B4: =3695+2400 -> 6095 | D4: =B4-C4 -> 6095 | H4: Pune | I4: 40000 | J4: Udhar | K4: =I26 -> 920480
A5: Virar | B5: 18060 | D5: =B5-C5 -> 18060 | H5: Sekaran Malaysia | I5: 305000 | J5: HDFC | K5: 14000
A6: BOB Interest | B6: 30000 | C6: 30000 | D6: =B6-C6 -> 0 | H6: Grey Shade | I6: 46480 | J6: Bob | K6: 59000
A7: Ambalal | B7: 27710 | D7: =B7-C7 -> 27710 | H7: Dinner set | I7: 216000 | J7: ICICI
A8: Matala bandhavana | B8: 8000 | C8: 8000 | D8: =B8-C8 -> 0 | H8: Dukan Udhari | I8: =15000+15000+3000 -> 33000 | J8: Cash | K8: 3000
A9: Sajid Bhai | B9: 17680 | D9: =B9-C9 -> 17680 | H9: Fitoor Plate | I9: 100000
A10: Vakeel Saab | B10: 392000 | D10: =B10-C10 -> 392000 | H10: Girish | I10: 32000
A11: Akash Potterywale | B11: =40000+14000 -> 54000 | D11: =B11-C11 -> 54000
A12: Hukumpal | B12: =24580+7510+55500 -> 87590 | C12: 29602 | D12: =B12-C12 -> 57988
A13: Parth | B13: 32496 | D13: =B13-C13 -> 32496
A14: Dasrath | B14: 6000 | D14: =B14-C14 -> 6000
A15: Atul | B15: 125000 | D15: =B15-C15 -> 125000
A16: Silver | B16: 275000 | D16: =B16-C16 -> 275000
A17: tax + fees | B17: 105221 | C17: 105221 | D17: =B17-C17 -> 0
A18: EMI - Nov25 | B18: =EMI!E27 -> 0 | D18: =B18-C18 -> 0
A19: Light Bill | B19: 12000 | C19: 12000 | D19: =B19-C19 -> 0 | K19: =SUM(K2:K13) -> 1176480
A20: Salary | B20: 56000 | C20: 56000 | D20: =B20-C20 -> 0
A21: Rent | B21: 110000 | C21: 110000 | D21: =B21-C21 -> 0
A22: Mul bhag | B22: 100000 | C22: 70000 | D22: =B22-C22 -> 30000
D23: =B23-C23 -> 0
A24: Total | B24: =SUM(B2:B23) -> 1505792 | C24: =SUM(C2:C23) -> 420823 | D24: =B24-C24 -> 1084969
H26: Total | I26: =SUM(I3:I25) -> 920480
H27: Balance | I27: =K19-D24 -> 91511

Sheet Loan 062025
A1: Owner | B1: Type | C1: Bank | D1: EMI Date | E1: Amount | F1: Outstanding | H1: After EMI | J1: Owner | K1: Type | L1: Bank | M1: EMI Date | N1: Amount | O1: Outstanding | P1: Paid | Q1: Remaining OS | S1: Income
A2: Dharmesh | B2: CC | C2: HDFC CC | D2: 45834 | E2: 9985 | F2: 257406 | G2: =F2 -> 257406 | H2: =IF(G2="",E2,0) -> 0 | I2: =IF(G2<>"",E2,0) -> 9985 | J2: Dharmesh | K2: EMI | L2: Early Salary | M2: 45810 | N2: 17247 | O2: 80436 | P2: 80436 | Q2: =O2-P2 -> 0 | S2: Owner | T2: Source | U2: Bank | V2: Amount | W2: Remarks
A3: Dharmesh | B3: CC | C3: Tata Card CC | D3: 45838 | E3: 2500 | F3: 25000 | G3: =F3 -> 25000 | H3: =IF(G3="",E3,0) -> 0 | I3: =IF(G3<>"",E3,0) -> 2500 | J3: Dharmesh | K3: EMI | L3: VIVIF | M3: 45808 | N3: 5700 | O3: 118000 | P3: 118000 | Q3: =O3-P3 -> 0 | S3: Arun | T3: Salary | U3: SBI | V3: 824543 | W3: Account
A4: Vinod | B4: CC | C4: SBI CC | D4: 45839 | E4: =F4*0.025 -> 3069.875 | F4: 122795 | G4: =F4 -> 122795 | H4: =IF(G4="",E4,0) -> 0 | I4: =IF(G4<>"",E4,0) -> 3069.875 | J4: Dharmesh | K4: EMI | L4: Navi | M4: 45811 | N4: 9999 | O4: 278749 | P4: 278749 | Q4: =O4-P4 -> 0 | S4: Arun | T4: Salary | U4: SBI NRO | V4: 69000 | W4: Account
A5: Yagnesh | B5: CC | C5: RBL | D5: 45840 | E5: 9823 | F5: =200000-38000 -> 162000 | G5: =F5 -> 162000 | H5: =IF(G5="",E5,0) -> 0 | I5: =IF(G5<>"",E5,0) -> 9823 | J5: Dharmesh | K5: EMI | L5: Cred | M5: 45810 | N5: 17544 | O5: 278894 | P5: 278894 | Q5: =O5-P5 -> 0 | S5: Dharmesh | T5: Salary | U5: HDFC | V5: 40000 | W5: Account
A6: Dharmesh | B6: EMI | C6: Bajaj | D6: 45840 | E6: 32392 | F6: =E6 -> 32392 | G6: 0 | H6: =IF(G6="",E6,0) -> 0 | I6: =IF(G6<>"",E6,0) -> 32392 | J6: Dharmesh | K6: EMI | L6: Kreditbee | M6: 45812 | N6: 3186 | O6: 24000 | P6: 8000 | Q6: =O6-P6 -> 16000 | S6: Total | V6: =SUM(V3:V5) -> 933543
A7: Dharmesh | B7: CC | C7: SBI CC | D7: 45842 | E7: =F7*0.025 -> 731.75 | F7: 29270 | G7: 69000 | H7: =IF(G7="",E7,0) -> 0 | I7: =IF(G7<>"",E7,0) -> 731.75 | J7: Dharmesh | K7: CC | L7: Tata Card CC | M7: 45807 | N7: 2500 | O7: 20000 | P7: 3000 | Q7: =O7-P7 -> 17000 | S7: LIC | T7: LIC | U7: IOB | V7: 282635 | W7: Addition
A8: Dharmesh | B8: EMI | C8: Kreditbee | D8: 45842 | E8: 3186 | F8: 15000 | G8: 15000 | H8: =IF(G8="",E8,0) -> 0 | I8: =IF(G8<>"",E8,0) -> 3186 | J8: Dharmesh | K8: CC | L8: RBL CC | M8: 45815 | N8: 1300 | O8: 20000 | P8: 3000 | Q8: =O8-P8 -> 17000 | S8: Total | V8: =V6+V7 -> 1216178
A9: Vinod | B9: CC | C9: HDFC CC | D9: 45844 | E9: =F9*0.05 -> 3468.15 | F9: 69363 | G9: 69363 | H9: =IF(G9="",E9,0) -> 0 | I9: =IF(G9<>"",E9,0) -> 3468.15 | J9: Dharmesh | K9: CC | L9: HDFC CC | M9: 45803 | N9: 9985 | O9: 273000 | P9: 253500 | Q9: =O9-P9 -> 19500
A10: Vinod | B10: CC | C10: HDFC Jumbo | D10: 45843 | E10: =6538+8530 -> 15068 | F10: 200000 | H10: =IF(G10="",E10,0) -> 15068 | I10: =IF(G10<>"",E10,0) -> 0 | J10: Dharmesh | K10: EMI | L10: Bajaj | M10: 45810 | N10: 32392 | O10: 32392 | P10: 0 | Q10: =O10-P10 -> 32392 | S10: Expense
A11: Arun | B11: EMI | C11: ICICI ML | D11: 45843 | E11: 37000 | F11: 860000 | H11: =IF(G11="",E11,0) -> 37000 | I11: =IF(G11<>"",E11,0) -> 0 | J11: Dharmesh | K11: CC | L11: Axis Priveldege | M11: 45815 | N11: 6320 | O11: 271000 | P11: 233566 | Q11: =O11-P11 -> 37434 | S11: Owner | U11: Bank | V11: Amount | W11: Remarks | X11: Actual
A12: Dharmesh | B12: EMI | C12: HDFC PL | D12: 45844 | E12: 59663 | F12: 3100000 | H12: =IF(G12="",E12,0) -> 59663 | I12: =IF(G12<>"",E12,0) -> 0 | J12: Dharmesh | K12: CC | L12: SBI CC | M12: 45818 | N12: 6320 | O12: 75000 | P12: 25000 | Q12: =O12-P12 -> 50000 | S12: Dharmesh | U12: HDFC | V12: 700000 | W12: Credit Card Payment | X12: 700000
A13: Rajubhai | B13: EMI | C13: Bharat bank | D13: 45844 | E13: 32500 | F13: 850000 | H13: =IF(G13="",E13,0) -> 32500 | I13: =IF(G13<>"",E13,0) -> 0 | J13: Dharmesh | K13: CC | L13: SBI CC | M13: 45812 | N13: 6320 | O13: 69000 | P13: 6320 | Q13: =O13-P13 -> 62680 | S13: Arun | U13: ICICI | V13: 25000 | W13: Arun Personal | X13: 25000
A14: Yagnesh | B14: CC | C14: HSBC CC | D14: 45847 | E14: 11482 | F14: =389000-166175 -> 222825 | G14: =389000-166175 -> 222825 | H14: =IF(G14="",E14,0) -> 0 | I14: =IF(G14<>"",E14,0) -> 11482 | J14: Dharmesh | K14: CC | L14: Axis Citi | M14: 45819 | N14: 3500 | O14: 78000 | P14: 6000 | Q14: =O14-P14 -> 72000 | S14: Virar Tax | U14: SBI | V14: 20000 | W14: Virar Tax
A15: Dharmesh | B15: CC | C15: Axis Priveldege | D15: 45845 | E15: =F15*0.025 -> 6043.275 | F15: 241731 | G15: 241731 | H15: =IF(G15="",E15,0) -> 0 | I15: =IF(G15<>"",E15,0) -> 6043.275 | J15: Dharmesh | K15: CC | L15: Axis MM | M15: 45822 | N15: 1200 | O15: 271000 | P15: 176336 | Q15: =O15-P15 -> 94664 | S15: Ved Trusha Fees | U15: SBI | V15: 120000 | W15: School Fees
A16: Dharmesh | B16: CC | C16: RBL CC | D16: 45845 | E16: 1100 | F16: 18000 | G16: 18000 | H16: =IF(G16="",E16,0) -> 0 | I16: =IF(G16<>"",E16,0) -> 1100 | J16: Dharmesh | K16: EMI | L16: HDFC PL | M16: 45814 | N16: 59663 | O16: 3100000 | P16: 200000 | Q16: =O16-P16 -> 2900000 | S16: Dharmesh | U16: HDFC | V16: 40000 | W16: SIP
A17: Yagnesh | B17: CC | C17: ICICI CC | D17: 45846 | E17: 12740 | F17: 90000 | G17: 67000 | H17: =IF(G17="",E17,0) -> 0 | I17: =IF(G17<>"",E17,0) -> 12740 | O17: =SUM(O2:O16) -> 4989471 | Q17: =SUM(Q2:Q16) -> 3318670 | S17: Arun | U17: SBI NRO | V17: 9000 | W17: Balance | X17: 59000
A18: Yagnesh | B18: CC | C18: HDFC CC | D18: 45847 | E18: 11532 | F18: 263000 | G18: 263000 | H18: =IF(G18="",E18,0) -> 0 | I18: =IF(G18<>"",E18,0) -> 11532 | S18: Arun | U18: SBI NRO | V18: 19543 | W18: Balance | X18: 19543
A19: Dharmesh | B19: CC | C19: SBI CC | D19: 45848 | E19: =F19*0.0218 -> 1958.294 | F19: 89830 | G19: 89830 | H19: =IF(G19="",E19,0) -> 0 | I19: =IF(G19<>"",E19,0) -> 1958.294 | S19: Total | V19: =SUM(V12:V18) -> 933543
A20: Yagnesh | B20: CC | C20: AXIS Citi | D20: 45848 | E20: 6500 | F20: 110000 | G20: 110000 | H20: =IF(G20="",E20,0) -> 0 | I20: =IF(G20<>"",E20,0) -> 6500 | S20: LIC | T20: LIC | U20: IOB | V20: 282635 | W20: LIC | X20: 200000
A21: Arun | B21: EMI | C21: ICICI | D21: 45848 | E21: 35000 | F21: 1200000 | H21: =IF(G21="",E21,0) -> 35000 | I21: =IF(G21<>"",E21,0) -> 0 | S21: Grand Total | V21: =V19+V20 -> 1216178 | X21: =SUM(X12:X20) -> 1003543 | Y21: =V21-X21 -> 212635
A22: Narottam | B22: EMI | C22: Bharat bank | D22: 45848 | E22: 35000 | F22: 3500000 | H22: =IF(G22="",E22,0) -> 35000 | I22: =IF(G22<>"",E22,0) -> 0
A23: Dharmesh | B23: CC | C23: SBI CC | D23: 45848 | E23: =F23*0.025 -> 795 | F23: 31800 | G23: 75000 | H23: =IF(G23="",E23,0) -> 0 | I23: =IF(G23<>"",E23,0) -> 795
A24: Dharmesh | B24: CC | C24: Citi -Axis | D24: 45848 | E24: 3891 | F24: 31800 | G24: 78000 | H24: =IF(G24="",E24,0) -> 0 | I24: =IF(G24<>"",E24,0) -> 3891
A25: Dharmesh | B25: CC | C25: Axis MM | D25: 45848 | E25: =F25*0.025 -> 6775 | F25: 271000 | G25: 271000 | H25: =IF(G25="",E25,0) -> 0 | I25: =IF(G25<>"",E25,0) -> 6775
A26: Dharmesh New Loan | B26: EMI | C26: HDFC_Axis | D26: 45848 | F26: 2000000
A27: Arun | B27: Credit card Repayment | C27: ALL CC | D27: 45848 | E27: =F27*0.1 -> 70000 | F27: 700000
A28: Total | E28: =SUM(E2:E25) -> 342203.34 | F28: =SUM(F2:F27) -> 14493212 | G28: =SUM(G2:G27) -> 2156950 | H28: =SUM(H2:H27) -> 214231
A29: Dharmesh Loab BT | B29: 1600000 | C29: Credit Card Payment | D29: 630000
A30: LIC Balance | C30: Karande | D30: 50000
A31: SBI Balance | C31: SIP | D31: 40000
C35: Yagnesh CC | D35: 590500
C36: Processing fees | D36: 46865
A38: Total | B38: =SUM(B29:B35) -> 1600000 | D38: =SUM(D29:D36) -> 1357365
A39: Balance | B39: =B38-D38 -> 242635

Sheet November 2024
A1: Date | B1: Actual Profit | C1: Mulbhag | D1: Profit | E1: Actual | F1: Total | G1: Cash | H1: Account Transfer | I1: Expense | J1: Expense Online | K1: Account Balance | L1: cash on hand | M1: Actual Balance | O1: Date | P1: Mul Bhag | Q1: Profit | R1: Actual | S1: Total | T1: Cash | U1: Account Transfer | V1: Expense
A2: Last month Balance | B2: =Table2345345687911121514161718192021222324252627283456789101134567891011126[[#This Row],[Profit]]-Table2345345687911121514161718192021222324252627283456789101134567891011126[[#This Row],[Mulbhag]] -> 0 | C2: =Table2345345687911121514161718192021222324252627283456789101134567891011126[[#This Row],[Profit]]/3 -> 0 | D2: =F2*0.3 -> 0 | E2: =F2-D2 -> 0 | F2: =G2+H2 -> 0 | K2: =Table2345345687911121514161718192021222324252627283456789101134567891011126[[#This Row],[Account Transfer]]-Table2345345687911121514161718192021222324252627283456789101134567891011126[[#This Row],[Expense Online]] -> 0 | L2: =Table2345345687911121514161718192021222324252627283456789101134567891011126[[#This Row],[Cash]]-Table2345345687911121514161718192021222324252627283456789101134567891011126[[#This Row],[Mulbhag]]-Table2345345687911121514161718192021222324252627283456789101134567891011126[[#This Row],[Actual Profit]]-Table2345345687911121514161718192021222324252627283456789101134567891011126[[#This Row],[Expense]] -> 0 | M2: =Table2345345687911121514161718192021222324252627283456789101134567891011126[[#This Row],[Cash]]-Table2345345687911121514161718192021222324252627283456789101134567891011126[[#This Row],[Expense]] -> 0 | O2: Export | V2: 0
A3: 45597 | B3: =Table2345345687911121514161718192021222324252627283456789101134567891011126[[#This Row],[Profit]]-Table2345345687911121514161718192021222324252627283456789101134567891011126[[#This Row],[Mulbhag]] -> 3611 | C3: =Table2345345687911121514161718192021222324252627283456789101134567891011126[[#This Row],[Profit]]/3 -> 1805.5 | D3: =F3*0.3 -> 5416.5 | E3: =F3-D3 -> 12638.5 | F3: =G3+H3 -> 18055 | G3: 7000 | H3: 11055 | I3: 500 | K3: =Table2345345687911121514161718192021222324252627283456789101134567891011126[[#This Row],[Account Transfer]]-Table2345345687911121514161718192021222324252627283456789101134567891011126[[#This Row],[Expense Online]] -> 11055 | L3: =Table2345345687911121514161718192021222324252627283456789101134567891011126[[#This Row],[Cash]]-Table2345345687911121514161718192021222324252627283456789101134567891011126[[#This Row],[Mulbhag]]-Table2345345687911121514161718192021222324252627283456789101134567891011126[[#This Row],[Actual Profit]]-Table2345345687911121514161718192021222324252627283456789101134567891011126[[#This Row],[Expense]] -> 1083.5 | M3: =Table2345345687911121514161718192021222324252627283456789101134567891011126[[#This Row],[Cash]]-Table2345345687911121514161718192021222324252627283456789101134567891011126[[#This Row],[Expense]] -> 6500 | O3: =A3 -> 45597 | P3: =Q3/3 -> 1805.5 | Q3: =S3*0.3 -> 5416.5 | R3: =S3-Q3 -> 12638.5 | S3: =T3+U3 -> 18055 | T3: =VLOOKUP(O3,$A$1:$J$34,7,0) -> 7000 | U3: =VLOOKUP(O3,$A$1:$J$34,8,0) -> 11055 | V3: =VLOOKUP(O3,$A$1:$J$34,9,0) -> 500
A4: 45598 | B4: =Table2345345687911121514161718192021222324252627283456789101134567891011126[[#This Row],[Profit]]-Table2345345687911121514161718192021222324252627283456789101134567891011126[[#This Row],[Mulbhag]] -> 1503.4 | C4: =Table2345345687911121514161718192021222324252627283456789101134567891011126[[#This Row],[Profit]]/3 -> 751.7 | D4: =F4*0.3 -> 2255.1 | E4: =F4-D4 -> 5261.9 | F4: =G4+H4 -> 7517 | G4: 236 | H4: 7281 | I4: 20 | K4: =Table2345345687911121514161718192021222324252627283456789101134567891011126[[#This Row],[Account Transfer]]-Table2345345687911121514161718192021222324252627283456789101134567891011126[[#This Row],[Expense Online]] -> 7281 | L4: =Table2345345687911121514161718192021222324252627283456789101134567891011126[[#This Row],[Cash]]-Table2345345687911121514161718192021222324252627283456789101134567891011126[[#This Row],[Mulbhag]]-Table2345345687911121514161718192021222324252627283456789101134567891011126[[#This Row],[Actual Profit]]-Table2345345687911121514161718192021222324252627283456789101134567891011126[[#This Row],[Expense]]+L3 -> -955.6 | M4: =Table2345345687911121514161718192021222324252627283456789101134567891011126[[#This Row],[Cash]]-Table2345345687911121514161718192021222324252627283456789101134567891011126[[#This Row],[Expense]] -> 216 | O4: =A4 -> 45598 | P4: =Q4/3 -> 751.7 | Q4: =S4*0.3 -> 2255.1 | R4: =S4-Q4 -> 5261.9 | S4: =T4+U4 -> 7517 | T4: =VLOOKUP(O4,$A$1:$J$34,7,0) -> 236 | U4: =VLOOKUP(O4,$A$1:$J$34,8,0) -> 7281 | V4: =VLOOKUP(O4,$A$1:$J$34,9,0) -> 20
A5: 45599 | B5: =Table2345345687911121514161718192021222324252627283456789101134567891011126[[#This Row],[Profit]]-Table2345345687911121514161718192021222324252627283456789101134567891011126[[#This Row],[Mulbhag]] -> 8690 | C5: =Table2345345687911121514161718192021222324252627283456789101134567891011126[[#This Row],[Profit]]/3 -> 4345 | D5: =F5*0.3 -> 13035 | E5: =F5-D5 -> 30415 | F5: =G5+H5 -> 43450 | G5: 30700 | H5: 12750 | I5: 260 | K5: =Table2345345687911121514161718192021222324252627283456789101134567891011126[[#This Row],[Account Transfer]]-Table2345345687911121514161718192021222324252627283456789101134567891011126[[#This Row],[Expense Online]] -> 12750 | L5: =Table2345345687911121514161718192021222324252627283456789101134567891011126[[#This Row],[Cash]]-Table2345345687911121514161718192021222324252627283456789101134567891011126[[#This Row],[Mulbhag]]-Table2345345687911121514161718192021222324252627283456789101134567891011126[[#This Row],[Actual Profit]]-Table2345345687911121514161718192021222324252627283456789101134567891011126[[#This Row],[Expense]] -> 17405 | M5: =Table2345345687911121514161718192021222324252627283456789101134567891011126[[#This Row],[Cash]]-Table2345345687911121514161718192021222324252627283456789101134567891011126[[#This Row],[Expense]] -> 30440 | O5: =A5 -> 45599 | P5: =Q5/3 -> 4345 | Q5: =S5*0.3 -> 13035 | R5: =S5-Q5 -> 30415 | S5: =T5+U5 -> 43450 | T5: =VLOOKUP(O5,$A$1:$J$34,7,0) -> 30700 | U5: =VLOOKUP(O5,$A$1:$J$34,8,0) -> 12750 | V5: =VLOOKUP(O5,$A$1:$J$34,9,0) -> 260
A6: 45600 | B6: =Table2345345687911121514161718192021222324252627283456789101134567891011126[[#This Row],[Profit]]-Table2345345687911121514161718192021222324252627283456789101134567891011126[[#This Row],[Mulbhag]] -> 1310 | C6: =Table2345345687911121514161718192021222324252627283456789101134567891011126[[#This Row],[Profit]]/3 -> 655 | D6: =F6*0.3 -> 1965 | E6: =F6-D6 -> 4585 | F6: =G6+H6 -> 6550 | G6: 4200 | H6: 2350 | I6: 120 | K6: =Table2345345687911121514161718192021222324252627283456789101134567891011126[[#This Row],[Account Transfer]]-Table2345345687911121514161718192021222324252627283456789101134567891011126[[#This Row],[Expense Online]] -> 2350 | L6: =Table2345345687911121514161718192021222324252627283456789101134567891011126[[#This Row],[Cash]]-Table2345345687911121514161718192021222324252627283456789101134567891011126[[#This Row],[Mulbhag]]-Table2345345687911121514161718192021222324252627283456789101134567891011126[[#This Row],[Actual Profit]]-Table2345345687911121514161718192021222324252627283456789101134567891011126[[#This Row],[Expense]] -> 2115 | M6: =Table2345345687911121514161718192021222324252627283456789101134567891011126[[#This Row],[Cash]]-Table2345345687911121514161718192021222324252627283456789101134567891011126[[#This Row],[Expense]] -> 4080 | O6: =A6 -> 45600 | P6: =Q6/3 -> 655 | Q6: =S6*0.3 -> 1965 | R6: =S6-Q6 -> 4585 | S6: =T6+U6 -> 6550 | T6: =VLOOKUP(O6,$A$1:$J$34,7,0) -> 4200 | U6: =VLOOKUP(O6,$A$1:$J$34,8,0) -> 2350 | V6: =VLOOKUP(O6,$A$1:$J$34,9,0) -> 120
A7: 45601 | B7: =Table2345345687911121514161718192021222324252627283456789101134567891011126[[#This Row],[Profit]]-Table2345345687911121514161718192021222324252627283456789101134567891011126[[#This Row],[Mulbhag]] -> 4920 | C7: =Table2345345687911121514161718192021222324252627283456789101134567891011126[[#This Row],[Profit]]/3 -> 2460 | D7: =F7*0.3 -> 7380 | E7: =F7-D7 -> 17220 | F7: =G7+H7 -> 24600 | G7: 10850 | H7: 13750 | I7: 550 | K7: =Table2345345687911121514161718192021222324252627283456789101134567891011126[[#This Row],[Account Transfer]]-Table2345345687911121514161718192021222324252627283456789101134567891011126[[#This Row],[Expense Online]] -> 13750 | L7: =Table2345345687911121514161718192021222324252627283456789101134567891011126[[#This Row],[Cash]]-Table2345345687911121514161718192021222324252627283456789101134567891011126[[#This Row],[Mulbhag]]-Table2345345687911121514161718192021222324252627283456789101134567891011126[[#This Row],[Actual Profit]]-Table2345345687911121514161718192021222324252627283456789101134567891011126[[#This Row],[Expense]] -> 2920 | M7: =Table2345345687911121514161718192021222324252627283456789101134567891011126[[#This Row],[Cash]]-Table2345345687911121514161718192021222324252627283456789101134567891011126[[#This Row],[Expense]] -> 10300 | O7: =A7 -> 45601 | P7: =Q7/3 -> 2460 | Q7: =S7*0.3 -> 7380 | R7: =S7-Q7 -> 17220 | S7: =T7+U7 -> 24600 | T7: =VLOOKUP(O7,$A$1:$J$34,7,0) -> 10850 | U7: =VLOOKUP(O7,$A$1:$J$34,8,0) -> 13750 | V7: =VLOOKUP(O7,$A$1:$J$34,9,0) -> 550
A8: 45602 | B8: =Table2345345687911121514161718192021222324252627283456789101134567891011126[[#This Row],[Profit]]-Table2345345687911121514161718192021222324252627283456789101134567891011126[[#This Row],[Mulbhag]] -> 2060 | C8: =Table2345345687911121514161718192021222324252627283456789101134567891011126[[#This Row],[Profit]]/3 -> 1030 | D8: =F8*0.3 -> 3090 | E8: =F8-D8 -> 7210 | F8: =G8+H8 -> 10300 | G8: 6820 | H8: 3480 | I8: 1640 | K8: =Table2345345687911121514161718192021222324252627283456789101134567891011126[[#This Row],[Account Transfer]]-Table2345345687911121514161718192021222324252627283456789101134567891011126[[#This Row],[Expense Online]] -> 3480 | L8: =Table2345345687911121514161718192021222324252627283456789101134567891011126[[#This Row],[Cash]]-Table2345345687911121514161718192021222324252627283456789101134567891011126[[#This Row],[Mulbhag]]-Table2345345687911121514161718192021222324252627283456789101134567891011126[[#This Row],[Actual Profit]]-Table2345345687911121514161718192021222324252627283456789101134567891011126[[#This Row],[Expense]] -> 2090 | M8: =Table2345345687911121514161718192021222324252627283456789101134567891011126[[#This Row],[Cash]]-Table2345345687911121514161718192021222324252627283456789101134567891011126[[#This Row],[Expense]] -> 5180 | O8: =A8 -> 45602 | P8: =Q8/3 -> 1030 | Q8: =S8*0.3 -> 3090 | R8: =S8-Q8 -> 7210 | S8: =T8+U8 -> 10300 | T8: =VLOOKUP(O8,$A$1:$J$34,7,0) -> 6820 | U8: =VLOOKUP(O8,$A$1:$J$34,8,0) -> 3480 | V8: =VLOOKUP(O8,$A$1:$J$34,9,0) -> 1640
A9: 45603 | B9: =Table2345345687911121514161718192021222324252627283456789101134567891011126[[#This Row],[Profit]]-Table2345345687911121514161718192021222324252627283456789101134567891011126[[#This Row],[Mulbhag]] -> 3828.6 | C9: =Table2345345687911121514161718192021222324252627283456789101134567891011126[[#This Row],[Profit]]/3 -> 1914.3 | D9: =F9*0.3 -> 5742.9 | E9: =F9-D9 -> 13400.1 | F9: =G9+H9 -> 19143 | G9: 15300 | H9: 3843 | I9: 1720 | K9: =Table2345345687911121514161718192021222324252627283456789101134567891011126[[#This Row],[Account Transfer]]-Table2345345687911121514161718192021222324252627283456789101134567891011126[[#This Row],[Expense Online]] -> 3843 | L9: =Table2345345687911121514161718192021222324252627283456789101134567891011126[[#This Row],[Cash]]-Table2345345687911121514161718192021222324252627283456789101134567891011126[[#This Row],[Mulbhag]]-Table2345345687911121514161718192021222324252627283456789101134567891011126[[#This Row],[Actual Profit]]-Table2345345687911121514161718192021222324252627283456789101134567891011126[[#This Row],[Expense]] -> 7837.1 | M9: =Table2345345687911121514161718192021222324252627283456789101134567891011126[[#This Row],[Cash]]-Table2345345687911121514161718192021222324252627283456789101134567891011126[[#This Row],[Expense]] -> 13580 | O9: =A9 -> 45603 | P9: =Q9/3 -> 1914.3 | Q9: =S9*0.3 -> 5742.9 | R9: =S9-Q9 -> 13400.1 | S9: =T9+U9 -> 19143 | T9: =VLOOKUP(O9,$A$1:$J$34,7,0) -> 15300 | U9: =VLOOKUP(O9,$A$1:$J$34,8,0) -> 3843 | V9: =VLOOKUP(O9,$A$1:$J$34,9,0) -> 1720
A10: 45604 | B10: =Table2345345687911121514161718192021222324252627283456789101134567891011126[[#This Row],[Profit]]-Table2345345687911121514161718192021222324252627283456789101134567891011126[[#This Row],[Mulbhag]] -> 1838 | C10: =Table2345345687911121514161718192021222324252627283456789101134567891011126[[#This Row],[Profit]]/3 -> 919 | D10: =F10*0.3 -> 2757 | E10: =F10-D10 -> 6433 | F10: =G10+H10 -> 9190 | G10: 4000 | H10: 5190 | I10: 120 | K10: =Table2345345687911121514161718192021222324252627283456789101134567891011126[[#This Row],[Account Transfer]]-Table2345345687911121514161718192021222324252627283456789101134567891011126[[#This Row],[Expense Online]] -> 5190 | L10: =Table2345345687911121514161718192021222324252627283456789101134567891011126[[#This Row],[Cash]]-Table2345345687911121514161718192021222324252627283456789101134567891011126[[#This Row],[Mulbhag]]-Table2345345687911121514161718192021222324252627283456789101134567891011126[[#This Row],[Actual Profit]]-Table2345345687911121514161718192021222324252627283456789101134567891011126[[#This Row],[Expense]] -> 1123 | M10: =Table2345345687911121514161718192021222324252627283456789101134567891011126[[#This Row],[Cash]]-Table2345345687911121514161718192021222324252627283456789101134567891011126[[#This Row],[Expense]] -> 3880 | O10: Total | P10: =SUM(P3:P9) -> 12961.5 | Q10: =SUM(Q3:Q9) -> 38884.5 | R10: =SUM(R2:R9) -> 90730.5 | S10: =SUM(S3:S9) -> 129615 | T10: =SUM(T2:T9) -> 75106 | U10: =SUM(U2:U9) -> 54509 | V10: =SUM(V2:V9) -> 4810
A11: 45605 | B11: =Table2345345687911121514161718192021222324252627283456789101134567891011126[[#This Row],[Profit]]-Table2345345687911121514161718192021222324252627283456789101134567891011126[[#This Row],[Mulbhag]] -> 10642 | C11: =Table2345345687911121514161718192021222324252627283456789101134567891011126[[#This Row],[Profit]]/3 -> 5321 | D11: =F11*0.3 -> 15963 | E11: =F11-D11 -> 37247 | F11: =G11+H11 -> 53210 | G11: 34175 | H11: =5110+13925 -> 19035 | I11: 1030 | K11: =Table2345345687911121514161718192021222324252627283456789101134567891011126[[#This Row],[Account Transfer]]-Table2345345687911121514161718192021222324252627283456789101134567891011126[[#This Row],[Expense Online]] -> 19035 | L11: =Table2345345687911121514161718192021222324252627283456789101134567891011126[[#This Row],[Cash]]-Table2345345687911121514161718192021222324252627283456789101134567891011126[[#This Row],[Mulbhag]]-Table2345345687911121514161718192021222324252627283456789101134567891011126[[#This Row],[Actual Profit]]-Table2345345687911121514161718192021222324252627283456789101134567891011126[[#This Row],[Expense]] -> 17182 | M11: =Table2345345687911121514161718192021222324252627283456789101134567891011126[[#This Row],[Cash]]-Table2345345687911121514161718192021222324252627283456789101134567891011126[[#This Row],[Expense]] -> 33145 | O11: Mul Bhag | Q11: =Q10/3 -> 12961.5
A12: 45606 | B12: =Table2345345687911121514161718192021222324252627283456789101134567891011126[[#This Row],[Profit]]-Table2345345687911121514161718192021222324252627283456789101134567891011126[[#This Row],[Mulbhag]] -> 10098.6 | C12: =Table2345345687911121514161718192021222324252627283456789101134567891011126[[#This Row],[Profit]]/3 -> 5049.3 | D12: =F12*0.3 -> 15147.9 | E12: =F12-D12 -> 35345.1 | F12: =G12+H12 -> 50493 | G12: 19050 | H12: 31443 | I12: 1400 | K12: =Table2345345687911121514161718192021222324252627283456789101134567891011126[[#This Row],[Account Transfer]]-Table2345345687911121514161718192021222324252627283456789101134567891011126[[#This Row],[Expense Online]] -> 31443 | L12: =Table2345345687911121514161718192021222324252627283456789101134567891011126[[#This Row],[Cash]]-Table2345345687911121514161718192021222324252627283456789101134567891011126[[#This Row],[Mulbhag]]-Table2345345687911121514161718192021222324252627283456789101134567891011126[[#This Row],[Actual Profit]]-Table2345345687911121514161718192021222324252627283456789101134567891011126[[#This Row],[Expense]] -> 2502.1 | M12: =Table2345345687911121514161718192021222324252627283456789101134567891011126[[#This Row],[Cash]]-Table2345345687911121514161718192021222324252627283456789101134567891011126[[#This Row],[Expense]] -> 17650
A13: 45607 | B13: =Table2345345687911121514161718192021222324252627283456789101134567891011126[[#This Row],[Profit]]-Table2345345687911121514161718192021222324252627283456789101134567891011126[[#This Row],[Mulbhag]] -> 3372 | C13: =Table2345345687911121514161718192021222324252627283456789101134567891011126[[#This Row],[Profit]]/3 -> 1686 | D13: =F13*0.3 -> 5058 | E13: =F13-D13 -> 11802 | F13: =G13+H13 -> 16860 | G13: 14150 | H13: 2710 | I13: 1200 | K13: =Table2345345687911121514161718192021222324252627283456789101134567891011126[[#This Row],[Account Transfer]]-Table2345345687911121514161718192021222324252627283456789101134567891011126[[#This Row],[Expense Online]] -> 2710 | L13: =Table2345345687911121514161718192021222324252627283456789101134567891011126[[#This Row],[Cash]]-Table2345345687911121514161718192021222324252627283456789101134567891011126[[#This Row],[Mulbhag]]-Table2345345687911121514161718192021222324252627283456789101134567891011126[[#This Row],[Actual Profit]]-Table2345345687911121514161718192021222324252627283456789101134567891011126[[#This Row],[Expense]] -> 7892 | M13: =Table2345345687911121514161718192021222324252627283456789101134567891011126[[#This Row],[Cash]]-Table2345345687911121514161718192021222324252627283456789101134567891011126[[#This Row],[Expense]] -> 12950 | O13: Date | Q13: Profit | R13: Actual | S13: Total | T13: Cash | U13: Account Transfer | V13: Expense
A14: 45608 | B14: =Table2345345687911121514161718192021222324252627283456789101134567891011126[[#This Row],[Profit]]-Table2345345687911121514161718192021222324252627283456789101134567891011126[[#This Row],[Mulbhag]] -> 7130.2 | C14: =Table2345345687911121514161718192021222324252627283456789101134567891011126[[#This Row],[Profit]]/3 -> 3565.1 | D14: =F14*0.3 -> 10695.3 | E14: =F14-D14 -> 24955.7 | F14: =G14+H14 -> 35651 | G14: 5710 | H14: 29941 | I14: 1700 | K14: =Table2345345687911121514161718192021222324252627283456789101134567891011126[[#This Row],[Account Transfer]]-Table2345345687911121514161718192021222324252627283456789101134567891011126[[#This Row],[Expense Online]] -> 29941 | L14: =Table2345345687911121514161718192021222324252627283456789101134567891011126[[#This Row],[Cash]]-Table2345345687911121514161718192021222324252627283456789101134567891011126[[#This Row],[Mulbhag]]-Table2345345687911121514161718192021222324252627283456789101134567891011126[[#This Row],[Actual Profit]]-Table2345345687911121514161718192021222324252627283456789101134567891011126[[#This Row],[Expense]] -> -6685.3 | M14: =Table2345345687911121514161718192021222324252627283456789101134567891011126[[#This Row],[Cash]]-Table2345345687911121514161718192021222324252627283456789101134567891011126[[#This Row],[Expense]] -> 4010 | O14: =A10 -> 45604 | P14: =Q14/3 -> 919 | Q14: =S14*0.3 -> 2757 | R14: =S14-Q14 -> 6433 | S14: =T14+U14 -> 9190 | T14: =VLOOKUP(O14,$A$1:$J$34,7,0) -> 4000 | U14: =VLOOKUP(O14,$A$1:$J$34,8,0) -> 5190 | V14: =VLOOKUP(O14,$A$1:$J$34,9,0) -> 120
A15: 45609 | B15: =Table2345345687911121514161718192021222324252627283456789101134567891011126[[#This Row],[Profit]]-Table2345345687911121514161718192021222324252627283456789101134567891011126[[#This Row],[Mulbhag]] -> 20120 | C15: =Table2345345687911121514161718192021222324252627283456789101134567891011126[[#This Row],[Profit]]/3 -> 10060 | D15: =F15*0.3 -> 30180 | E15: =F15-D15 -> 70420 | F15: =G15+H15 -> 100600 | G15: 7000 | H15: 93600 | I15: 1410 | J15: 610 | K15: =Table2345345687911121514161718192021222324252627283456789101134567891011126[[#This Row],[Account Transfer]]-Table2345345687911121514161718192021222324252627283456789101134567891011126[[#This Row],[Expense Online]] -> 92990 | L15: =Table2345345687911121514161718192021222324252627283456789101134567891011126[[#This Row],[Cash]]-Table2345345687911121514161718192021222324252627283456789101134567891011126[[#This Row],[Mulbhag]]-Table2345345687911121514161718192021222324252627283456789101134567891011126[[#This Row],[Actual Profit]]-Table2345345687911121514161718192021222324252627283456789101134567891011126[[#This Row],[Expense]] -> -24590 | M15: =Table2345345687911121514161718192021222324252627283456789101134567891011126[[#This Row],[Cash]]-Table2345345687911121514161718192021222324252627283456789101134567891011126[[#This Row],[Expense]] -> 5590 | O15: =A11 -> 45605 | P15: =Q15/3 -> 5321 | Q15: =S15*0.3 -> 15963 | R15: =S15-Q15 -> 37247 | S15: =T15+U15 -> 53210 | T15: =VLOOKUP(O15,$A$1:$J$34,7,0) -> 34175 | U15: =VLOOKUP(O15,$A$1:$J$34,8,0) -> 19035 | V15: =VLOOKUP(O15,$A$1:$J$34,9,0) -> 1030
A16: 45610 | B16: =Table2345345687911121514161718192021222324252627283456789101134567891011126[[#This Row],[Profit]]-Table2345345687911121514161718192021222324252627283456789101134567891011126[[#This Row],[Mulbhag]] -> 4529 | C16: =Table2345345687911121514161718192021222324252627283456789101134567891011126[[#This Row],[Profit]]/3 -> 2264.5 | D16: =F16*0.3 -> 6793.5 | E16: =F16-D16 -> 15851.5 | F16: =G16+H16 -> 22645 | G16: 7400 | H16: 15245 | I16: 2350 | J16: 520 | K16: =Table2345345687911121514161718192021222324252627283456789101134567891011126[[#This Row],[Account Transfer]]-Table2345345687911121514161718192021222324252627283456789101134567891011126[[#This Row],[Expense Online]] -> 14725 | L16: =Table2345345687911121514161718192021222324252627283456789101134567891011126[[#This Row],[Cash]]-Table2345345687911121514161718192021222324252627283456789101134567891011126[[#This Row],[Mulbhag]]-Table2345345687911121514161718192021222324252627283456789101134567891011126[[#This Row],[Actual Profit]]-Table2345345687911121514161718192021222324252627283456789101134567891011126[[#This Row],[Expense]] -> -1743.5 | M16: =Table2345345687911121514161718192021222324252627283456789101134567891011126[[#This Row],[Cash]]-Table2345345687911121514161718192021222324252627283456789101134567891011126[[#This Row],[Expense]] -> 5050 | O16: =A12 -> 45606 | P16: =Q16/3 -> 5049.3 | Q16: =S16*0.3 -> 15147.9 | R16: =S16-Q16 -> 35345.1 | S16: =T16+U16 -> 50493 | T16: =VLOOKUP(O16,$A$1:$J$34,7,0) -> 19050 | U16: =VLOOKUP(O16,$A$1:$J$34,8,0) -> 31443 | V16: =VLOOKUP(O16,$A$1:$J$34,9,0) -> 1400
A17: 45611 | B17: =Table2345345687911121514161718192021222324252627283456789101134567891011126[[#This Row],[Profit]]-Table2345345687911121514161718192021222324252627283456789101134567891011126[[#This Row],[Mulbhag]] -> 4430.6 | C17: =Table2345345687911121514161718192021222324252627283456789101134567891011126[[#This Row],[Profit]]/3 -> 2215.3 | D17: =F17*0.3 -> 6645.9 | E17: =F17-D17 -> 15507.1 | F17: =G17+H17 -> 22153 | G17: 18710 | H17: 3443 | I17: 3520 | K17: =Table2345345687911121514161718192021222324252627283456789101134567891011126[[#This Row],[Account Transfer]]-Table2345345687911121514161718192021222324252627283456789101134567891011126[[#This Row],[Expense Online]] -> 3443 | L17: =Table2345345687911121514161718192021222324252627283456789101134567891011126[[#This Row],[Cash]]-Table2345345687911121514161718192021222324252627283456789101134567891011126[[#This Row],[Mulbhag]]-Table2345345687911121514161718192021222324252627283456789101134567891011126[[#This Row],[Actual Profit]]-Table2345345687911121514161718192021222324252627283456789101134567891011126[[#This Row],[Expense]] -> 8544.1 | M17: =Table2345345687911121514161718192021222324252627283456789101134567891011126[[#This Row],[Cash]]-Table2345345687911121514161718192021222324252627283456789101134567891011126[[#This Row],[Expense]] -> 15190 | O17: =A13 -> 45607 | P17: =Q17/3 -> 1686 | Q17: =S17*0.3 -> 5058 | R17: =S17-Q17 -> 11802 | S17: =T17+U17 -> 16860 | T17: =VLOOKUP(O17,$A$1:$J$34,7,0) -> 14150 | U17: =VLOOKUP(O17,$A$1:$J$34,8,0) -> 2710 | V17: =VLOOKUP(O17,$A$1:$J$34,9,0) -> 1200
A18: 45612 | B18: =Table2345345687911121514161718192021222324252627283456789101134567891011126[[#This Row],[Profit]]-Table2345345687911121514161718192021222324252627283456789101134567891011126[[#This Row],[Mulbhag]] -> 6660 | C18: =Table2345345687911121514161718192021222324252627283456789101134567891011126[[#This Row],[Profit]]/3 -> 3330 | D18: =F18*0.3 -> 9990 | E18: =F18-D18 -> 23310 | F18: =G18+H18 -> 33300 | G18: 21000 | H18: 12300 | I18: 1190 | J18: 800 | K18: =Table2345345687911121514161718192021222324252627283456789101134567891011126[[#This Row],[Account Transfer]]-Table2345345687911121514161718192021222324252627283456789101134567891011126[[#This Row],[Expense Online]] -> 11500 | L18: =Table2345345687911121514161718192021222324252627283456789101134567891011126[[#This Row],[Cash]]-Table2345345687911121514161718192021222324252627283456789101134567891011126[[#This Row],[Mulbhag]]-Table2345345687911121514161718192021222324252627283456789101134567891011126[[#This Row],[Actual Profit]]-Table2345345687911121514161718192021222324252627283456789101134567891011126[[#This Row],[Expense]] -> 9820 | M18: =Table2345345687911121514161718192021222324252627283456789101134567891011126[[#This Row],[Cash]]-Table2345345687911121514161718192021222324252627283456789101134567891011126[[#This Row],[Expense]] -> 19810 | O18: =A14 -> 45608 | P18: =Q18/3 -> 3565.1 | Q18: =S18*0.3 -> 10695.3 | R18: =S18-Q18 -> 24955.7 | S18: =T18+U18 -> 35651 | T18: =VLOOKUP(O18,$A$1:$J$34,7,0) -> 5710 | U18: =VLOOKUP(O18,$A$1:$J$34,8,0) -> 29941 | V18: =VLOOKUP(O18,$A$1:$J$34,9,0) -> 1700
A19: 45613 | B19: =Table2345345687911121514161718192021222324252627283456789101134567891011126[[#This Row],[Profit]]-Table2345345687911121514161718192021222324252627283456789101134567891011126[[#This Row],[Mulbhag]] -> 6067 | C19: =Table2345345687911121514161718192021222324252627283456789101134567891011126[[#This Row],[Profit]]/3 -> 3033.5 | D19: =F19*0.3 -> 9100.5 | E19: =F19-D19 -> 21234.5 | F19: =G19+H19 -> 30335 | G19: 13675 | H19: 16660 | I19: 1350 | K19: =Table2345345687911121514161718192021222324252627283456789101134567891011126[[#This Row],[Account Transfer]]-Table2345345687911121514161718192021222324252627283456789101134567891011126[[#This Row],[Expense Online]] -> 16660 | L19: =Table2345345687911121514161718192021222324252627283456789101134567891011126[[#This Row],[Cash]]-Table2345345687911121514161718192021222324252627283456789101134567891011126[[#This Row],[Mulbhag]]-Table2345345687911121514161718192021222324252627283456789101134567891011126[[#This Row],[Actual Profit]]-Table2345345687911121514161718192021222324252627283456789101134567891011126[[#This Row],[Expense]] -> 3224.5 | M19: =Table2345345687911121514161718192021222324252627283456789101134567891011126[[#This Row],[Cash]]-Table2345345687911121514161718192021222324252627283456789101134567891011126[[#This Row],[Expense]] -> 12325 | O19: =A15 -> 45609 | P19: =Q19/3 -> 10060 | Q19: =S19*0.3 -> 30180 | R19: =S19-Q19 -> 70420 | S19: =T19+U19 -> 100600 | T19: =VLOOKUP(O19,$A$1:$J$34,7,0) -> 7000 | U19: =VLOOKUP(O19,$A$1:$J$34,8,0) -> 93600 | V19: =VLOOKUP(O19,$A$1:$J$34,9,0) -> 1410
A20: 45614 | B20: =Table2345345687911121514161718192021222324252627283456789101134567891011126[[#This Row],[Profit]]-Table2345345687911121514161718192021222324252627283456789101134567891011126[[#This Row],[Mulbhag]] -> 4058 | C20: =Table2345345687911121514161718192021222324252627283456789101134567891011126[[#This Row],[Profit]]/3 -> 2029 | D20: =F20*0.3 -> 6087 | E20: =F20-D20 -> 14203 | F20: =G20+H20 -> 20290 | G20: 4500 | H20: 15790 | I20: =1585+3540 -> 5125 | K20: =Table2345345687911121514161718192021222324252627283456789101134567891011126[[#This Row],[Account Transfer]]-Table2345345687911121514161718192021222324252627283456789101134567891011126[[#This Row],[Expense Online]] -> 15790 | L20: =Table2345345687911121514161718192021222324252627283456789101134567891011126[[#This Row],[Cash]]-Table2345345687911121514161718192021222324252627283456789101134567891011126[[#This Row],[Mulbhag]]-Table2345345687911121514161718192021222324252627283456789101134567891011126[[#This Row],[Actual Profit]]-Table2345345687911121514161718192021222324252627283456789101134567891011126[[#This Row],[Expense]] -> -6712 | M20: =Table2345345687911121514161718192021222324252627283456789101134567891011126[[#This Row],[Cash]]-Table2345345687911121514161718192021222324252627283456789101134567891011126[[#This Row],[Expense]] -> -625 | O20: =A16 -> 45610 | P20: =Q20/3 -> 2264.5 | Q20: =S20*0.3 -> 6793.5 | R20: =S20-Q20 -> 15851.5 | S20: =T20+U20 -> 22645 | T20: =VLOOKUP(O20,$A$1:$J$34,7,0) -> 7400 | U20: =VLOOKUP(O20,$A$1:$J$34,8,0) -> 15245 | V20: =VLOOKUP(O20,$A$1:$J$34,9,0) -> 2350
A21: 45615 | B21: =Table2345345687911121514161718192021222324252627283456789101134567891011126[[#This Row],[Profit]]-Table2345345687911121514161718192021222324252627283456789101134567891011126[[#This Row],[Mulbhag]] -> 1170 | C21: =Table2345345687911121514161718192021222324252627283456789101134567891011126[[#This Row],[Profit]]/3 -> 585 | D21: =F21*0.3 -> 1755 | E21: =F21-D21 -> 4095 | F21: =G21+H21 -> 5850 | G21: 1830 | H21: 4020 | I21: 1700 | K21: =Table2345345687911121514161718192021222324252627283456789101134567891011126[[#This Row],[Account Transfer]]-Table2345345687911121514161718192021222324252627283456789101134567891011126[[#This Row],[Expense Online]] -> 4020 | L21: =Table2345345687911121514161718192021222324252627283456789101134567891011126[[#This Row],[Cash]]-Table2345345687911121514161718192021222324252627283456789101134567891011126[[#This Row],[Mulbhag]]-Table2345345687911121514161718192021222324252627283456789101134567891011126[[#This Row],[Actual Profit]]-Table2345345687911121514161718192021222324252627283456789101134567891011126[[#This Row],[Expense]] -> -1625 | M21: =Table2345345687911121514161718192021222324252627283456789101134567891011126[[#This Row],[Cash]]-Table2345345687911121514161718192021222324252627283456789101134567891011126[[#This Row],[Expense]] -> 130 | O21: Total | P21: =SUM(P14:P20) -> 28864.9 | Q21: =SUM(Q14:Q20) -> 86594.7 | R21: =SUM(R14:R20) -> 202054.3 | S21: =SUM(S14:S20) -> 288649 | T21: =SUM(T14:T20) -> 91485 | U21: =SUM(U14:U20) -> 197164 | V21: =SUM(V14:V20) -> 9210
A22: 45616 | B22: =Table2345345687911121514161718192021222324252627283456789101134567891011126[[#This Row],[Profit]]-Table2345345687911121514161718192021222324252627283456789101134567891011126[[#This Row],[Mulbhag]] -> 1620 | C22: =Table2345345687911121514161718192021222324252627283456789101134567891011126[[#This Row],[Profit]]/3 -> 810 | D22: =F22*0.3 -> 2430 | E22: =F22-D22 -> 5670 | F22: =G22+H22 -> 8100 | G22: 2600 | H22: 5500 | I22: 1700 | J22: 120 | K22: =Table2345345687911121514161718192021222324252627283456789101134567891011126[[#This Row],[Account Transfer]]-Table2345345687911121514161718192021222324252627283456789101134567891011126[[#This Row],[Expense Online]] -> 5380 | L22: =Table2345345687911121514161718192021222324252627283456789101134567891011126[[#This Row],[Cash]]-Table2345345687911121514161718192021222324252627283456789101134567891011126[[#This Row],[Mulbhag]]-Table2345345687911121514161718192021222324252627283456789101134567891011126[[#This Row],[Actual Profit]]-Table2345345687911121514161718192021222324252627283456789101134567891011126[[#This Row],[Expense]] -> -1530 | M22: =Table2345345687911121514161718192021222324252627283456789101134567891011126[[#This Row],[Cash]]-Table2345345687911121514161718192021222324252627283456789101134567891011126[[#This Row],[Expense]] -> 900 | O22: Mul Bhag | Q22: =Q21/3 -> 28864.9 | S22: =R22+Q22 -> 28864.9
A23: 45617 | B23: =Table2345345687911121514161718192021222324252627283456789101134567891011126[[#This Row],[Profit]]-Table2345345687911121514161718192021222324252627283456789101134567891011126[[#This Row],[Mulbhag]] -> 4228 | C23: =Table2345345687911121514161718192021222324252627283456789101134567891011126[[#This Row],[Profit]]/3 -> 2114 | D23: =F23*0.3 -> 6342 | E23: =F23-D23 -> 14798 | F23: =G23+H23 -> 21140 | G23: 5320 | H23: 15820 | I23: =700+2500 -> 3200 | J23: 60 | K23: =Table2345345687911121514161718192021222324252627283456789101134567891011126[[#This Row],[Account Transfer]]-Table2345345687911121514161718192021222324252627283456789101134567891011126[[#This Row],[Expense Online]] -> 15760 | L23: =Table2345345687911121514161718192021222324252627283456789101134567891011126[[#This Row],[Cash]]-Table2345345687911121514161718192021222324252627283456789101134567891011126[[#This Row],[Mulbhag]]-Table2345345687911121514161718192021222324252627283456789101134567891011126[[#This Row],[Actual Profit]]-Table2345345687911121514161718192021222324252627283456789101134567891011126[[#This Row],[Expense]] -> -4222 | M23: =Table2345345687911121514161718192021222324252627283456789101134567891011126[[#This Row],[Cash]]-Table2345345687911121514161718192021222324252627283456789101134567891011126[[#This Row],[Expense]] -> 2120
A24: 45618 | B24: =Table2345345687911121514161718192021222324252627283456789101134567891011126[[#This Row],[Profit]]-Table2345345687911121514161718192021222324252627283456789101134567891011126[[#This Row],[Mulbhag]] -> 6993.8 | C24: =Table2345345687911121514161718192021222324252627283456789101134567891011126[[#This Row],[Profit]]/3 -> 3496.9 | D24: =F24*0.3 -> 10490.7 | E24: =F24-D24 -> 24478.3 | F24: =G24+H24 -> 34969 | G24: 32689 | H24: 2280 | I24: 4340 | K24: =Table2345345687911121514161718192021222324252627283456789101134567891011126[[#This Row],[Account Transfer]]-Table2345345687911121514161718192021222324252627283456789101134567891011126[[#This Row],[Expense Online]] -> 2280 | L24: =Table2345345687911121514161718192021222324252627283456789101134567891011126[[#This Row],[Cash]]-Table2345345687911121514161718192021222324252627283456789101134567891011126[[#This Row],[Mulbhag]]-Table2345345687911121514161718192021222324252627283456789101134567891011126[[#This Row],[Actual Profit]]-Table2345345687911121514161718192021222324252627283456789101134567891011126[[#This Row],[Expense]] -> 17858.3 | M24: =Table2345345687911121514161718192021222324252627283456789101134567891011126[[#This Row],[Cash]]-Table2345345687911121514161718192021222324252627283456789101134567891011126[[#This Row],[Expense]] -> 28349 | O24: Date | Q24: Profit | R24: Actual | S24: Total | T24: Cash | U24: Account Transfer | V24: Expense
A25: 45619 | B25: =Table2345345687911121514161718192021222324252627283456789101134567891011126[[#This Row],[Profit]]-Table2345345687911121514161718192021222324252627283456789101134567891011126[[#This Row],[Mulbhag]] -> 2672 | C25: =Table2345345687911121514161718192021222324252627283456789101134567891011126[[#This Row],[Profit]]/3 -> 1336 | D25: =F25*0.3 -> 4008 | E25: =F25-D25 -> 9352 | F25: =G25+H25 -> 13360 | G25: 4680 | H25: =7880+800 -> 8680 | I25: 1200 | K25: =Table2345345687911121514161718192021222324252627283456789101134567891011126[[#This Row],[Account Transfer]]-Table2345345687911121514161718192021222324252627283456789101134567891011126[[#This Row],[Expense Online]] -> 8680 | L25: =Table2345345687911121514161718192021222324252627283456789101134567891011126[[#This Row],[Cash]]-Table2345345687911121514161718192021222324252627283456789101134567891011126[[#This Row],[Mulbhag]]-Table2345345687911121514161718192021222324252627283456789101134567891011126[[#This Row],[Actual Profit]]-Table2345345687911121514161718192021222324252627283456789101134567891011126[[#This Row],[Expense]] -> -528 | M25: =Table2345345687911121514161718192021222324252627283456789101134567891011126[[#This Row],[Cash]]-Table2345345687911121514161718192021222324252627283456789101134567891011126[[#This Row],[Expense]] -> 3480 | O25: =A17 -> 45611 | P25: =Q25/3 -> 2215.3 | Q25: =S25*0.3 -> 6645.9 | R25: =S25-Q25 -> 15507.1 | S25: =T25+U25 -> 22153 | T25: =VLOOKUP(O25,$A$1:$J$34,7,0) -> 18710 | U25: =VLOOKUP(O25,$A$1:$J$34,8,0) -> 3443 | V25: =VLOOKUP(O25,$A$1:$J$34,9,0) -> 3520
A26: 45620 | B26: =Table2345345687911121514161718192021222324252627283456789101134567891011126[[#This Row],[Profit]]-Table2345345687911121514161718192021222324252627283456789101134567891011126[[#This Row],[Mulbhag]] -> 4193 | C26: =Table2345345687911121514161718192021222324252627283456789101134567891011126[[#This Row],[Profit]]/3 -> 2096.5 | D26: =F26*0.3 -> 6289.5 | E26: =F26-D26 -> 14675.5 | F26: =G26+H26 -> 20965 | G26: 6000 | H26: =11015+3950 -> 14965 | I26: 1250 | K26: =Table2345345687911121514161718192021222324252627283456789101134567891011126[[#This Row],[Account Transfer]]-Table2345345687911121514161718192021222324252627283456789101134567891011126[[#This Row],[Expense Online]] -> 14965 | L26: =Table2345345687911121514161718192021222324252627283456789101134567891011126[[#This Row],[Cash]]-Table2345345687911121514161718192021222324252627283456789101134567891011126[[#This Row],[Mulbhag]]-Table2345345687911121514161718192021222324252627283456789101134567891011126[[#This Row],[Actual Profit]]-Table2345345687911121514161718192021222324252627283456789101134567891011126[[#This Row],[Expense]] -> -1539.5 | M26: =Table2345345687911121514161718192021222324252627283456789101134567891011126[[#This Row],[Cash]]-Table2345345687911121514161718192021222324252627283456789101134567891011126[[#This Row],[Expense]] -> 4750 | O26: =A18 -> 45612 | P26: =Q26/3 -> 3330 | Q26: =S26*0.3 -> 9990 | R26: =S26-Q26 -> 23310 | S26: =T26+U26 -> 33300 | T26: =VLOOKUP(O26,$A$1:$J$34,7,0) -> 21000 | U26: =VLOOKUP(O26,$A$1:$J$34,8,0) -> 12300 | V26: =VLOOKUP(O26,$A$1:$J$34,9,0) -> 1190
A27: 45621 | B27: =Table2345345687911121514161718192021222324252627283456789101134567891011126[[#This Row],[Profit]]-Table2345345687911121514161718192021222324252627283456789101134567891011126[[#This Row],[Mulbhag]] -> 5650 | C27: =Table2345345687911121514161718192021222324252627283456789101134567891011126[[#This Row],[Profit]]/3 -> 2825 | D27: =F27*0.3 -> 8475 | E27: =F27-D27 -> 19775 | F27: =G27+H27 -> 28250 | G27: 9800 | H27: 18450 | I27: 3100 | K27: =Table2345345687911121514161718192021222324252627283456789101134567891011126[[#This Row],[Account Transfer]]-Table2345345687911121514161718192021222324252627283456789101134567891011126[[#This Row],[Expense Online]] -> 18450 | L27: =Table2345345687911121514161718192021222324252627283456789101134567891011126[[#This Row],[Cash]]-Table2345345687911121514161718192021222324252627283456789101134567891011126[[#This Row],[Mulbhag]]-Table2345345687911121514161718192021222324252627283456789101134567891011126[[#This Row],[Actual Profit]]-Table2345345687911121514161718192021222324252627283456789101134567891011126[[#This Row],[Expense]] -> -1775 | M27: =Table2345345687911121514161718192021222324252627283456789101134567891011126[[#This Row],[Cash]]-Table2345345687911121514161718192021222324252627283456789101134567891011126[[#This Row],[Expense]] -> 6700 | O27: =A19 -> 45613 | P27: =Q27/3 -> 3033.5 | Q27: =S27*0.3 -> 9100.5 | R27: =S27-Q27 -> 21234.5 | S27: =T27+U27 -> 30335 | T27: =VLOOKUP(O27,$A$1:$J$34,7,0) -> 13675 | U27: =VLOOKUP(O27,$A$1:$J$34,8,0) -> 16660 | V27: =VLOOKUP(O27,$A$1:$J$34,9,0) -> 1350
A28: 45622 | B28: =Table2345345687911121514161718192021222324252627283456789101134567891011126[[#This Row],[Profit]]-Table2345345687911121514161718192021222324252627283456789101134567891011126[[#This Row],[Mulbhag]] -> 2671 | C28: =Table2345345687911121514161718192021222324252627283456789101134567891011126[[#This Row],[Profit]]/3 -> 1335.5 | D28: =F28*0.3 -> 4006.5 | E28: =F28-D28 -> 9348.5 | F28: =G28+H28 -> 13355 | G28: 7655 | H28: 5700 | I28: 3655 | K28: =Table2345345687911121514161718192021222324252627283456789101134567891011126[[#This Row],[Account Transfer]]-Table2345345687911121514161718192021222324252627283456789101134567891011126[[#This Row],[Expense Online]] -> 5700 | L28: =Table2345345687911121514161718192021222324252627283456789101134567891011126[[#This Row],[Cash]]-Table2345345687911121514161718192021222324252627283456789101134567891011126[[#This Row],[Mulbhag]]-Table2345345687911121514161718192021222324252627283456789101134567891011126[[#This Row],[Actual Profit]]-Table2345345687911121514161718192021222324252627283456789101134567891011126[[#This Row],[Expense]] -> -6.5 | M28: =Table2345345687911121514161718192021222324252627283456789101134567891011126[[#This Row],[Cash]]-Table2345345687911121514161718192021222324252627283456789101134567891011126[[#This Row],[Expense]] -> 4000 | O28: =A20 -> 45614 | P28: =Q28/3 -> 2029 | Q28: =S28*0.3 -> 6087 | R28: =S28-Q28 -> 14203 | S28: =T28+U28 -> 20290 | T28: =VLOOKUP(O28,$A$1:$J$34,7,0) -> 4500 | U28: =VLOOKUP(O28,$A$1:$J$34,8,0) -> 15790 | V28: =VLOOKUP(O28,$A$1:$J$34,9,0) -> 5125
A29: 45623 | B29: =Table2345345687911121514161718192021222324252627283456789101134567891011126[[#This Row],[Profit]]-Table2345345687911121514161718192021222324252627283456789101134567891011126[[#This Row],[Mulbhag]] -> 8235.2 | C29: =Table2345345687911121514161718192021222324252627283456789101134567891011126[[#This Row],[Profit]]/3 -> 4117.6 | D29: =F29*0.3 -> 12352.8 | E29: =F29-D29 -> 28823.2 | F29: =G29+H29 -> 41176 | G29: 34785 | H29: 6391 | I29: 8540 | K29: =Table2345345687911121514161718192021222324252627283456789101134567891011126[[#This Row],[Account Transfer]]-Table2345345687911121514161718192021222324252627283456789101134567891011126[[#This Row],[Expense Online]] -> 6391 | L29: =Table2345345687911121514161718192021222324252627283456789101134567891011126[[#This Row],[Cash]]-Table2345345687911121514161718192021222324252627283456789101134567891011126[[#This Row],[Mulbhag]]-Table2345345687911121514161718192021222324252627283456789101134567891011126[[#This Row],[Actual Profit]]-Table2345345687911121514161718192021222324252627283456789101134567891011126[[#This Row],[Expense]] -> 13892.2 | M29: =Table2345345687911121514161718192021222324252627283456789101134567891011126[[#This Row],[Cash]]-Table2345345687911121514161718192021222324252627283456789101134567891011126[[#This Row],[Expense]] -> 26245 | O29: =A21 -> 45615 | P29: =Q29/3 -> 585 | Q29: =S29*0.3 -> 1755 | R29: =S29-Q29 -> 4095 | S29: =T29+U29 -> 5850 | T29: =VLOOKUP(O29,$A$1:$J$34,7,0) -> 1830 | U29: =VLOOKUP(O29,$A$1:$J$34,8,0) -> 4020 | V29: =VLOOKUP(O29,$A$1:$J$34,9,0) -> 1700
A30: 45624 | B30: =Table2345345687911121514161718192021222324252627283456789101134567891011126[[#This Row],[Profit]]-Table2345345687911121514161718192021222324252627283456789101134567891011126[[#This Row],[Mulbhag]] -> 1388 | C30: =Table2345345687911121514161718192021222324252627283456789101134567891011126[[#This Row],[Profit]]/3 -> 694 | D30: =F30*0.3 -> 2082 | E30: =F30-D30 -> 4858 | F30: =G30+H30 -> 6940 | G30: 4770 | H30: 2170 | I30: 1150 | K30: =Table2345345687911121514161718192021222324252627283456789101134567891011126[[#This Row],[Account Transfer]]-Table2345345687911121514161718192021222324252627283456789101134567891011126[[#This Row],[Expense Online]] -> 2170 | L30: =Table2345345687911121514161718192021222324252627283456789101134567891011126[[#This Row],[Cash]]-Table2345345687911121514161718192021222324252627283456789101134567891011126[[#This Row],[Mulbhag]]-Table2345345687911121514161718192021222324252627283456789101134567891011126[[#This Row],[Actual Profit]]-Table2345345687911121514161718192021222324252627283456789101134567891011126[[#This Row],[Expense]] -> 1538 | M30: =Table2345345687911121514161718192021222324252627283456789101134567891011126[[#This Row],[Cash]]-Table2345345687911121514161718192021222324252627283456789101134567891011126[[#This Row],[Expense]] -> 3620 | O30: =A22 -> 45616 | P30: =Q30/3 -> 810 | Q30: =S30*0.3 -> 2430 | R30: =S30-Q30 -> 5670 | S30: =T30+U30 -> 8100 | T30: =VLOOKUP(O30,$A$1:$J$34,7,0) -> 2600 | U30: =VLOOKUP(O30,$A$1:$J$34,8,0) -> 5500 | V30: =VLOOKUP(O30,$A$1:$J$34,9,0) -> 1700
