Workbook

Sheet Sheet1
A1: Start Date | B1: End Date | C1: Profit | D1: Actual | E1: Total | F1: Cash | G1: Account Transfer | H1: Mul bhag
A2: 44866 | B2: 44895 | C2: =E2*0.3 -> 242775.6 | D2: =E2-C2 -> 566476.4 | E2: 809252 | F2: 441624 | G2: 367628 | H2: =C2/3 -> 80925.2 | J2: Avg business Before diwali | K2: =AVERAGE(E2:E12) -> 614454 | L2: =K2*10 -> 6144540 | N2: =L10*12/L2 -> 0.30856663
A3: 44896 | B3: 45261 | C3: =E3*0.3 -> 206920.5 | D3: =E3-C3 -> 482814.5 | E3: 689735 | F3: 331694 | G3: 358041 | H3: =C3/3 -> 68973.5 | J3: Avg business on diwali | K3: =SUM(E13:E14) -> 6840033.1
A4: 44928 | B4: 44957 | C4: =E4*0.3 -> 173440.5 | D4: =E4-C4 -> 404694.5 | E4: 578135 | F4: 300478 | G4: 277657 | H4: =C4/3 -> 57813.5
A5: 44958 | B5: 44985 | C5: =E5*0.3 -> 226772.7 | D5: =E5-C5 -> 529136.3 | E5: 755909 | F5: 382322 | G5: 373587 | H5: =C5/3 -> 75590.9 | J5: Fixed Cost | K5: Rent | L5: =105000 -> 105000
A6: 44986 | B6: 45016 | C6: =E6*0.3 -> 201082.8 | D6: =E6-C6 -> 469193.2 | E6: 670276 | F6: 288155 | G6: 382121 | H6: =C6/3 -> 67027.6 | K6: Avg Salary | L6: 36000
A7: 45017 | B7: 45046 | C7: =E7*0.3 -> 159962.4 | D7: =E7-C7 -> 373245.6 | E7: 533208 | F7: 314141 | G7: 219067 | H7: =C7/3 -> 53320.8 | K7: Light bill | L7: 10000
A8: 45047 | B8: 45077 | C8: =E8*0.3 -> 165549 | D8: =E8-C8 -> 386281 | E8: 551830 | F8: 266235 | G8: 285595 | H8: =C8/3 -> 55183 | K8: Breakage | L8: 7000
A9: 45078 | B9: 45107 | C9: =E9*0.3 -> 138583.5 | D9: =E9-C9 -> 323361.5 | E9: ='June 2023'!D30+'May 2023'!D49 -> 461945 | F9: ='June 2023'!E30+'May 2023'!E49 -> 190800 | G9: ='June 2023'!F30+'May 2023'!F49 -> 271145 | H9: =C9/3 -> 46194.5
A10: 45108 | B10: 45138 | C10: =E10*0.3 -> 106491 | D10: =E10-C10 -> 248479 | E10: ='July 2023'!D31+'July 2023'!D41 -> 354970 | F10: ='July 2023'!E31+'July 2023'!E41 -> 125790 | G10: ='July 2023'!F31+'July 2023'!F41 -> 229180 | H10: =C10/3 -> 35497 | L10: =SUM(L5:L9) -> 158000
A11: 45139 | B11: 45169 | C11: =E11*0.3 -> 185762.1 | D11: =E11-C11 -> 433444.9 | E11: 619207 | F11: 220841 | G11: 398366 | H11: =C11/3 -> 61920.7
A12: 45170 | B12: 45199 | C12: =E12*0.3 -> 220358.1 | D12: =E12-C12 -> 514168.9 | E12: 734527 | F12: 262189 | G12: 472338 | H12: =C12/3 -> 73452.7
A13: 45200 | B13: 45230 | C13: =E13*0.3 -> 1281118.2 | D13: =E13-C13 -> 2989275.9 | E13: 4270394.1 | F13: 2496280 | G13: 1326204.1 | H13: =C13/3 -> 427039.41
A14: 45231 | B14: 45256 | C14: =E14*0.3 -> 770891.7 | D14: =E14-C14 -> 1798747.3 | E14: 2569639 | F14: 1719140 | G14: 850499 | H14: =C14/3 -> 256963.9
A15: Total | C15: =SUM(C2:C14) -> 4079708.1 | D15: =SUM(D2:D14) -> 9519319 | E15: =SUM(E2:E14) -> 13599027 | F15: =SUM(F2:F14) -> 7339689 | G15: =SUM(G2:G14) -> 5811428.1 | H15: =SUM(H2:H14) -> 1359902.7
A18: Item(Packing) | B18: Actual Rate | C18: Sell Price | D18: Profit Per box | E18: Profit(%)
A19: T0(180) | B19: =(1.1*180)+52+6+20 -> 276 | C19: =180*2 -> 360 | D19: =C19-B19 -> 84 | E19: =D19/B19 -> 0.30434783
A20: T0(200) | B20: =(1.1*200)+52+6+20 -> 298 | C20: =200*2 -> 400 | D20: =C20-B20 -> 102 | E20: =D20/B20 -> 0.34228188
A21: T00(195) | B21: =(1.1*195)+52+6+20 -> 292.5 | C21: =195*2 -> 390 | D21: =C21-B21 -> 97.5 | E21: =D21/B21 -> 0.33333333
A22: T00(200) | B22: =(1.1*200)+52+6+20 -> 298 | C22: =200*2 -> 400 | D22: =C22-B22 -> 102 | E22: =D22/B22 -> 0.34228188
A23: T3(100) | B23: =(1.4*100)+52+6 -> 198 | C23: =100*3.5 -> 350 | D23: =C23-B23 -> 152 | E23: =D23/B23 -> 0.76767677
A24: Chai Kulhad big(100) | B24: =(2*100)+52+6 -> 258 | C24: =100*5 -> 500 | D24: =C24-B24 -> 242 | E24: =D24/B24 -> 0.9379845
A25: Chai Kulhad small(180) | B25: =(1.3*180)+52+6 -> 292 | C25: =180*2.4 -> 432 | D25: =C25-B25 -> 140 | E25: =D25/B25 -> 0.47945205
A26: T5(90) | B26: =(1.8*90)+52+6 -> 220 | C26: =90*5 -> 450 | D26: =C26-B26 -> 230 | E26: =D26/B26 -> 1.0454545
A27: T9(63) | B27: =(2.5*90)+52+6 -> 283 | C27: =63*7 -> 441 | D27: =C27-B27 -> 158 | E27: =D27/B27 -> 0.55830389
A28: Handi(500gms) | B28: =(12*18)+52+6 -> 274 | C28: =30*18 -> 540 | D28: =C28-B28 -> 266 | E28: =D28/B28 -> 0.97080292
A29: Handi(1000gms) | B29: =(17*12)+52+6 -> 262 | C29: =50*12 -> 600 | D29: =C29-B29 -> 338 | E29: =D29/B29 -> 1.2900763
A30: Handi(1500gms) | B30: =(10*27)+52+6 -> 328 | C30: =80*10 -> 800 | D30: =C30-B30 -> 472 | E30: =D30/B30 -> 1.4390244
A31: Lid | B31: =(30*5)+52+6 -> 208 | C31: =10*30 -> 300 | D31: =C31-B31 -> 92 | E31: =D31/B31 -> 0.44230769

Sheet January 2023
A1: Date | B1: Profit | C1: Actual | D1: Total | E1: Cash | F1: Account Transfer | G1: Expense | H1: Percentage | I1: Cash In Hand | K1: Date | L1: Profit | M1: Actual | N1: Total | O1: Cash | P1: Account Transfer | Q1: Expense
A2: 44928 | B2: =D2*0.3 -> 1242 | C2: =D2-B2 -> 2898 | D2: =E2+F2 -> 4140 | E2: 4060 | F2: 80 | G2: 100 | H2: =IFERROR(B2/C2,0) -> 0.42857143 | I2: =SUM($D$2:D2)-SUM($G$2:G2) -> 4040 | K2: Export | Q2: 0
A3: 44929 | B3: =D3*0.3 -> 12624 | C3: =D3-B3 -> 29456 | D3: =E3+F3 -> 42080 | E3: 33690 | F3: 8390 | G3: 1110 | H3: =IFERROR(B3/C3,0) -> 0.42857143 | I3: =SUM($D$2:D3)-SUM($G$2:G3) -> 45010 | K3: =A2 -> 44928 | L3: =N3*0.39 -> 1614.6 | M3: =N3-L3 -> 2525.4 | N3: =O3+P3 -> 4140 | O3: =VLOOKUP(K3,$A$1:$H$37,5,0) -> 4060 | P3: =VLOOKUP(K3,$A$1:$H$37,6,0) -> 80 | Q3: =VLOOKUP(K3,$A$1:$H$37,7,0) -> 100
A4: 44930 | B4: =D4*0.3 -> 11262 | C4: =D4-B4 -> 26278 | D4: =E4+F4 -> 37540 | E4: 10750 | F4: 26790 | G4: 100 | H4: =IFERROR(B4/C4,0) -> 0.42857143 | I4: =SUM($D$2:D4)-SUM($G$2:G4) -> 82450 | K4: =A3 -> 44929 | L4: =N4*0.39 -> 16411.2 | M4: =N4-L4 -> 25668.8 | N4: =O4+P4 -> 42080 | O4: =VLOOKUP(K4,$A$1:$H$37,5,0) -> 33690 | P4: =VLOOKUP(K4,$A$1:$H$37,6,0) -> 8390 | Q4: =VLOOKUP(K4,$A$1:$H$37,7,0) -> 1110
A5: 44931 | B5: =D5*0.3 -> 3051.3 | C5: =D5-B5 -> 7119.7 | D5: =E5+F5 -> 10171 | E5: 9421 | F5: 750 | G5: 3590 | H5: =IFERROR(B5/C5,0) -> 0.42857143 | I5: =SUM($D$2:D5)-SUM($G$2:G5) -> 89031 | K5: =A4 -> 44930 | L5: =N5*0.39 -> 14640.6 | M5: =N5-L5 -> 22899.4 | N5: =O5+P5 -> 37540 | O5: =VLOOKUP(K5,$A$1:$H$37,5,0) -> 10750 | P5: =VLOOKUP(K5,$A$1:$H$37,6,0) -> 26790 | Q5: =VLOOKUP(K5,$A$1:$H$37,7,0) -> 100
A6: 44932 | B6: =D6*0.3 -> 19530.3 | C6: =D6-B6 -> 45570.7 | D6: =E6+F6 -> 65101 | E6: 13750 | F6: 51351 | G6: 2730 | H6: =IFERROR(B6/C6,0) -> 0.42857143 | I6: =SUM($D$2:D6)-SUM($G$2:G6) -> 151402 | K6: =A5 -> 44931 | L6: =N6*0.39 -> 3966.69 | M6: =N6-L6 -> 6204.31 | N6: =O6+P6 -> 10171 | O6: =VLOOKUP(K6,$A$1:$H$37,5,0) -> 9421 | P6: =VLOOKUP(K6,$A$1:$H$37,6,0) -> 750 | Q6: =VLOOKUP(K6,$A$1:$H$37,7,0) -> 3590
A7: 44933 | B7: =D7*0.3 -> 2805 | C7: =D7-B7 -> 6545 | D7: =E7+F7 -> 9350 | E7: 4480 | F7: 4870 | G7: 170 | H7: =IFERROR(B7/C7,0) -> 0.42857143 | I7: =SUM($D$2:D7)-SUM($G$2:G7) -> 160582 | K7: =A6 -> 44932 | L7: =N7*0.39 -> 25389.39 | M7: =N7-L7 -> 39711.61 | N7: =O7+P7 -> 65101 | O7: =VLOOKUP(K7,$A$1:$H$37,5,0) -> 13750 | P7: =VLOOKUP(K7,$A$1:$H$37,6,0) -> 51351 | Q7: =VLOOKUP(K7,$A$1:$H$37,7,0) -> 2730
A8: 44934 | B8: =D8*0.3 -> 6366 | C8: =D8-B8 -> 14854 | D8: =E8+F8 -> 21220 | E8: 12070 | F8: 9150 | G8: 8700 | H8: =IFERROR(B8/C8,0) -> 0.42857143 | I8: =SUM($D$2:D8)-SUM($G$2:G8) -> 173102 | K8: =A7 -> 44933 | L8: =N8*0.39 -> 3646.5 | M8: =N8-L8 -> 5703.5 | N8: =O8+P8 -> 9350 | O8: =VLOOKUP(K8,$A$1:$H$37,5,0) -> 4480 | P8: =VLOOKUP(K8,$A$1:$H$37,6,0) -> 4870 | Q8: =VLOOKUP(K8,$A$1:$H$37,7,0) -> 170
A9: 44935 | B9: =D9*0.3 -> 3033 | C9: =D9-B9 -> 7077 | D9: =E9+F9 -> 10110 | E9: 6680 | F9: =2880+550 -> 3430 | G9: 400 | H9: =IFERROR(B9/C9,0) -> 0.42857143 | I9: =SUM($D$2:D9)-SUM($G$2:G9) -> 182812 | K9: =A8 -> 44934 | L9: =N9*0.39 -> 8275.8 | M9: =N9-L9 -> 12944.2 | N9: =O9+P9 -> 21220 | O9: =VLOOKUP(K9,$A$1:$H$37,5,0) -> 12070 | P9: =VLOOKUP(K9,$A$1:$H$37,6,0) -> 9150 | Q9: =VLOOKUP(K9,$A$1:$H$37,7,0) -> 8700
A10: 44936 | B10: =D10*0.3 -> 6240 | C10: =D10-B10 -> 14560 | D10: =E10+F10 -> 20800 | E10: 13260 | F10: 7540 | G10: 7100 | H10: =IFERROR(B10/C10,0) -> 0.42857143 | I10: =SUM($D$2:D10)-SUM($G$2:G10) -> 196512 | K10: Total | L10: =SUM(L3:L9) -> 73944.78 | M10: =SUM(M2:M9) -> 115657.22 | N10: =SUM(N2:N9) -> 189602 | O10: =SUM(O2:O9) -> 88221 | P10: =SUM(P2:P9) -> 101381 | Q10: =SUM(Q2:Q9) -> 16500
A11: 44937 | B11: =D11*0.3 -> 1782 | C11: =D11-B11 -> 4158 | D11: =E11+F11 -> 5940 | E11: 2710 | F11: 3230 | G11: 900 | H11: =IFERROR(B11/C11,0) -> 0.42857143 | I11: =SUM($D$2:D11)-SUM($G$2:G11) -> 201552 | K11: Mul Bhag | L11: =L10/3 -> 24648.26
A12: 44938 | B12: =D12*0.3 -> 10635.3 | C12: =D12-B12 -> 24815.7 | D12: =E12+F12 -> 35451 | E12: 30020 | F12: 5431 | G12: 4520 | H12: =IFERROR(B12/C12,0) -> 0.42857143 | I12: =SUM($D$2:D12)-SUM($G$2:G12) -> 232483
A13: 44939 | B13: =D13*0.3 -> 9395.4 | C13: =D13-B13 -> 21922.6 | D13: =E13+F13 -> 31318 | E13: 24638 | F13: 6680 | G13: 2310 | H13: =IFERROR(B13/C13,0) -> 0.42857143 | I13: =SUM($D$2:D13)-SUM($G$2:G13) -> 261491 | K13: Date | L13: Profit | M13: Actual | N13: Total | O13: Cash | P13: Account Transfer | Q13: Expense
A14: 44940 | B14: =D14*0.3 -> 4305 | C14: =D14-B14 -> 10045 | D14: =E14+F14 -> 14350 | E14: 6460 | F14: 7890 | G14: 560 | H14: =IFERROR(B14/C14,0) -> 0.42857143 | I14: =SUM($D$2:D14)-SUM($G$2:G14) -> 275281 | K14: =A9 -> 44935 | L14: =N14*0.39 -> 3942.9 | M14: =N14-L14 -> 6167.1 | N14: =O14+P14 -> 10110 | O14: =VLOOKUP(K14,$A$1:$H$37,5,0) -> 6680 | P14: =VLOOKUP(K14,$A$1:$H$37,6,0) -> 3430 | Q14: =VLOOKUP(K14,$A$1:$H$37,7,0) -> 400
A15: 44941 | B15: =D15*0.3 -> 1981.2 | C15: =D15-B15 -> 4622.8 | D15: =E15+F15 -> 6604 | E15: 4124 | F15: 2480 | G15: 100 | H15: =IFERROR(B15/C15,0) -> 0.42857143 | I15: =SUM($D$2:D15)-SUM($G$2:G15) -> 281785 | K15: =A10 -> 44936 | L15: =N15*0.39 -> 8112 | M15: =N15-L15 -> 12688 | N15: =O15+P15 -> 20800 | O15: =VLOOKUP(K15,$A$1:$H$37,5,0) -> 13260 | P15: =VLOOKUP(K15,$A$1:$H$37,6,0) -> 7540 | Q15: =VLOOKUP(K15,$A$1:$H$37,7,0) -> 7100
A16: 44942 | B16: =D16*0.3 -> 5217 | C16: =D16-B16 -> 12173 | D16: =E16+F16 -> 17390 | E16: 8240 | F16: 9150 | G16: 3100 | H16: =IFERROR(B16/C16,0) -> 0.42857143 | I16: =SUM($D$2:D16)-SUM($G$2:G16) -> 296075 | K16: =A11 -> 44937 | L16: =N16*0.39 -> 2316.6 | M16: =N16-L16 -> 3623.4 | N16: =O16+P16 -> 5940 | O16: =VLOOKUP(K16,$A$1:$H$37,5,0) -> 2710 | P16: =VLOOKUP(K16,$A$1:$H$37,6,0) -> 3230 | Q16: =VLOOKUP(K16,$A$1:$H$37,7,0) -> 900
A17: 44943 | B17: =D17*0.3 -> 6028.5 | C17: =D17-B17 -> 14066.5 | D17: =E17+F17 -> 20095 | E17: 7350 | F17: 12745 | G17: 160 | H17: =IFERROR(B17/C17,0) -> 0.42857143 | I17: =SUM($D$2:D17)-SUM($G$2:G17) -> 316010 | K17: =A12 -> 44938 | L17: =N17*0.39 -> 13825.89 | M17: =N17-L17 -> 21625.11 | N17: =O17+P17 -> 35451 | O17: =VLOOKUP(K17,$A$1:$H$37,5,0) -> 30020 | P17: =VLOOKUP(K17,$A$1:$H$37,6,0) -> 5431 | Q17: =VLOOKUP(K17,$A$1:$H$37,7,0) -> 4520
A18: 44944 | B18: =D18*0.3 -> 1839 | C18: =D18-B18 -> 4291 | D18: =E18+F18 -> 6130 | E18: 600 | F18: 5530 | G18: 60 | H18: =IFERROR(B18/C18,0) -> 0.42857143 | I18: =SUM($D$2:D18)-SUM($G$2:G18) -> 322080 | K18: =A13 -> 44939 | L18: =N18*0.39 -> 12214.02 | M18: =N18-L18 -> 19103.98 | N18: =O18+P18 -> 31318 | O18: =VLOOKUP(K18,$A$1:$H$37,5,0) -> 24638 | P18: =VLOOKUP(K18,$A$1:$H$37,6,0) -> 6680 | Q18: =VLOOKUP(K18,$A$1:$H$37,7,0) -> 2310
A19: 44945 | B19: =D19*0.3 -> 2760 | C19: =D19-B19 -> 6440 | D19: =E19+F19 -> 9200 | E19: 6600 | F19: 2600 | G19: 100 | H19: =IFERROR(B19/C19,0) -> 0.42857143 | I19: =SUM($D$2:D19)-SUM($G$2:G19) -> 331180 | K19: =A14 -> 44940 | L19: =N19*0.39 -> 5596.5 | M19: =N19-L19 -> 8753.5 | N19: =O19+P19 -> 14350 | O19: =VLOOKUP(K19,$A$1:$H$37,5,0) -> 6460 | P19: =VLOOKUP(K19,$A$1:$H$37,6,0) -> 7890 | Q19: =VLOOKUP(K19,$A$1:$H$37,7,0) -> 560
A20: 44946 | B20: =D20*0.3 -> 9960 | C20: =D20-B20 -> 23240 | D20: =E20+F20 -> 33200 | E20: 11990 | F20: 21210 | G20: 6060 | H20: =IFERROR(B20/C20,0) -> 0.42857143 | I20: =SUM($D$2:D20)-SUM($G$2:G20) -> 358320 | K20: =A15 -> 44941 | L20: =N20*0.39 -> 2575.56 | M20: =N20-L20 -> 4028.44 | N20: =O20+P20 -> 6604 | O20: =VLOOKUP(K20,$A$1:$H$37,5,0) -> 4124 | P20: =VLOOKUP(K20,$A$1:$H$37,6,0) -> 2480 | Q20: =VLOOKUP(K20,$A$1:$H$37,7,0) -> 100
A21: 44947 | B21: =D21*0.3 -> 5310 | C21: =D21-B21 -> 12390 | D21: =E21+F21 -> 17700 | E21: 11200 | F21: 6500 | G21: 60 | H21: =IFERROR(B21/C21,0) -> 0.42857143 | I21: =SUM($D$2:D21)-SUM($G$2:G21) -> 375960 | K21: Total | L21: =SUM(L14:L20) -> 48583.47 | M21: =SUM(M14:M20) -> 75989.53 | N21: =SUM(N14:N20) -> 124573 | O21: =SUM(O14:O20) -> 87892 | P21: =SUM(P14:P20) -> 36681 | Q21: =SUM(Q14:Q20) -> 15890
A22: 44948 | B22: =D22*0.3 -> 1278 | C22: =D22-B22 -> 2982 | D22: =E22+F22 -> 4260 | E22: 4160 | F22: 100 | G22: 100 | H22: =IFERROR(B22/C22,0) -> 0.42857143 | I22: =SUM($D$2:D22)-SUM($G$2:G22) -> 380120 | K22: Mul Bhag | L22: =L21/3 -> 16194.49
A23: 44949 | B23: =D23*0.3 -> 2934 | C23: =D23-B23 -> 6846 | D23: =E23+F23 -> 9780 | E23: 5580 | F23: 4200 | G23: 140 | H23: =IFERROR(B23/C23,0) -> 0.42857143 | I23: =SUM($D$2:D23)-SUM($G$2:G23) -> 389760
A24: 44950 | B24: =D24*0.3 -> 2191.5 | C24: =D24-B24 -> 5113.5 | D24: =E24+F24 -> 7305 | E24: 4730 | F24: 2575 | G24: 260 | H24: =IFERROR(B24/C24,0) -> 0.42857143 | I24: =SUM($D$2:D24)-SUM($G$2:G24) -> 396805 | K24: Date | L24: Profit | M24: Actual | N24: Total | O24: Cash | P24: Account Transfer | Q24: Expense
A25: 44951 | B25: =D25*0.3 -> 4194 | C25: =D25-B25 -> 9786 | D25: =E25+F25 -> 13980 | E25: 10140 | F25: 3840 | G25: 260 | H25: =IFERROR(B25/C25,0) -> 0.42857143 | I25: =SUM($D$2:D25)-SUM($G$2:G25) -> 410525 | K25: =A16 -> 44942 | L25: =N25*0.39 -> 6782.1 | M25: =N25-L25 -> 10607.9 | N25: =O25+P25 -> 17390 | O25: =VLOOKUP(K25,$A$1:$H$37,5,0) -> 8240 | P25: =VLOOKUP(K25,$A$1:$H$37,6,0) -> 9150 | Q25: =VLOOKUP(K25,$A$1:$H$37,7,0) -> 3100
A26: 44952 | B26: =D26*0.3 -> 1204.5 | C26: =D26-B26 -> 2810.5 | D26: =E26+F26 -> 4015 | E26: 3585 | F26: 430 | G26: 435 | H26: =IFERROR(B26/C26,0) -> 0.42857143 | I26: =SUM($D$2:D26)-SUM($G$2:G26) -> 414105 | K26: =A17 -> 44943 | L26: =N26*0.39 -> 7837.05 | M26: =N26-L26 -> 12257.95 | N26: =O26+P26 -> 20095 | O26: =VLOOKUP(K26,$A$1:$H$37,5,0) -> 7350 | P26: =VLOOKUP(K26,$A$1:$H$37,6,0) -> 12745 | Q26: =VLOOKUP(K26,$A$1:$H$37,7,0) -> 160
A27: 44953 | B27: =D27*0.3 -> 8373 | C27: =D27-B27 -> 19537 | D27: =E27+F27 -> 27910 | E27: 10180 | F27: 17730 | G27: 1360 | H27: =IFERROR(B27/C27,0) -> 0.42857143 | I27: =SUM($D$2:D27)-SUM($G$2:G27) -> 440655 | K27: =A18 -> 44944 | L27: =N27*0.39 -> 2390.7 | M27: =N27-L27 -> 3739.3 | N27: =O27+P27 -> 6130 | O27: =VLOOKUP(K27,$A$1:$H$37,5,0) -> 600 | P27: =VLOOKUP(K27,$A$1:$H$37,6,0) -> 5530 | Q27: =VLOOKUP(K27,$A$1:$H$37,7,0) -> 60
A28: 44954 | B28: =D28*0.3 -> 10746 | C28: =D28-B28 -> 25074 | D28: =E28+F28 -> 35820 | E28: 18090 | F28: 17730 | G28: 1360 | H28: =IFERROR(B28/C28,0) -> 0.42857143 | I28: =SUM($D$2:D28)-SUM($G$2:G28) -> 475115 | K28: =A19 -> 44945 | L28: =N28*0.39 -> 3588 | M28: =N28-L28 -> 5612 | N28: =O28+P28 -> 9200 | O28: =VLOOKUP(K28,$A$1:$H$37,5,0) -> 6600 | P28: =VLOOKUP(K28,$A$1:$H$37,6,0) -> 2600 | Q28: =VLOOKUP(K28,$A$1:$H$37,7,0) -> 100
A29: 44955 | B29: =D29*0.3 -> 4564.5 | C29: =D29-B29 -> 10650.5 | D29: =E29+F29 -> 15215 | E29: 5735 | F29: 9480 | G29: 2000 | H29: =IFERROR(B29/C29,0) -> 0.42857143 | I29: =SUM($D$2:D29)-SUM($G$2:G29) -> 488330 | K29: =A20 -> 44946 | L29: =N29*0.39 -> 12948 | M29: =N29-L29 -> 20252 | N29: =O29+P29 -> 33200 | O29: =VLOOKUP(K29,$A$1:$H$37,5,0) -> 11990 | P29: =VLOOKUP(K29,$A$1:$H$37,6,0) -> 21210 | Q29: =VLOOKUP(K29,$A$1:$H$37,7,0) -> 6060
A30: 44956 | B30: =D30*0.3 -> 3597 | C30: =D30-B30 -> 8393 | D30: =E30+F30 -> 11990 | E30: 6735 | F30: 5255 | G30: 1165 | H30: =IFERROR(B30/C30,0) -> 0.42857143 | I30: =SUM($D$2:D30)-SUM($G$2:G30) -> 499155 | K30: =A21 -> 44947 | L30: =N30*0.39 -> 6903 | M30: =N30-L30 -> 10797 | N30: =O30+P30 -> 17700 | O30: =VLOOKUP(K30,$A$1:$H$37,5,0) -> 11200 | P30: =VLOOKUP(K30,$A$1:$H$37,6,0) -> 6500 | Q30: =VLOOKUP(K30,$A$1:$H$37,7,0) -> 60
A31: 44957 | B31: =D31*0.3 -> 10233 | C31: =D31-B31 -> 23877 | D31: =E31+F31 -> 34110 | E31: 13510 | F31: 20600 | G31: 100 | H31: =IFERROR(B31/C31,0) -> 0.42857143 | I31: =SUM($D$2:D31)-SUM($G$2:G31) -> 533165 | K31: =A22 -> 44948 | L31: =N31*0.39 -> 1661.4 | M31: =N31-L31 -> 2598.6 | N31: =O31+P31 -> 4260 | O31: =VLOOKUP(K31,$A$1:$H$37,5,0) -> 4160 | P31: =VLOOKUP(K31,$A$1:$H$37,6,0) -> 100 | Q31: =VLOOKUP(K31,$A$1:$H$37,7,0) -> 100
A32: 44958 | B32: =D32*0.3 -> 5409 | C32: =D32-B32 -> 12621 | D32: =E32+F32 -> 18030 | E32: 8610 | F32: 9420 | G32: 6110 | H32: =IFERROR(B32/C32,0) -> 0.42857143 | I32: =SUM($D$2:D32)-SUM($G$2:G32) -> 545085 | K32: Total | L32: =SUM(L25:L31) -> 42110.25 | M32: =SUM(M25:M31) -> 65864.75 | N32: =SUM(N25:N31) -> 107975 | O32: =SUM(O25:O31) -> 50140 | P32: =SUM(P25:P31) -> 57835 | Q32: =SUM(Q25:Q31) -> 9640
A33: 44959 | B33: =D33*0.3 -> 6147 | C33: =D33-B33 -> 14343 | D33: =E33+F33 -> 20490 | E33: 17450 | F33: 3040 | G33: 5250 | H33: =IFERROR(B33/C33,0) -> 0.42857143 | I33: =SUM($D$2:D33)-SUM($G$2:G33) -> 560325 | K33: Mul Bhag | L33: =L32/3 -> 14036.75
A34: 44960 | B34: =D34*0.3 -> 6354 | C34: =D34-B34 -> 14826 | D34: =E34+F34 -> 21180 | E34: 11880 | F34: 9300 | G34: 200 | H34: =IFERROR(B34/C34,0) -> 0.42857143 | I34: =SUM($D$2:D34)-SUM($G$2:G34) -> 581305
A35: 44961 | B35: =D35*0.3 -> 7572 | C35: =D35-B35 -> 17668 | D35: =E35+F35 -> 25240 | E35: 17070 | F35: 8170 | G35: 5720 | H35: =IFERROR(B35/C35,0) -> 0.42857143 | I35: =SUM($D$2:D35)-SUM($G$2:G35) -> 600825 | K35: Date | L35: Profit | M35: Actual | N35: Total | O35: Cash | P35: Account Transfer | Q35: Expense
A36: 44962 | B36: =D36*0.3 -> 3457.5 | C36: =D36-B36 -> 8067.5 | D36: =E36+F36 -> 11525 | E36: 6615 | F36: 4910 | G36: 450 | H36: =IFERROR(B36/C36,0) -> 0.42857143 | I36: =SUM($D$2:D36)-SUM($G$2:G36) -> 611900 | K36: =A23 -> 44949 | L36: =N36*0.39 -> 3814.2 | M36: =N36-L36 -> 5965.8 | N36: =O36+P36 -> 9780 | O36: =VLOOKUP(K36,$A$1:$H$37,5,0) -> 5580 | P36: =VLOOKUP(K36,$A$1:$H$37,6,0) -> 4200 | Q36: =VLOOKUP(K36,$A$1:$H$37,7,0) -> 140
A37: Total | B37: =SUM(B3:B31) -> 173440.5 | C37: =SUM(C3:C31) -> 404694.5 | D37: =SUM(D3:D31) -> 578135 | E37: =SUM(E3:E31) -> 300478 | F37: =SUM(F3:F31) -> 277657 | G37: =SUM(G3:G31) -> 49010 | H37: =SUM(H3:H31) -> 12.428571 | I37: =SUM(I3:I31) -> 8760853 | K37: =A24 -> 44950 | L37: =N37*0.39 -> 2848.95 | M37: =N37-L37 -> 4456.05 | N37: =O37+P37 -> 7305 | O37: =VLOOKUP(K37,$A$1:$H$37,5,0) -> 4730 | P37: =VLOOKUP(K37,$A$1:$H$37,6,0) -> 2575 | Q37: =VLOOKUP(K37,$A$1:$H$37,7,0) -> 260
B38: =B37/3 -> 57813.5 | E38: =D37*0.42 -> 242816.7 | K38: =A25 -> 44951 | L38: =N38*0.39 -> 5452.2 | M38: =N38-L38 -> 8527.8 | N38: =O38+P38 -> 13980 | O38: =VLOOKUP(K38,$A$1:$H$37,5,0) -> 10140 | P38: =VLOOKUP(K38,$A$1:$H$37,6,0) -> 3840 | Q38: =VLOOKUP(K38,$A$1:$H$37,7,0) -> 260
B39: =B38*100/D37 -> 10 | E39: =E38/3 -> 80938.9 | K39: =A26 -> 44952 | L39: =N39*0.39 -> 1565.85 | M39: =N39-L39 -> 2449.15 | N39: =O39+P39 -> 4015 | O39: =VLOOKUP(K39,$A$1:$H$37,5,0) -> 3585 | P39: =VLOOKUP(K39,$A$1:$H$37,6,0) -> 430 | Q39: =VLOOKUP(K39,$A$1:$H$37,7,0) -> 435
K40: =A27 -> 44953 | L40: =N40*0.39 -> 10884.9 | M40: =N40-L40 -> 17025.1 | N40: =O40+P40 -> 27910 | O40: =VLOOKUP(K40,$A$1:$H$37,5,0) -> 10180 | P40: =VLOOKUP(K40,$A$1:$H$37,6,0) -> 17730 | Q40: =VLOOKUP(K40,$A$1:$H$37,7,0) -> 1360
...

Sheet Febuary 2023
A1: Date | B1: Profit | C1: Actual | D1: Total | E1: Cash | F1: Account Transfer | G1: Expense | H1: Percentage | I1: Cash In Hand | K1: Date | L1: Profit | M1: Actual | N1: Total | O1: Cash | P1: Account Transfer | Q1: Expense
A2: 44956 | B2: =D2*0.3 -> 3597 | C2: =D2-B2 -> 8393 | D2: =E2+F2 -> 11990 | E2: 6735 | F2: 5255 | G2: 1165 | H2: =IFERROR(B2/C2,0) -> 0.42857143 | I2: =SUM($D$2:D2)-SUM($G$2:G2) -> 10825 | K2: Export | Q2: 0
A3: 44957 | B3: =D3*0.3 -> 10233 | C3: =D3-B3 -> 23877 | D3: =E3+F3 -> 34110 | E3: 13510 | F3: 20600 | G3: 100 | H3: =IFERROR(B3/C3,0) -> 0.42857143 | I3: =SUM($D$2:D3)-SUM($G$2:G3) -> 44835 | K3: =A2 -> 44956 | L3: =N3*0.39 -> 4676.1 | M3: =N3-L3 -> 7313.9 | N3: =O3+P3 -> 11990 | O3: =VLOOKUP(K3,$A$1:$H$37,5,0) -> 6735 | P3: =VLOOKUP(K3,$A$1:$H$37,6,0) -> 5255 | Q3: =VLOOKUP(K3,$A$1:$H$37,7,0) -> 1165
A4: 44958 | B4: =D4*0.3 -> 5409 | C4: =D4-B4 -> 12621 | D4: =E4+F4 -> 18030 | E4: 8610 | F4: 9420 | G4: 6110 | H4: =IFERROR(B4/C4,0) -> 0.42857143 | I4: =SUM($D$2:D4)-SUM($G$2:G4) -> 56755 | K4: =A3 -> 44957 | L4: =N4*0.39 -> 13302.9 | M4: =N4-L4 -> 20807.1 | N4: =O4+P4 -> 34110 | O4: =VLOOKUP(K4,$A$1:$H$37,5,0) -> 13510 | P4: =VLOOKUP(K4,$A$1:$H$37,6,0) -> 20600 | Q4: =VLOOKUP(K4,$A$1:$H$37,7,0) -> 100
A5: 44959 | B5: =D5*0.3 -> 6147 | C5: =D5-B5 -> 14343 | D5: =E5+F5 -> 20490 | E5: 17450 | F5: 3040 | G5: 5250 | H5: =IFERROR(B5/C5,0) -> 0.42857143 | I5: =SUM($D$2:D5)-SUM($G$2:G5) -> 71995 | K5: =A4 -> 44958 | L5: =N5*0.39 -> 7031.7 | M5: =N5-L5 -> 10998.3 | N5: =O5+P5 -> 18030 | O5: =VLOOKUP(K5,$A$1:$H$37,5,0) -> 8610 | P5: =VLOOKUP(K5,$A$1:$H$37,6,0) -> 9420 | Q5: =VLOOKUP(K5,$A$1:$H$37,7,0) -> 6110
A6: 44960 | B6: =D6*0.3 -> 6354 | C6: =D6-B6 -> 14826 | D6: =E6+F6 -> 21180 | E6: 11880 | F6: 9300 | G6: 200 | H6: =IFERROR(B6/C6,0) -> 0.42857143 | I6: =SUM($D$2:D6)-SUM($G$2:G6) -> 92975 | K6: =A5 -> 44959 | L6: =N6*0.39 -> 7991.1 | M6: =N6-L6 -> 12498.9 | N6: =O6+P6 -> 20490 | O6: =VLOOKUP(K6,$A$1:$H$37,5,0) -> 17450 | P6: =VLOOKUP(K6,$A$1:$H$37,6,0) -> 3040 | Q6: =VLOOKUP(K6,$A$1:$H$37,7,0) -> 5250
A7: 44961 | B7: =D7*0.3 -> 7572 | C7: =D7-B7 -> 17668 | D7: =E7+F7 -> 25240 | E7: 17070 | F7: 8170 | G7: 5720 | H7: =IFERROR(B7/C7,0) -> 0.42857143 | I7: =SUM($D$2:D7)-SUM($G$2:G7) -> 112495 | K7: =A6 -> 44960 | L7: =N7*0.39 -> 8260.2 | M7: =N7-L7 -> 12919.8 | N7: =O7+P7 -> 21180 | O7: =VLOOKUP(K7,$A$1:$H$37,5,0) -> 11880 | P7: =VLOOKUP(K7,$A$1:$H$37,6,0) -> 9300 | Q7: =VLOOKUP(K7,$A$1:$H$37,7,0) -> 200
A8: 44962 | B8: =D8*0.3 -> 3457.5 | C8: =D8-B8 -> 8067.5 | D8: =E8+F8 -> 11525 | E8: 6615 | F8: 4910 | G8: 450 | H8: =IFERROR(B8/C8,0) -> 0.42857143 | I8: =SUM($D$2:D8)-SUM($G$2:G8) -> 123570 | K8: =A7 -> 44961 | L8: =N8*0.39 -> 9843.6 | M8: =N8-L8 -> 15396.4 | N8: =O8+P8 -> 25240 | O8: =VLOOKUP(K8,$A$1:$H$37,5,0) -> 17070 | P8: =VLOOKUP(K8,$A$1:$H$37,6,0) -> 8170 | Q8: =VLOOKUP(K8,$A$1:$H$37,7,0) -> 5720
A9: 44963 | B9: =D9*0.3 -> 3883.5 | C9: =D9-B9 -> 9061.5 | D9: =E9+F9 -> 12945 | E9: 3825 | F9: 9120 | G9: 1100 | H9: =IFERROR(B9/C9,0) -> 0.42857143 | I9: =SUM($D$2:D9)-SUM($G$2:G9) -> 135415 | K9: =A8 -> 44962 | L9: =N9*0.39 -> 4494.75 | M9: =N9-L9 -> 7030.25 | N9: =O9+P9 -> 11525 | O9: =VLOOKUP(K9,$A$1:$H$37,5,0) -> 6615 | P9: =VLOOKUP(K9,$A$1:$H$37,6,0) -> 4910 | Q9: =VLOOKUP(K9,$A$1:$H$37,7,0) -> 450
A10: 44964 | B10: =D10*0.3 -> 10995.6 | C10: =D10-B10 -> 25656.4 | D10: =E10+F10 -> 36652 | E10: 26892 | F10: 9760 | G10: 1020 | H10: =IFERROR(B10/C10,0) -> 0.42857143 | I10: =SUM($D$2:D10)-SUM($G$2:G10) -> 171047 | K10: Total | L10: =SUM(L3:L9) -> 55600.35 | M10: =SUM(M2:M9) -> 86964.65 | N10: =SUM(N2:N9) -> 142565 | O10: =SUM(O2:O9) -> 81870 | P10: =SUM(P2:P9) -> 60695 | Q10: =SUM(Q2:Q9) -> 18995
A11: 44965 | B11: =D11*0.3 -> 6683.7 | C11: =D11-B11 -> 15595.3 | D11: =E11+F11 -> 22279 | E11: 15235 | F11: 7044 | G11: 1920 | H11: =IFERROR(B11/C11,0) -> 0.42857143 | I11: =SUM($D$2:D11)-SUM($G$2:G11) -> 191406 | K11: Mul Bhag | L11: =L10/3 -> 18533.45
A12: 44966 | B12: =D12*0.3 -> 26995.5 | C12: =D12-B12 -> 62989.5 | D12: =E12+F12 -> 89985 | E12: 3750 | F12: 86235 | G12: 220 | H12: =IFERROR(B12/C12,0) -> 0.42857143 | I12: =SUM($D$2:D12)-SUM($G$2:G12) -> 281171
A13: 44967 | B13: =D13*0.3 -> 4899 | C13: =D13-B13 -> 11431 | D13: =E13+F13 -> 16330 | E13: 11890 | F13: 4440 | G13: 3890 | H13: =IFERROR(B13/C13,0) -> 0.42857143 | I13: =SUM($D$2:D13)-SUM($G$2:G13) -> 293611 | K13: Date | L13: Profit | M13: Actual | N13: Total | O13: Cash | P13: Account Transfer | Q13: Expense
A14: 44968 | B14: =D14*0.3 -> 17361 | C14: =D14-B14 -> 40509 | D14: =E14+F14 -> 57870 | E14: =33890+430 -> 34320 | F14: 23550 | G14: 2000 | H14: =IFERROR(B14/C14,0) -> 0.42857143 | I14: =SUM($D$2:D14)-SUM($G$2:G14) -> 349481 | K14: =A9 -> 44963 | L14: =N14*0.39 -> 5048.55 | M14: =N14-L14 -> 7896.45 | N14: =O14+P14 -> 12945 | O14: =VLOOKUP(K14,$A$1:$H$37,5,0) -> 3825 | P14: =VLOOKUP(K14,$A$1:$H$37,6,0) -> 9120 | Q14: =VLOOKUP(K14,$A$1:$H$37,7,0) -> 1100
A15: 44969 | B15: =D15*0.3 -> 12788.7 | C15: =D15-B15 -> 29840.3 | D15: =E15+F15 -> 42629 | E15: 9300 | F15: 33329 | G15: 220 | H15: =IFERROR(B15/C15,0) -> 0.42857143 | I15: =SUM($D$2:D15)-SUM($G$2:G15) -> 391890 | K15: =A10 -> 44964 | L15: =N15*0.39 -> 14294.28 | M15: =N15-L15 -> 22357.72 | N15: =O15+P15 -> 36652 | O15: =VLOOKUP(K15,$A$1:$H$37,5,0) -> 26892 | P15: =VLOOKUP(K15,$A$1:$H$37,6,0) -> 9760 | Q15: =VLOOKUP(K15,$A$1:$H$37,7,0) -> 1020
A16: 44970 | B16: =D16*0.3 -> 5730 | C16: =D16-B16 -> 13370 | D16: =E16+F16 -> 19100 | E16: 10300 | F16: 8800 | G16: 2700 | H16: =IFERROR(B16/C16,0) -> 0.42857143 | I16: =SUM($D$2:D16)-SUM($G$2:G16) -> 408290 | K16: =A11 -> 44965 | L16: =N16*0.39 -> 8688.81 | M16: =N16-L16 -> 13590.19 | N16: =O16+P16 -> 22279 | O16: =VLOOKUP(K16,$A$1:$H$37,5,0) -> 15235 | P16: =VLOOKUP(K16,$A$1:$H$37,6,0) -> 7044 | Q16: =VLOOKUP(K16,$A$1:$H$37,7,0) -> 1920
A17: 44971 | B17: =D17*0.3 -> 3387 | C17: =D17-B17 -> 7903 | D17: =E17+F17 -> 11290 | E17: 9870 | F17: 1420 | G17: 1130 | H17: =IFERROR(B17/C17,0) -> 0.42857143 | I17: =SUM($D$2:D17)-SUM($G$2:G17) -> 418450 | K17: =A12 -> 44966 | L17: =N17*0.39 -> 35094.15 | M17: =N17-L17 -> 54890.85 | N17: =O17+P17 -> 89985 | O17: =VLOOKUP(K17,$A$1:$H$37,5,0) -> 3750 | P17: =VLOOKUP(K17,$A$1:$H$37,6,0) -> 86235 | Q17: =VLOOKUP(K17,$A$1:$H$37,7,0) -> 220
A18: 44972 | B18: =D18*0.3 -> 2955 | C18: =D18-B18 -> 6895 | D18: =E18+F18 -> 9850 | E18: 7320 | F18: 2530 | G18: 17660 | H18: =IFERROR(B18/C18,0) -> 0.42857143 | I18: =SUM($D$2:D18)-SUM($G$2:G18) -> 410640 | K18: =A13 -> 44967 | L18: =N18*0.39 -> 6368.7 | M18: =N18-L18 -> 9961.3 | N18: =O18+P18 -> 16330 | O18: =VLOOKUP(K18,$A$1:$H$37,5,0) -> 11890 | P18: =VLOOKUP(K18,$A$1:$H$37,6,0) -> 4440 | Q18: =VLOOKUP(K18,$A$1:$H$37,7,0) -> 3890
A19: 44973 | B19: =D19*0.3 -> 3078 | C19: =D19-B19 -> 7182 | D19: =E19+F19 -> 10260 | E19: 1100 | F19: 9160 | G19: 0 | H19: =IFERROR(B19/C19,0) -> 0.42857143 | I19: =SUM($D$2:D19)-SUM($G$2:G19) -> 420900 | K19: =A14 -> 44968 | L19: =N19*0.39 -> 22569.3 | M19: =N19-L19 -> 35300.7 | N19: =O19+P19 -> 57870 | O19: =VLOOKUP(K19,$A$1:$H$37,5,0) -> 34320 | P19: =VLOOKUP(K19,$A$1:$H$37,6,0) -> 23550 | Q19: =VLOOKUP(K19,$A$1:$H$37,7,0) -> 2000
A20: 44974 | B20: =D20*0.3 -> 3985.5 | C20: =D20-B20 -> 9299.5 | D20: =E20+F20 -> 13285 | E20: 7220 | F20: 6065 | G20: 500 | H20: =IFERROR(B20/C20,0) -> 0.42857143 | I20: =SUM($D$2:D20)-SUM($G$2:G20) -> 433685 | K20: =A15 -> 44969 | L20: =N20*0.39 -> 16625.31 | M20: =N20-L20 -> 26003.69 | N20: =O20+P20 -> 42629 | O20: =VLOOKUP(K20,$A$1:$H$37,5,0) -> 9300 | P20: =VLOOKUP(K20,$A$1:$H$37,6,0) -> 33329 | Q20: =VLOOKUP(K20,$A$1:$H$37,7,0) -> 220
A21: 44975 | B21: =D21*0.3 -> 13852.5 | C21: =D21-B21 -> 32322.5 | D21: =E21+F21 -> 46175 | E21: 17640 | F21: 28535 | G21: 1200 | H21: =IFERROR(B21/C21,0) -> 0.42857143 | I21: =SUM($D$2:D21)-SUM($G$2:G21) -> 478660 | K21: Total | L21: =SUM(L14:L20) -> 108689.1 | M21: =SUM(M14:M20) -> 170000.9 | N21: =SUM(N14:N20) -> 278690 | O21: =SUM(O14:O20) -> 105212 | P21: =SUM(P14:P20) -> 173478 | Q21: =SUM(Q14:Q20) -> 10370
A22: 44976 | B22: =D22*0.3 -> 4338 | C22: =D22-B22 -> 10122 | D22: =E22+F22 -> 14460 | E22: 13490 | F22: 970 | G22: 2070 | H22: =IFERROR(B22/C22,0) -> 0.42857143 | I22: =SUM($D$2:D22)-SUM($G$2:G22) -> 491050 | K22: Mul Bhag | L22: =L21/3 -> 36229.7
A23: 44977 | B23: =D23*0.3 -> 1923 | C23: =D23-B23 -> 4487 | D23: =E23+F23 -> 6410 | E23: 5490 | F23: 920 | G23: 13200 | H23: =IFERROR(B23/C23,0) -> 0.42857143 | I23: =SUM($D$2:D23)-SUM($G$2:G23) -> 484260
A24: 44978 | B24: =D24*0.3 -> 4680 | C24: =D24-B24 -> 10920 | D24: =E24+F24 -> 15600 | E24: 10500 | F24: 5100 | G24: 830 | H24: =IFERROR(B24/C24,0) -> 0.42857143 | I24: =SUM($D$2:D24)-SUM($G$2:G24) -> 499030 | K24: Date | L24: Profit | M24: Actual | N24: Total | O24: Cash | P24: Account Transfer | Q24: Expense
A25: 44979 | B25: =D25*0.3 -> 17379 | C25: =D25-B25 -> 40551 | D25: =E25+F25 -> 57930 | E25: 9050 | F25: 48880 | G25: 1300 | H25: =IFERROR(B25/C25,0) -> 0.42857143 | I25: =SUM($D$2:D25)-SUM($G$2:G25) -> 555660 | K25: =A16 -> 44970 | L25: =N25*0.39 -> 7449 | M25: =N25-L25 -> 11651 | N25: =O25+P25 -> 19100 | O25: =VLOOKUP(K25,$A$1:$H$37,5,0) -> 10300 | P25: =VLOOKUP(K25,$A$1:$H$37,6,0) -> 8800 | Q25: =VLOOKUP(K25,$A$1:$H$37,7,0) -> 2700
A26: 44980 | B26: =D26*0.3 -> 18929.1 | C26: =D26-B26 -> 44167.9 | D26: =E26+F26 -> 63097 | E26: 45240 | F26: 17857 | G26: 770 | H26: =IFERROR(B26/C26,0) -> 0.42857143 | I26: =SUM($D$2:D26)-SUM($G$2:G26) -> 617987 | K26: =A17 -> 44971 | L26: =N26*0.39 -> 4403.1 | M26: =N26-L26 -> 6886.9 | N26: =O26+P26 -> 11290 | O26: =VLOOKUP(K26,$A$1:$H$37,5,0) -> 9870 | P26: =VLOOKUP(K26,$A$1:$H$37,6,0) -> 1420 | Q26: =VLOOKUP(K26,$A$1:$H$37,7,0) -> 1130
A27: 44981 | B27: =D27*0.3 -> 6217.5 | C27: =D27-B27 -> 14507.5 | D27: =E27+F27 -> 20725 | E27: 13860 | F27: 6865 | G27: 1100 | H27: =IFERROR(B27/C27,0) -> 0.42857143 | I27: =SUM($D$2:D27)-SUM($G$2:G27) -> 637612 | K27: =A18 -> 44972 | L27: =N27*0.39 -> 3841.5 | M27: =N27-L27 -> 6008.5 | N27: =O27+P27 -> 9850 | O27: =VLOOKUP(K27,$A$1:$H$37,5,0) -> 7320 | P27: =VLOOKUP(K27,$A$1:$H$37,6,0) -> 2530 | Q27: =VLOOKUP(K27,$A$1:$H$37,7,0) -> 17660
A28: 44982 | B28: =D28*0.3 -> 6785.1 | C28: =D28-B28 -> 15831.9 | D28: =E28+F28 -> 22617 | E28: 11205 | F28: 11412 | G28: 140 | H28: =IFERROR(B28/C28,0) -> 0.42857143 | I28: =SUM($D$2:D28)-SUM($G$2:G28) -> 660089 | K28: =A19 -> 44973 | L28: =N28*0.39 -> 4001.4 | M28: =N28-L28 -> 6258.6 | N28: =O28+P28 -> 10260 | O28: =VLOOKUP(K28,$A$1:$H$37,5,0) -> 1100 | P28: =VLOOKUP(K28,$A$1:$H$37,6,0) -> 9160 | Q28: =VLOOKUP(K28,$A$1:$H$37,7,0) -> 0
A29: 44983 | B29: =D29*0.3 -> 6699 | C29: =D29-B29 -> 15631 | D29: =E29+F29 -> 22330 | E29: =19270+360 -> 19630 | F29: 2700 | G29: 2200 | H29: =IFERROR(B29/C29,0) -> 0.42857143 | I29: =SUM($D$2:D29)-SUM($G$2:G29) -> 680219 | K29: =A20 -> 44974 | L29: =N29*0.39 -> 5181.15 | M29: =N29-L29 -> 8103.85 | N29: =O29+P29 -> 13285 | O29: =VLOOKUP(K29,$A$1:$H$37,5,0) -> 7220 | P29: =VLOOKUP(K29,$A$1:$H$37,6,0) -> 6065 | Q29: =VLOOKUP(K29,$A$1:$H$37,7,0) -> 500
A30: 44984 | B30: =D30*0.3 -> 5644.5 | C30: =D30-B30 -> 13170.5 | D30: =E30+F30 -> 18815 | E30: 11110 | F30: 7705 | G30: 100 | H30: =IFERROR(B30/C30,0) -> 0.42857143 | I30: =SUM($D$2:D30)-SUM($G$2:G30) -> 698934 | K30: =A21 -> 44975 | L30: =N30*0.39 -> 18008.25 | M30: =N30-L30 -> 28166.75 | N30: =O30+P30 -> 46175 | O30: =VLOOKUP(K30,$A$1:$H$37,5,0) -> 17640 | P30: =VLOOKUP(K30,$A$1:$H$37,6,0) -> 28535 | Q30: =VLOOKUP(K30,$A$1:$H$37,7,0) -> 1200
A31: 44985 | B31: =D31*0.3 -> 8643 | C31: =D31-B31 -> 20167 | D31: =E31+F31 -> 28810 | E31: 22460 | F31: 6350 | G31: 230 | H31: =IFERROR(B31/C31,0) -> 0.42857143 | I31: =SUM($D$2:D31)-SUM($G$2:G31) -> 727514 | K31: =A22 -> 44976 | L31: =N31*0.39 -> 5639.4 | M31: =N31-L31 -> 8820.6 | N31: =O31+P31 -> 14460 | O31: =VLOOKUP(K31,$A$1:$H$37,5,0) -> 13490 | P31: =VLOOKUP(K31,$A$1:$H$37,6,0) -> 970 | Q31: =VLOOKUP(K31,$A$1:$H$37,7,0) -> 2070
A32: 44986 | B32: =D32*0.3 -> 0 | C32: =D32-B32 -> 0 | D32: =E32+F32 -> 0 | H32: =IFERROR(B32/C32,0) -> 0 | I32: =SUM($D$2:D32)-SUM($G$2:G32) -> 727514 | K32: Total | L32: =SUM(L25:L31) -> 48523.8 | M32: =SUM(M25:M31) -> 75896.2 | N32: =SUM(N25:N31) -> 124420 | O32: =SUM(O25:O31) -> 66940 | P32: =SUM(P25:P31) -> 57480 | Q32: =SUM(Q25:Q31) -> 25260
A33: 44987 | B33: =D33*0.3 -> 0 | C33: =D33-B33 -> 0 | D33: =E33+F33 -> 0 | H33: =IFERROR(B33/C33,0) -> 0 | I33: =SUM($D$2:D33)-SUM($G$2:G33) -> 727514 | K33: Mul Bhag | L33: =L32/3 -> 16174.6
A34: 44988 | B34: =D34*0.3 -> 0 | C34: =D34-B34 -> 0 | D34: =E34+F34 -> 0 | H34: =IFERROR(B34/C34,0) -> 0 | I34: =SUM($D$2:D34)-SUM($G$2:G34) -> 727514
A35: 44989 | B35: =D35*0.3 -> 0 | C35: =D35-B35 -> 0 | D35: =E35+F35 -> 0 | H35: =IFERROR(B35/C35,0) -> 0 | I35: =SUM($D$2:D35)-SUM($G$2:G35) -> 727514 | K35: Date | L35: Profit | M35: Actual | N35: Total | O35: Cash | P35: Account Transfer | Q35: Expense
A36: 44990 | B36: =D36*0.3 -> 0 | C36: =D36-B36 -> 0 | D36: =E36+F36 -> 0 | H36: =IFERROR(B36/C36,0) -> 0 | I36: =SUM($D$2:D36)-SUM($G$2:G36) -> 727514 | K36: =A23 -> 44977 | L36: =N36*0.39 -> 2499.9 | M36: =N36-L36 -> 3910.1 | N36: =O36+P36 -> 6410 | O36: =VLOOKUP(K36,$A$1:$H$37,5,0) -> 5490 | P36: =VLOOKUP(K36,$A$1:$H$37,6,0) -> 920 | Q36: =VLOOKUP(K36,$A$1:$H$37,7,0) -> 13200
A37: Total | B37: =SUM(B4:B36) -> 226772.7 | C37: =SUM(C4:C36) -> 529136.3 | D37: =SUM(D4:D36) -> 755909 | E37: =SUM(E4:E36) -> 382322 | F37: =SUM(F4:F36) -> 373587 | G37: =SUM(G4:G36) -> 73230 | H37: =SUM(H4:H36) -> 12 | I37: =SUM(I4:I36) -> 14532361 | K37: =A24 -> 44978 | L37: =N37*0.39 -> 6084 | M37: =N37-L37 -> 9516 | N37: =O37+P37 -> 15600 | O37: =VLOOKUP(K37,$A$1:$H$37,5,0) -> 10500 | P37: =VLOOKUP(K37,$A$1:$H$37,6,0) -> 5100 | Q37: =VLOOKUP(K37,$A$1:$H$37,7,0) -> 830
B38: =B37/3 -> 75590.9 | E38: =D37*0.42 -> 317481.78 | K38: =A25 -> 44979 | L38: =N38*0.39 -> 22592.7 | M38: =N38-L38 -> 35337.3 | N38: =O38+P38 -> 57930 | O38: =VLOOKUP(K38,$A$1:$H$37,5,0) -> 9050 | P38: =VLOOKUP(K38,$A$1:$H$37,6,0) -> 48880 | Q38: =VLOOKUP(K38,$A$1:$H$37,7,0) -> 1300
B39: =B38*100/D37 -> 10 | E39: =E38/3 -> 105827.26 | K39: =A26 -> 44980 | L39: =N39*0.39 -> 24607.83 | M39: =N39-L39 -> 38489.17 | N39: =O39+P39 -> 63097 | O39: =VLOOKUP(K39,$A$1:$H$37,5,0) -> 45240 | P39: =VLOOKUP(K39,$A$1:$H$37,6,0) -> 17857 | Q39: =VLOOKUP(K39,$A$1:$H$37,7,0) -> 770
A40: Date | B40: Profit | C40: Actual | D40: Total | E40: Cash | F40: Account Transfer | G40: Expense | H40: Mul Bhag | K40: =A27 -> 44981 | L40: =N40*0.39 -> 8082.75 | M40: =N40-L40 -> 12642.25 | N40: =O40+P40 -> 20725 | O40: =VLOOKUP(K40,$A$1:$H$37,5,0) -> 13860 | P40: =VLOOKUP(K40,$A$1:$H$37,6,0) -> 6865 | Q40: =VLOOKUP(K40,$A$1:$H$37,7,0) -> 1100
...

Sheet March 2023
A1: Date | B1: Profit | C1: Actual | D1: Total | E1: Cash | F1: Account Transfer | G1: Expense | H1: Percentage | I1: Cash In Hand | K1: Date | L1: Profit | M1: Actual | N1: Total | O1: Cash | P1: Account Transfer | Q1: Expense
A2: 44984 | B2: =D2*0.39 -> 7337.85 | C2: =D2-B2 -> 11477.15 | D2: =E2+F2 -> 18815 | E2: 11110 | F2: 7705 | G2: 100 | H2: =IFERROR(B2/C2,0) -> 0.63934426 | I2: =SUM($D$2:D2)-SUM($G$2:G2) -> 18715 | K2: Export | Q2: 0
A3: 44985 | B3: =D3*0.39 -> 11235.9 | C3: =D3-B3 -> 17574.1 | D3: 28810 | E3: 22460 | F3: 6350 | G3: 230 | H3: =IFERROR(B3/C3,0) -> 0.63934426 | I3: =SUM($D$2:D3)-SUM($G$2:G3) -> 47295 | K3: =A2 -> 44984 | L3: =N3*0.39 -> 7337.85 | M3: =N3-L3 -> 11477.15 | N3: =O3+P3 -> 18815 | O3: =VLOOKUP(K3,$A$1:$H$37,5,0) -> 11110 | P3: =VLOOKUP(K3,$A$1:$H$37,6,0) -> 7705 | Q3: =VLOOKUP(K3,$A$1:$H$37,7,0) -> 100
A4: 44986 | B4: =D4*0.39 -> 4849.65 | C4: =D4-B4 -> 7585.35 | D4: 12435 | E4: 8725 | F4: 3710 | G4: 5140 | H4: =IFERROR(B4/C4,0) -> 0.63934426 | I4: =SUM($D$2:D4)-SUM($G$2:G4) -> 54590 | K4: =A3 -> 44985 | L4: =N4*0.39 -> 11235.9 | M4: =N4-L4 -> 17574.1 | N4: =O4+P4 -> 28810 | O4: =VLOOKUP(K4,$A$1:$H$37,5,0) -> 22460 | P4: =VLOOKUP(K4,$A$1:$H$37,6,0) -> 6350 | Q4: =VLOOKUP(K4,$A$1:$H$37,7,0) -> 230
A5: 44987 | B5: =D5*0.39 -> 3798.6 | C5: =D5-B5 -> 5941.4 | D5: 9740 | E5: 6610 | F5: 3130 | G5: 300 | H5: =IFERROR(B5/C5,0) -> 0.63934426 | I5: =SUM($D$2:D5)-SUM($G$2:G5) -> 64030 | K5: =A4 -> 44986 | L5: =N5*0.39 -> 4849.65 | M5: =N5-L5 -> 7585.35 | N5: =O5+P5 -> 12435 | O5: =VLOOKUP(K5,$A$1:$H$37,5,0) -> 8725 | P5: =VLOOKUP(K5,$A$1:$H$37,6,0) -> 3710 | Q5: =VLOOKUP(K5,$A$1:$H$37,7,0) -> 5140
A6: 44988 | B6: =D6*0.39 -> 3572.4 | C6: =D6-B6 -> 5587.6 | D6: 9160 | E6: 5020 | F6: 4140 | G6: 19200 | H6: =IFERROR(B6/C6,0) -> 0.63934426 | I6: =SUM($D$2:D6)-SUM($G$2:G6) -> 53990 | K6: =A5 -> 44987 | L6: =N6*0.39 -> 3798.6 | M6: =N6-L6 -> 5941.4 | N6: =O6+P6 -> 9740 | O6: =VLOOKUP(K6,$A$1:$H$37,5,0) -> 6610 | P6: =VLOOKUP(K6,$A$1:$H$37,6,0) -> 3130 | Q6: =VLOOKUP(K6,$A$1:$H$37,7,0) -> 300
A7: 44989 | B7: =D7*0.39 -> 9151.35 | C7: =D7-B7 -> 14313.65 | D7: 23465 | E7: 12665 | F7: 10800 | G7: 15935 | H7: =IFERROR(B7/C7,0) -> 0.63934426 | I7: =SUM($D$2:D7)-SUM($G$2:G7) -> 61520 | K7: =A6 -> 44988 | L7: =N7*0.39 -> 3572.4 | M7: =N7-L7 -> 5587.6 | N7: =O7+P7 -> 9160 | O7: =VLOOKUP(K7,$A$1:$H$37,5,0) -> 5020 | P7: =VLOOKUP(K7,$A$1:$H$37,6,0) -> 4140 | Q7: =VLOOKUP(K7,$A$1:$H$37,7,0) -> 19200
A8: 44990 | B8: =D8*0.39 -> 18335.85 | C8: =D8-B8 -> 28679.15 | D8: 47015 | E8: 25600 | F8: 21415 | G8: 12600 | H8: =IFERROR(B8/C8,0) -> 0.63934426 | I8: =SUM($D$2:D8)-SUM($G$2:G8) -> 95935 | K8: =A7 -> 44989 | L8: =N8*0.39 -> 9151.35 | M8: =N8-L8 -> 14313.65 | N8: =O8+P8 -> 23465 | O8: =VLOOKUP(K8,$A$1:$H$37,5,0) -> 12665 | P8: =VLOOKUP(K8,$A$1:$H$37,6,0) -> 10800 | Q8: =VLOOKUP(K8,$A$1:$H$37,7,0) -> 15935
A9: 44991 | B9: =D9*0.39 -> 4688.58 | C9: =D9-B9 -> 7333.42 | D9: =E9+F9 -> 12022 | E9: 4760 | F9: 7262 | G9: 100 | H9: =IFERROR(B9/C9,0) -> 0.63934426 | I9: =SUM($D$2:D9)-SUM($G$2:G9) -> 107857 | K9: =A8 -> 44990 | L9: =N9*0.39 -> 18335.85 | M9: =N9-L9 -> 28679.15 | N9: =O9+P9 -> 47015 | O9: =VLOOKUP(K9,$A$1:$H$37,5,0) -> 25600 | P9: =VLOOKUP(K9,$A$1:$H$37,6,0) -> 21415 | Q9: =VLOOKUP(K9,$A$1:$H$37,7,0) -> 12600
A10: 44992 | B10: =D10*0.39 -> 0 | C10: =D10-B10 -> 0 | D10: =E10+F10 -> 0 | E10: 0 | H10: =IFERROR(B10/C10,0) -> 0 | I10: =SUM($D$2:D10)-SUM($G$2:G10) -> 107857 | K10: Total | L10: =SUM(L3:L9) -> 58281.6 | M10: =SUM(M2:M9) -> 91158.4 | N10: =SUM(N2:N9) -> 149440 | O10: =SUM(O2:O9) -> 92190 | P10: =SUM(P2:P9) -> 57250 | Q10: =SUM(Q2:Q9) -> 53505
A11: 44993 | B11: =D11*0.39 -> 21536.19 | C11: =D11-B11 -> 33684.81 | D11: =E11+F11 -> 55221 | E11: 7450 | F11: =47771 -> 47771 | G11: 200 | H11: =IFERROR(B11/C11,0) -> 0.63934426 | I11: =SUM($D$2:D11)-SUM($G$2:G11) -> 162878 | K11: Mul Bhag | L11: =L10/3 -> 19427.2
A12: 44994 | B12: =D12*0.39 -> 11230.05 | C12: =D12-B12 -> 17564.95 | D12: =E12+F12 -> 28795 | E12: 8450 | F12: 20345 | G12: 1880 | H12: =IFERROR(B12/C12,0) -> 0.63934426 | I12: =SUM($D$2:D12)-SUM($G$2:G12) -> 189793
A13: 44995 | B13: =D13*0.39 -> 1823.25 | C13: =D13-B13 -> 2851.75 | D13: =E13+F13 -> 4675 | E13: 3975 | F13: 700 | G13: 2200 | H13: =IFERROR(B13/C13,0) -> 0.63934426 | I13: =SUM($D$2:D13)-SUM($G$2:G13) -> 192268 | K13: Date | L13: Profit | M13: Actual | N13: Total | O13: Cash | P13: Account Transfer | Q13: Expense
A14: 44996 | B14: =D14*0.39 -> 7597.2 | C14: =D14-B14 -> 11882.8 | D14: =E14+F14 -> 19480 | E14: 8810 | F14: 10670 | G14: 3270 | H14: =IFERROR(B14/C14,0) -> 0.63934426 | I14: =SUM($D$2:D14)-SUM($G$2:G14) -> 208478 | K14: =A9 -> 44991 | L14: =N14*0.39 -> 4688.58 | M14: =N14-L14 -> 7333.42 | N14: =O14+P14 -> 12022 | O14: =VLOOKUP(K14,$A$1:$H$37,5,0) -> 4760 | P14: =VLOOKUP(K14,$A$1:$H$37,6,0) -> 7262 | Q14: =VLOOKUP(K14,$A$1:$H$37,7,0) -> 100
A15: 44997 | B15: =D15*0.39 -> 9180.6 | C15: =D15-B15 -> 14359.4 | D15: =E15+F15 -> 23540 | E15: 15765 | F15: 7775 | G15: 4200 | H15: =IFERROR(B15/C15,0) -> 0.63934426 | I15: =SUM($D$2:D15)-SUM($G$2:G15) -> 227818 | K15: =A10 -> 44992 | L15: =N15*0.39 -> 0 | M15: =N15-L15 -> 0 | N15: =O15+P15 -> 0 | O15: =VLOOKUP(K15,$A$1:$H$37,5,0) -> 0 | P15: =VLOOKUP(K15,$A$1:$H$37,6,0) -> 0 | Q15: =VLOOKUP(K15,$A$1:$H$37,7,0) -> 0
A16: 44998 | B16: =D16*0.39 -> 1620.45 | C16: =D16-B16 -> 2534.55 | D16: =E16+F16 -> 4155 | E16: 3175 | F16: 980 | G16: 230 | H16: =IFERROR(B16/C16,0) -> 0.63934426 | I16: =SUM($D$2:D16)-SUM($G$2:G16) -> 231743 | K16: =A11 -> 44993 | L16: =N16*0.3 -> 16566.3 | M16: =N16-L16 -> 38654.7 | N16: =O16+P16 -> 55221 | O16: =VLOOKUP(K16,$A$1:$H$37,5,0) -> 7450 | P16: =VLOOKUP(K16,$A$1:$H$37,6,0) -> 47771 | Q16: =VLOOKUP(K16,$A$1:$H$37,7,0) -> 200
A17: 44999 | B17: =D17*0.39 -> 2000.7 | C17: =D17-B17 -> 3129.3 | D17: =E17+F17 -> 5130 | E17: 3350 | F17: 1780 | G17: 150 | H17: =IFERROR(B17/C17,0) -> 0.63934426 | I17: =SUM($D$2:D17)-SUM($G$2:G17) -> 236723 | K17: =A12 -> 44994 | L17: =N17*0.3 -> 8638.5 | M17: =N17-L17 -> 20156.5 | N17: =O17+P17 -> 28795 | O17: =VLOOKUP(K17,$A$1:$H$37,5,0) -> 8450 | P17: =VLOOKUP(K17,$A$1:$H$37,6,0) -> 20345 | Q17: =VLOOKUP(K17,$A$1:$H$37,7,0) -> 1880
A18: 45000 | B18: =D18*0.39 -> 7597.2 | C18: =D18-B18 -> 11882.8 | D18: =E18+F18 -> 19480 | E18: 10570 | F18: 8910 | G18: 3620 | H18: =IFERROR(B18/C18,0) -> 0.63934426 | I18: =SUM($D$2:D18)-SUM($G$2:G18) -> 252583 | K18: =A13 -> 44995 | L18: =N18*0.39 -> 1823.25 | M18: =N18-L18 -> 2851.75 | N18: =O18+P18 -> 4675 | O18: =VLOOKUP(K18,$A$1:$H$37,5,0) -> 3975 | P18: =VLOOKUP(K18,$A$1:$H$37,6,0) -> 700 | Q18: =VLOOKUP(K18,$A$1:$H$37,7,0) -> 2200
A19: 45001 | B19: =D19*0.39 -> 15296.97 | C19: =D19-B19 -> 23926.03 | D19: =E19+F19 -> 39223 | E19: 7360 | F19: 31863 | G19: 1600 | H19: =IFERROR(B19/C19,0) -> 0.63934426 | I19: =SUM($D$2:D19)-SUM($G$2:G19) -> 290206 | K19: =A14 -> 44996 | L19: =N19*0.39 -> 7597.2 | M19: =N19-L19 -> 11882.8 | N19: =O19+P19 -> 19480 | O19: =VLOOKUP(K19,$A$1:$H$37,5,0) -> 8810 | P19: =VLOOKUP(K19,$A$1:$H$37,6,0) -> 10670 | Q19: =VLOOKUP(K19,$A$1:$H$37,7,0) -> 3270
A20: 45002 | B20: =D20*0.39 -> 4317.3 | C20: =D20-B20 -> 6752.7 | D20: =E20+F20 -> 11070 | E20: =5280+1800 -> 7080 | F20: =3240+750 -> 3990 | G20: 900 | H20: =IFERROR(B20/C20,0) -> 0.63934426 | I20: =SUM($D$2:D20)-SUM($G$2:G20) -> 300376 | K20: =A15 -> 44997 | L20: =N20*0.3 -> 7062 | M20: =N20-L20 -> 16478 | N20: =O20+P20 -> 23540 | O20: =VLOOKUP(K20,$A$1:$H$37,5,0) -> 15765 | P20: =VLOOKUP(K20,$A$1:$H$37,6,0) -> 7775 | Q20: =VLOOKUP(K20,$A$1:$H$37,7,0) -> 4200
A21: 45003 | B21: =D21*0.39 -> 7761 | C21: =D21-B21 -> 12139 | D21: =E21+F21 -> 19900 | E21: =5120+1080 -> 6200 | F21: 13700 | G21: 3600 | H21: =IFERROR(B21/C21,0) -> 0.63934426 | I21: =SUM($D$2:D21)-SUM($G$2:G21) -> 316676 | K21: Total | L21: =SUM(L14:L20) -> 46375.83 | M21: =SUM(M14:M20) -> 97357.17 | N21: =SUM(N14:N20) -> 143733 | O21: =SUM(O14:O20) -> 49210 | P21: =SUM(P14:P20) -> 94523 | Q21: =SUM(Q14:Q20) -> 11850
A22: 45004 | B22: =D22*0.39 -> 6576.57 | C22: =D22-B22 -> 10286.43 | D22: =E22+F22 -> 16863 | E22: =7285+4260 -> 11545 | F22: 5318 | G22: 600 | H22: =IFERROR(B22/C22,0) -> 0.63934426 | I22: =SUM($D$2:D22)-SUM($G$2:G22) -> 332939 | K22: Mul Bhag | L22: =L21/3 -> 15458.61
A23: 45005 | B23: =D23*0.39 -> 4722.9 | C23: =D23-B23 -> 7387.1 | D23: =E23+F23 -> 12110 | E23: 3980 | F23: 8130 | G23: 900 | H23: =IFERROR(B23/C23,0) -> 0.63934426 | I23: =SUM($D$2:D23)-SUM($G$2:G23) -> 344149
A24: 45006 | B24: =D24*0.39 -> 17961.45 | C24: =D24-B24 -> 28093.55 | D24: =E24+F24 -> 46055 | E24: 29915 | F24: 16140 | G24: 100 | H24: =IFERROR(B24/C24,0) -> 0.63934426 | I24: =SUM($D$2:D24)-SUM($G$2:G24) -> 390104 | K24: Date | L24: Profit | M24: Actual | N24: Total | O24: Cash | P24: Account Transfer | Q24: Expense
A25: 45007 | B25: =D25*0.39 -> 5619.9 | C25: =D25-B25 -> 8790.1 | D25: =E25+F25 -> 14410 | E25: 11070 | F25: 3340 | G25: 3130 | H25: =IFERROR(B25/C25,0) -> 0.63934426 | I25: =SUM($D$2:D25)-SUM($G$2:G25) -> 401384 | K25: =A16 -> 44998 | L25: =N25*0.39 -> 1620.45 | M25: =N25-L25 -> 2534.55 | N25: =O25+P25 -> 4155 | O25: =VLOOKUP(K25,$A$1:$H$37,5,0) -> 3175 | P25: =VLOOKUP(K25,$A$1:$H$37,6,0) -> 980 | Q25: =VLOOKUP(K25,$A$1:$H$37,7,0) -> 230
A26: 45008 | B26: =D26*0.39 -> 8819.46 | C26: =D26-B26 -> 13794.54 | D26: =E26+F26 -> 22614 | E26: 14390 | F26: 8224 | G26: 35100 | H26: =IFERROR(B26/C26,0) -> 0.63934426 | I26: =SUM($D$2:D26)-SUM($G$2:G26) -> 388898 | K26: =A17 -> 44999 | L26: =N26*0.39 -> 2000.7 | M26: =N26-L26 -> 3129.3 | N26: =O26+P26 -> 5130 | O26: =VLOOKUP(K26,$A$1:$H$37,5,0) -> 3350 | P26: =VLOOKUP(K26,$A$1:$H$37,6,0) -> 1780 | Q26: =VLOOKUP(K26,$A$1:$H$37,7,0) -> 150
A27: 45009 | B27: =D27*0.39 -> 20330.7 | C27: =D27-B27 -> 31799.3 | D27: =E27+F27 -> 52130 | E27: 8450 | F27: 43680 | G27: 3100 | H27: =IFERROR(B27/C27,0) -> 0.63934426 | I27: =SUM($D$2:D27)-SUM($G$2:G27) -> 437928 | K27: =A18 -> 45000 | L27: =N27*0.39 -> 7597.2 | M27: =N27-L27 -> 11882.8 | N27: =O27+P27 -> 19480 | O27: =VLOOKUP(K27,$A$1:$H$37,5,0) -> 10570 | P27: =VLOOKUP(K27,$A$1:$H$37,6,0) -> 8910 | Q27: =VLOOKUP(K27,$A$1:$H$37,7,0) -> 3620
A28: 45010 | B28: =D28*0.39 -> 6895.2 | C28: =D28-B28 -> 10784.8 | D28: =E28+F28 -> 17680 | E28: 3940 | F28: 13740 | G28: 2600 | H28: =IFERROR(B28/C28,0) -> 0.63934426 | I28: =SUM($D$2:D28)-SUM($G$2:G28) -> 453008 | K28: =A19 -> 45001 | L28: =N28*0.39 -> 15296.97 | M28: =N28-L28 -> 23926.03 | N28: =O28+P28 -> 39223 | O28: =VLOOKUP(K28,$A$1:$H$37,5,0) -> 7360 | P28: =VLOOKUP(K28,$A$1:$H$37,6,0) -> 31863 | Q28: =VLOOKUP(K28,$A$1:$H$37,7,0) -> 1600
A29: 45011 | B29: =D29*0.39 -> 8697 | C29: =D29-B29 -> 13603 | D29: =E29+F29 -> 22300 | E29: 16300 | F29: 6000 | G29: 6120 | H29: =IFERROR(B29/C29,0) -> 0.63934426 | I29: =SUM($D$2:D29)-SUM($G$2:G29) -> 469188 | K29: =A20 -> 45002 | L29: =N29*0.39 -> 4317.3 | M29: =N29-L29 -> 6752.7 | N29: =O29+P29 -> 11070 | O29: =VLOOKUP(K29,$A$1:$H$37,5,0) -> 7080 | P29: =VLOOKUP(K29,$A$1:$H$37,6,0) -> 3990 | Q29: =VLOOKUP(K29,$A$1:$H$37,7,0) -> 900
A30: 45012 | B30: =D30*0.39 -> 4048.2 | C30: =D30-B30 -> 6331.8 | D30: =E30+F30 -> 10380 | E30: 7630 | F30: 2750 | G30: 9840 | H30: =IFERROR(B30/C30,0) -> 0.63934426 | I30: =SUM($D$2:D30)-SUM($G$2:G30) -> 469728 | K30: =A21 -> 45003 | L30: =N30*0.39 -> 7761 | M30: =N30-L30 -> 12139 | N30: =O30+P30 -> 19900 | O30: =VLOOKUP(K30,$A$1:$H$37,5,0) -> 6200 | P30: =VLOOKUP(K30,$A$1:$H$37,6,0) -> 13700 | Q30: =VLOOKUP(K30,$A$1:$H$37,7,0) -> 3600
A31: 45013 | B31: =D31*0.39 -> 21983.52 | C31: =D31-B31 -> 34384.48 | D31: =E31+F31 -> 56368 | E31: 9120 | F31: 47248 | G31: =2280+1200 -> 3480 | H31: =IFERROR(B31/C31,0) -> 0.63934426 | I31: =SUM($D$2:D31)-SUM($G$2:G31) -> 522616 | K31: =A22 -> 45004 | L31: =N31*0.39 -> 6576.57 | M31: =N31-L31 -> 10286.43 | N31: =O31+P31 -> 16863 | O31: =VLOOKUP(K31,$A$1:$H$37,5,0) -> 11545 | P31: =VLOOKUP(K31,$A$1:$H$37,6,0) -> 5318 | Q31: =VLOOKUP(K31,$A$1:$H$37,7,0) -> 600
A32: 45014 | B32: =D32*0.39 -> 11294.01 | C32: =D32-B32 -> 17664.99 | D32: =E32+F32 -> 28959 | E32: =9130+670 -> 9800 | F32: 19159 | G32: 2500 | H32: =IFERROR(B32/C32,0) -> 0.63934426 | I32: =SUM($D$2:D32)-SUM($G$2:G32) -> 549075 | K32: Total | L32: =SUM(L25:L31) -> 45170.19 | M32: =SUM(M25:M31) -> 70650.81 | N32: =SUM(N25:N31) -> 115821 | O32: =SUM(O25:O31) -> 49280 | P32: =SUM(P25:P31) -> 66541 | Q32: =SUM(Q25:Q31) -> 10700
A33: 45015 | B33: =D33*0.39 -> 7012.59 | C33: =D33-B33 -> 10968.41 | D33: =E33+F33 -> 17981 | E33: 10730 | F33: 7251 | G33: 2500 | H33: =IFERROR(B33/C33,0) -> 0.63934426 | I33: =SUM($D$2:D33)-SUM($G$2:G33) -> 564556 | K33: Mul Bhag | L33: =L32/3 -> 15056.73
A34: 45016 | B34: =D34*0.39 -> 3088.8 | C34: =D34-B34 -> 4831.2 | D34: =E34+F34 -> 7920 | E34: 5720 | F34: 2200 | G34: 1000 | H34: =IFERROR(B34/C34,0) -> 0.63934426 | I34: =SUM($D$2:D34)-SUM($G$2:G34) -> 571476
A35: 45017 | B35: =D35*0.39 -> 8503.95 | C35: =D35-B35 -> 13301.05 | D35: =E35+F35 -> 21805 | E35: 14285 | F35: 7520 | G35: 200 | H35: =IFERROR(B35/C35,0) -> 0.63934426 | I35: =SUM($D$2:D35)-SUM($G$2:G35) -> 593081 | K35: Date | L35: Profit | M35: Actual | N35: Total | O35: Cash | P35: Account Transfer | Q35: Expense
A36: 45018 | B36: =D36*0.39 -> 13185.9 | C36: =D36-B36 -> 20624.1 | D36: =E36+F36 -> 33810 | E36: 23325 | F36: 10485 | G36: 6600 | H36: =IFERROR(B36/C36,0) -> 0.63934426 | I36: =SUM($D$2:D36)-SUM($G$2:G36) -> 620291 | K36: =A23 -> 45005 | L36: =N36*0.3 -> 3633 | M36: =N36-L36 -> 8477 | N36: =O36+P36 -> 12110 | O36: =VLOOKUP(K36,$A$1:$H$37,5,0) -> 3980 | P36: =VLOOKUP(K36,$A$1:$H$37,6,0) -> 8130 | Q36: =VLOOKUP(K36,$A$1:$H$37,7,0) -> 900
A37: Total | B37: =SUM(B4:B34) -> 261407.64 | C37: =SUM(C4:C34) -> 408868.36 | D37: =SUM(D4:D34) -> 670276 | E37: =SUM(E4:E34) -> 288155 | F37: =SUM(F4:F34) -> 382121 | G37: =SUM(G4:G34) -> 146095 | H37: =SUM(H4:H34) -> 19.180328 | I37: =SUM(I4:I34) -> 9050370 | K37: =A24 -> 45006 | L37: =N37*0.3 -> 13816.5 | M37: =N37-L37 -> 32238.5 | N37: =O37+P37 -> 46055 | O37: =VLOOKUP(K37,$A$1:$H$37,5,0) -> 29915 | P37: =VLOOKUP(K37,$A$1:$H$37,6,0) -> 16140 | Q37: =VLOOKUP(K37,$A$1:$H$37,7,0) -> 100
B38: =B37/3 -> 87135.88 | E38: =D37*0.42 -> 281515.92 | K38: =A25 -> 45007 | L38: =N38*0.3 -> 4323 | M38: =N38-L38 -> 10087 | N38: =O38+P38 -> 14410 | O38: =VLOOKUP(K38,$A$1:$H$37,5,0) -> 11070 | P38: =VLOOKUP(K38,$A$1:$H$37,6,0) -> 3340 | Q38: =VLOOKUP(K38,$A$1:$H$37,7,0) -> 3130
B39: =B38*100/D37 -> 13 | E39: =E38/3 -> 93838.64 | K39: =A26 -> 45008 | L39: =N39*0.3 -> 6784.2 | M39: =N39-L39 -> 15829.8 | N39: =O39+P39 -> 22614 | O39: =VLOOKUP(K39,$A$1:$H$37,5,0) -> 14390 | P39: =VLOOKUP(K39,$A$1:$H$37,6,0) -> 8224 | Q39: =VLOOKUP(K39,$A$1:$H$37,7,0) -> 35100
A40: Date | B40: Profit | C40: Actual | D40: Total | E40: Cash | F40: Account Transfer | G40: Expense | H40: Mul Bhag | K40: =A27 -> 45009 | L40: =N40*0.3 -> 15639 | M40: =N40-L40 -> 36491 | N40: =O40+P40 -> 52130 | O40: =VLOOKUP(K40,$A$1:$H$37,5,0) -> 8450 | P40: =VLOOKUP(K40,$A$1:$H$37,6,0) -> 43680 | Q40: =VLOOKUP(K40,$A$1:$H$37,7,0) -> 3100
...

Sheet April 2023
A1: Date | B1: Profit | C1: Actual | D1: Total | E1: Cash | F1: Account Transfer | G1: Expense | H1: Percentage | I1: Cash In Hand | J1: Glass | K1: Total | L1: Cash | M1: Account Transfer | O1: Date | P1: Profit | Q1: Actual | R1: Total | S1: Cash | T1: Account Transfer | U1: Expense
A2: 45012 | B2: =D2*0.39 -> 4048.2 | C2: =D2-B2 -> 6331.8 | D2: =E2+F2 -> 10380 | E2: 7630 | F2: 2750 | G2: 9840 | H2: =IFERROR(B2/C2,0) -> 0.63934426 | I2: =SUM($D$2:D2)-SUM($G$2:G2) -> 540 | K2: =L2+M2 -> 0 | O2: Export | U2: 0
A3: 45013 | B3: =D3*0.39 -> 21983.52 | C3: =D3-B3 -> 34384.48 | D3: =E3+F3 -> 56368 | E3: 9120 | F3: 47248 | G3: =2280+1200 -> 3480 | H3: =IFERROR(B3/C3,0) -> 0.63934426 | I3: =SUM($D$2:D3)-SUM($G$2:G3) -> 53428 | K3: =L3+M3 -> 0 | O3: =A2 -> 45012 | P3: =R3*0.3 -> 3114 | Q3: =R3-P3 -> 7266 | R3: =S3+T3 -> 10380 | S3: =VLOOKUP(O3,$A$1:$H$37,5,0) -> 7630 | T3: =VLOOKUP(O3,$A$1:$H$37,6,0) -> 2750 | U3: =VLOOKUP(O3,$A$1:$H$37,7,0) -> 9840
A4: 45014 | B4: =D4*0.39 -> 11294.01 | C4: =D4-B4 -> 17664.99 | D4: =E4+F4 -> 28959 | E4: =9130+670 -> 9800 | F4: 19159 | G4: 2500 | H4: =IFERROR(B4/C4,0) -> 0.63934426 | I4: =SUM($D$2:D4)-SUM($G$2:G4) -> 79887 | K4: =L4+M4 -> 0 | O4: =A3 -> 45013 | P4: =R4*0.3 -> 16910.4 | Q4: =R4-P4 -> 39457.6 | R4: =S4+T4 -> 56368 | S4: =VLOOKUP(O4,$A$1:$H$37,5,0) -> 9120 | T4: =VLOOKUP(O4,$A$1:$H$37,6,0) -> 47248 | U4: =VLOOKUP(O4,$A$1:$H$37,7,0) -> 3480
A5: 45015 | B5: =D5*0.39 -> 7012.59 | C5: =D5-B5 -> 10968.41 | D5: =E5+F5 -> 17981 | E5: 10730 | F5: 7251 | G5: 2500 | H5: =IFERROR(B5/C5,0) -> 0.63934426 | I5: =SUM($D$2:D5)-SUM($G$2:G5) -> 95368 | K5: =L5+M5 -> 0 | O5: =A4 -> 45014 | P5: =R5*0.3 -> 8687.7 | Q5: =R5-P5 -> 20271.3 | R5: =S5+T5 -> 28959 | S5: =VLOOKUP(O5,$A$1:$H$37,5,0) -> 9800 | T5: =VLOOKUP(O5,$A$1:$H$37,6,0) -> 19159 | U5: =VLOOKUP(O5,$A$1:$H$37,7,0) -> 2500
A6: 45016 | B6: =D6*0.39 -> 3088.8 | C6: =D6-B6 -> 4831.2 | D6: =E6+F6 -> 7920 | E6: 5720 | F6: 2200 | G6: 1000 | H6: =IFERROR(B6/C6,0) -> 0.63934426 | I6: =SUM($D$2:D6)-SUM($G$2:G6) -> 102288 | K6: =L6+M6 -> 0 | O6: =A5 -> 45015 | P6: =R6*0.3 -> 5394.3 | Q6: =R6-P6 -> 12586.7 | R6: =S6+T6 -> 17981 | S6: =VLOOKUP(O6,$A$1:$H$37,5,0) -> 10730 | T6: =VLOOKUP(O6,$A$1:$H$37,6,0) -> 7251 | U6: =VLOOKUP(O6,$A$1:$H$37,7,0) -> 2500
A7: 45017 | B7: =D7*0.39 -> 8503.95 | C7: =D7-B7 -> 13301.05 | D7: =E7+F7 -> 21805 | E7: 14285 | F7: 7520 | G7: 200 | H7: =IFERROR(B7/C7,0) -> 0.63934426 | I7: =SUM($D$2:D7)-SUM($G$2:G7) -> 123893 | J7: T0,T00 | K7: =L7+M7 -> 7800 | L7: 2160 | M7: 5640 | O7: =A6 -> 45016 | P7: =R7*0.3 -> 2376 | Q7: =R7-P7 -> 5544 | R7: =S7+T7 -> 7920 | S7: =VLOOKUP(O7,$A$1:$H$37,5,0) -> 5720 | T7: =VLOOKUP(O7,$A$1:$H$37,6,0) -> 2200 | U7: =VLOOKUP(O7,$A$1:$H$37,7,0) -> 1000
A8: 45018 | B8: =D8*0.39 -> 13185.9 | C8: =D8-B8 -> 20624.1 | D8: =E8+F8 -> 33810 | E8: 23325 | F8: 10485 | G8: 6600 | H8: =IFERROR(B8/C8,0) -> 0.63934426 | I8: =SUM($D$2:D8)-SUM($G$2:G8) -> 151103 | K8: =L8+M8 -> 8520 | L8: 8520 | O8: =A7 -> 45017 | P8: =R8*0.3 -> 6541.5 | Q8: =R8-P8 -> 15263.5 | R8: =S8+T8 -> 21805 | S8: =VLOOKUP(O8,$A$1:$H$37,5,0) -> 14285 | T8: =VLOOKUP(O8,$A$1:$H$37,6,0) -> 7520 | U8: =VLOOKUP(O8,$A$1:$H$37,7,0) -> 200
A9: 45019 | B9: =D9*0.39 -> 5091.84 | C9: =D9-B9 -> 7964.16 | D9: =E9+F9 -> 13056 | E9: 8572 | F9: 4484 | G9: 8400 | H9: =IFERROR(B9/C9,0) -> 0.63934426 | I9: =SUM($D$2:D9)-SUM($G$2:G9) -> 155759 | K9: =L9+M9 -> 1384 | L9: 1384 | O9: =A8 -> 45018 | P9: =R9*0.3 -> 10143 | Q9: =R9-P9 -> 23667 | R9: =S9+T9 -> 33810 | S9: =VLOOKUP(O9,$A$1:$H$37,5,0) -> 23325 | T9: =VLOOKUP(O9,$A$1:$H$37,6,0) -> 10485 | U9: =VLOOKUP(O9,$A$1:$H$37,7,0) -> 6600
A10: 45020 | B10: =D10*0.39 -> 7889.7 | C10: =D10-B10 -> 12340.3 | D10: =E10+F10 -> 20230 | E10: 9480 | F10: 10750 | G10: 2900 | H10: =IFERROR(B10/C10,0) -> 0.63934426 | I10: =SUM($D$2:D10)-SUM($G$2:G10) -> 173089 | K10: =L10+M10 -> 3830 | L10: 540 | M10: 3290 | O10: Total | P10: =SUM(P3:P9) -> 53166.9 | Q10: =SUM(Q2:Q9) -> 124056.1 | R10: =SUM(R2:R9) -> 177223 | S10: =SUM(S2:S9) -> 80610 | T10: =SUM(T2:T9) -> 96613 | U10: =SUM(U2:U9) -> 26120
A11: 45021 | B11: =D11*0.39 -> 12628.2 | C11: =D11-B11 -> 19751.8 | D11: =E11+F11 -> 32380 | E11: 17260 | F11: 15120 | G11: 9820 | H11: =IFERROR(B11/C11,0) -> 0.63934426 | I11: =SUM($D$2:D11)-SUM($G$2:G11) -> 195649 | K11: =L11+M11 -> 0 | O11: Mul Bhag | P11: =P10/3 -> 17722.3
A12: 45022 | B12: =D12*0.39 -> 1571.7 | C12: =D12-B12 -> 2458.3 | D12: =E12+F12 -> 4030 | E12: 2650 | F12: 1380 | G12: 200 | H12: =IFERROR(B12/C12,0) -> 0.63934426 | I12: =SUM($D$2:D12)-SUM($G$2:G12) -> 199479 | K12: =L12+M12 -> 0
A13: 45023 | B13: =D13*0.39 -> 5326.62 | C13: =D13-B13 -> 8331.38 | D13: =E13+F13 -> 13658 | E13: 9890 | F13: 3768 | G13: 660 | H13: =IFERROR(B13/C13,0) -> 0.63934426 | I13: =SUM($D$2:D13)-SUM($G$2:G13) -> 212477 | K13: =L13+M13 -> 0 | O13: Date | P13: Profit | Q13: Actual | R13: Total | S13: Cash | T13: Account Transfer | U13: Expense
A14: 45024 | B14: =D14*0.39 -> 5508.75 | C14: =D14-B14 -> 8616.25 | D14: =E14+F14 -> 14125 | E14: 8225 | F14: 5900 | G14: 3700 | H14: =IFERROR(B14/C14,0) -> 0.63934426 | I14: =SUM($D$2:D14)-SUM($G$2:G14) -> 222902 | K14: =L14+M14 -> 0 | O14: =A9 -> 45019 | P14: =R14*0.3 -> 3916.8 | Q14: =R14-P14 -> 9139.2 | R14: =S14+T14 -> 13056 | S14: =VLOOKUP(O14,$A$1:$H$37,5,0) -> 8572 | T14: =VLOOKUP(O14,$A$1:$H$37,6,0) -> 4484 | U14: =VLOOKUP(O14,$A$1:$H$37,7,0) -> 8400
A15: 45025 | B15: =D15*0.39 -> 6084 | C15: =D15-B15 -> 9516 | D15: =E15+F15 -> 15600 | E15: 13820 | F15: 1780 | G15: 100 | H15: =IFERROR(B15/C15,0) -> 0.63934426 | I15: =SUM($D$2:D15)-SUM($G$2:G15) -> 238402 | K15: =L15+M15 -> 0 | O15: =A10 -> 45020 | P15: =R15*0.3 -> 6069 | Q15: =R15-P15 -> 14161 | R15: =S15+T15 -> 20230 | S15: =VLOOKUP(O15,$A$1:$H$37,5,0) -> 9480 | T15: =VLOOKUP(O15,$A$1:$H$37,6,0) -> 10750 | U15: =VLOOKUP(O15,$A$1:$H$37,7,0) -> 2900
A16: 45026 | B16: =D16*0.39 -> 9059.7 | C16: =D16-B16 -> 14170.3 | D16: =E16+F16 -> 23230 | E16: 4280 | F16: 18950 | G16: 100 | H16: =IFERROR(B16/C16,0) -> 0.63934426 | I16: =SUM($D$2:D16)-SUM($G$2:G16) -> 261532 | K16: =L16+M16 -> 0 | O16: =A11 -> 45021 | P16: =R16*0.3 -> 9714 | Q16: =R16-P16 -> 22666 | R16: =S16+T16 -> 32380 | S16: =VLOOKUP(O16,$A$1:$H$37,5,0) -> 17260 | T16: =VLOOKUP(O16,$A$1:$H$37,6,0) -> 15120 | U16: =VLOOKUP(O16,$A$1:$H$37,7,0) -> 9820
A17: 45027 | B17: =D17*0.39 -> 6501.3 | C17: =D17-B17 -> 10168.7 | D17: =E17+F17 -> 16670 | E17: 6000 | F17: 10670 | G17: 27100 | H17: =IFERROR(B17/C17,0) -> 0.63934426 | I17: =SUM($D$2:D17)-SUM($G$2:G17) -> 251102 | K17: =L17+M17 -> 0 | O17: =A12 -> 45022 | P17: =R17*0.3 -> 1209 | Q17: =R17-P17 -> 2821 | R17: =S17+T17 -> 4030 | S17: =VLOOKUP(O17,$A$1:$H$37,5,0) -> 2650 | T17: =VLOOKUP(O17,$A$1:$H$37,6,0) -> 1380 | U17: =VLOOKUP(O17,$A$1:$H$37,7,0) -> 200
A18: 45028 | B18: =D18*0.39 -> 13263.9 | C18: =D18-B18 -> 20746.1 | D18: =E18+F18 -> 34010 | E18: 18710 | F18: 15300 | G18: 15700 | H18: =IFERROR(B18/C18,0) -> 0.63934426 | I18: =SUM($D$2:D18)-SUM($G$2:G18) -> 269412 | K18: =L18+M18 -> 0 | O18: =A13 -> 45023 | P18: =R18*0.3 -> 4097.4 | Q18: =R18-P18 -> 9560.6 | R18: =S18+T18 -> 13658 | S18: =VLOOKUP(O18,$A$1:$H$37,5,0) -> 9890 | T18: =VLOOKUP(O18,$A$1:$H$37,6,0) -> 3768 | U18: =VLOOKUP(O18,$A$1:$H$37,7,0) -> 660
A19: 45029 | B19: =D19*0.39 -> 4219.8 | C19: =D19-B19 -> 6600.2 | D19: =E19+F19 -> 10820 | E19: 9050 | F19: 1770 | G19: 3500 | H19: =IFERROR(B19/C19,0) -> 0.63934426 | I19: =SUM($D$2:D19)-SUM($G$2:G19) -> 276732 | K19: =L19+M19 -> 0 | O19: =A14 -> 45024 | P19: =R19*0.3 -> 4237.5 | Q19: =R19-P19 -> 9887.5 | R19: =S19+T19 -> 14125 | S19: =VLOOKUP(O19,$A$1:$H$37,5,0) -> 8225 | T19: =VLOOKUP(O19,$A$1:$H$37,6,0) -> 5900 | U19: =VLOOKUP(O19,$A$1:$H$37,7,0) -> 3700
A20: 45030 | B20: =D20*0.39 -> 6093.75 | C20: =D20-B20 -> 9531.25 | D20: =E20+F20 -> 15625 | E20: 11800 | F20: 3825 | G20: 1090 | H20: =IFERROR(B20/C20,0) -> 0.63934426 | I20: =SUM($D$2:D20)-SUM($G$2:G20) -> 291267 | K20: =L20+M20 -> 0 | O20: =A15 -> 45025 | P20: =R20*0.3 -> 4680 | Q20: =R20-P20 -> 10920 | R20: =S20+T20 -> 15600 | S20: =VLOOKUP(O20,$A$1:$H$37,5,0) -> 13820 | T20: =VLOOKUP(O20,$A$1:$H$37,6,0) -> 1780 | U20: =VLOOKUP(O20,$A$1:$H$37,7,0) -> 100
A21: 45031 | B21: =D21*0.39 -> 9941.1 | C21: =D21-B21 -> 15548.9 | D21: =E21+F21 -> 25490 | E21: 5820 | F21: 19670 | G21: 52600 | H21: =IFERROR(B21/C21,0) -> 0.63934426 | I21: =SUM($D$2:D21)-SUM($G$2:G21) -> 264157 | K21: =L21+M21 -> 0 | O21: Total | P21: =SUM(P14:P20) -> 33923.7 | Q21: =SUM(Q14:Q20) -> 79155.3 | R21: =SUM(R14:R20) -> 113079 | S21: =SUM(S14:S20) -> 69897 | T21: =SUM(T14:T20) -> 43182 | U21: =SUM(U14:U20) -> 25780
A22: 45032 | B22: =D22*0.39 -> 12316.2 | C22: =D22-B22 -> 19263.8 | D22: =E22+F22 -> 31580 | E22: 17875 | F22: 13705 | G22: 900 | H22: =IFERROR(B22/C22,0) -> 0.63934426 | I22: =SUM($D$2:D22)-SUM($G$2:G22) -> 294837 | K22: =L22+M22 -> 0 | O22: Mul Bhag | P22: =P21/3 -> 11307.9 | Q22: 12750 | R22: =Q22+P22 -> 24057.9
A23: 45033 | B23: =D23*0.39 -> 12000.3 | C23: =D23-B23 -> 18769.7 | D23: =E23+F23 -> 30770 | E23: 10390 | F23: 20380 | G23: 4000 | H23: =IFERROR(B23/C23,0) -> 0.63934426 | I23: =SUM($D$2:D23)-SUM($G$2:G23) -> 321607 | K23: =L23+M23 -> 0 | Q23: ser
A24: 45034 | B24: =D24*0.39 -> 6688.5 | C24: =D24-B24 -> 10461.5 | D24: =E24+F24 -> 17150 | E24: 9430 | F24: 7720 | G24: 2300 | H24: =IFERROR(B24/C24,0) -> 0.63934426 | I24: =SUM($D$2:D24)-SUM($G$2:G24) -> 336457 | K24: =L24+M24 -> 0 | O24: Date | P24: Profit | Q24: Actual | R24: Total | S24: Cash | T24: Account Transfer | U24: Expense
A25: 45035 | B25: =D25*0.39 -> 8225.1 | C25: =D25-B25 -> 12864.9 | D25: =E25+F25 -> 21090 | E25: 5190 | F25: 15900 | G25: 40 | H25: =IFERROR(B25/C25,0) -> 0.63934426 | I25: =SUM($D$2:D25)-SUM($G$2:G25) -> 357507 | K25: =L25+M25 -> 0 | O25: =A16 -> 45026 | P25: =R25*0.3 -> 6969 | Q25: =R25-P25 -> 16261 | R25: =S25+T25 -> 23230 | S25: =VLOOKUP(O25,$A$1:$H$37,5,0) -> 4280 | T25: =VLOOKUP(O25,$A$1:$H$37,6,0) -> 18950 | U25: =VLOOKUP(O25,$A$1:$H$37,7,0) -> 100
A26: 45036 | B26: =D26*0.39 -> 10830.3 | C26: =D26-B26 -> 16939.7 | D26: =E26+F26 -> 27770 | E26: =Table23453456879111215141617181920212223242526272834[[#This Row],[Expense]]+21540 -> 27550 | F26: 220 | G26: 6010 | H26: =IFERROR(B26/C26,0) -> 0.63934426 | I26: =SUM($D$2:D26)-SUM($G$2:G26) -> 379267 | K26: =L26+M26 -> 0 | O26: =A17 -> 45027 | P26: =R26*0.3 -> 5001 | Q26: =R26-P26 -> 11669 | R26: =S26+T26 -> 16670 | S26: =VLOOKUP(O26,$A$1:$H$37,5,0) -> 6000 | T26: =VLOOKUP(O26,$A$1:$H$37,6,0) -> 10670 | U26: =VLOOKUP(O26,$A$1:$H$37,7,0) -> 27100
A27: 45037 | B27: =D27*0.39 -> 1661.4 | C27: =D27-B27 -> 2598.6 | D27: =E27+F27 -> 4260 | E27: =Table23453456879111215141617181920212223242526272834[[#This Row],[Expense]]+3957 -> 4080 | F27: 180 | G27: 123 | H27: =IFERROR(B27/C27,0) -> 0.63934426 | I27: =SUM($D$2:D27)-SUM($G$2:G27) -> 383404 | K27: =L27+M27 -> 0 | O27: =A18 -> 45028 | P27: =R27*0.3 -> 10203 | Q27: =R27-P27 -> 23807 | R27: =S27+T27 -> 34010 | S27: =VLOOKUP(O27,$A$1:$H$37,5,0) -> 18710 | T27: =VLOOKUP(O27,$A$1:$H$37,6,0) -> 15300 | U27: =VLOOKUP(O27,$A$1:$H$37,7,0) -> 15700
