Workbook
Name ColumnTitle1: Loan3[[#Headers],[Pmt No.]]
Name ColumnTitle1: Loan3[[#Headers],[Pmt No.]]
Name ColumnTitle1: Loan3[[#Headers],[Pmt No.]]
Name ColumnTitle1: Loan3[[#Headers],[Pmt No.]]
Name ColumnTitle1: Loan3[[#Headers],[Pmt No.]]
Name ColumnTitle1: Loan4[[#Headers],[Pmt No.]]
Name ColumnTitle1: Loan3[[#Headers],[Pmt No.]]
Name ColumnTitle1: Loan3[[#Headers],[Pmt No.]]
Name ColumnTitle1: Loan[[#Headers],[Pmt No.]]
Name EndingBalance: -FV(Axis!InterestRate/12,Axis!PaymentNumber,-Axis!MonthlyPayment,Axis!LoanAmount)
Name EndingBalance: -FV(Bajaj!InterestRate/12,Bajaj!PaymentNumber,-Bajaj!MonthlyPayment,Bajaj!LoanAmount)
Name EndingBalance: -FV(Citi!InterestRate/12,Citi!PaymentNumber,-Citi!MonthlyPayment,Citi!LoanAmount)
Name EndingBalance: -FV(CLIX!InterestRate/12,CLIX!PaymentNumber,-CLIX!MonthlyPayment,CLIX!LoanAmount)
Name EndingBalance: -FV(Edelwise!InterestRate/12,Edelwise!PaymentNumber,-Edelwise!MonthlyPayment,Edelwise!LoanAmount)
Name EndingBalance: -FV(Fullerton!InterestRate/12,Fullerton!PaymentNumber,-Fullerton!MonthlyPayment,Fullerton!LoanAmount)
Name EndingBalance: -FV(HDFC!InterestRate/12,HDFC!PaymentNumber,-HDFC!MonthlyPayment,HDFC!LoanAmount)
Name EndingBalance: -FV('Loan Calculator'!InterestRate/12,'Loan Calculator'!PaymentNumber,-'Loan Calculator'!MonthlyPayment,'Loan Calculator'!LoanAmount)
Name EndingBalance: -FV(InterestRate/12,PaymentNumber,-MonthlyPayment,LoanAmount)
Name HeaderRow: ROW(Axis!$9:$9)
Name HeaderRow: ROW(Bajaj!$9:$9)
Name HeaderRow: ROW(Citi!$9:$9)
Name HeaderRow: ROW(CLIX!$9:$9)
Name HeaderRow: ROW(Edelwise!$9:$9)
Name HeaderRow: ROW(Fullerton!$9:$9)
Name HeaderRow: ROW(HDFC!$9:$9)
Name HeaderRow: ROW('Loan Calculator'!$9:$9)
Name HeaderRow: ROW(IndusIn!$9:$9)
Name InterestAmt: -IPMT(Axis!InterestRate/12,Axis!PaymentNumber,Axis!NumberOfPayments,Axis!LoanAmount)
Name InterestAmt: -IPMT(Bajaj!InterestRate/12,Bajaj!PaymentNumber,Bajaj!NumberOfPayments,Bajaj!LoanAmount)
Name InterestAmt: -IPMT(Citi!InterestRate/12,Citi!PaymentNumber,Citi!NumberOfPayments,Citi!LoanAmount)
Name InterestAmt: -IPMT(CLIX!InterestRate/12,CLIX!PaymentNumber,CLIX!NumberOfPayments,CLIX!LoanAmount)
Name InterestAmt: -IPMT(Edelwise!InterestRate/12,Edelwise!PaymentNumber,Edelwise!NumberOfPayments,Edelwise!LoanAmount)
Name InterestAmt: -IPMT(Fullerton!InterestRate/12,Fullerton!PaymentNumber,Fullerton!NumberOfPayments,Fullerton!LoanAmount)
Name InterestAmt: -IPMT(HDFC!InterestRate/12,HDFC!PaymentNumber,HDFC!NumberOfPayments,HDFC!LoanAmount)
Name InterestAmt: -IPMT('Loan Calculator'!InterestRate/12,'Loan Calculator'!PaymentNumber,'Loan Calculator'!NumberOfPayments,'Loan Calculator'!LoanAmount)
Name InterestAmt: -IPMT(InterestRate/12,PaymentNumber,NumberOfPayments,LoanAmount)
Name InterestRate: Axis!$D$5
Name InterestRate: Bajaj!$D$5
Name InterestRate: Citi!$D$5
Name InterestRate: CLIX!$D$5
Name InterestRate: Edelwise!$D$5
Name InterestRate: Fullerton!$D$5
Name InterestRate: HDFC!$D$5
Name InterestRate: 'Loan Calculator'!$D$5
Name InterestRate: IndusIn!$D$5
Name LastCol: COUNTA(Axis!$9:$9)
Name LastCol: COUNTA(Bajaj!$9:$9)
Name LastCol: COUNTA(Citi!$9:$9)
Name LastCol: COUNTA(CLIX!$9:$9)
Name LastCol: COUNTA(Edelwise!$9:$9)
Name LastCol: COUNTA(Fullerton!$9:$9)
Name LastCol: COUNTA(HDFC!$9:$9)
Name LastCol: COUNTA('Loan Calculator'!$9:$9)
Name LastCol: COUNTA(IndusIn!$9:$9)
Name LastRow: MATCH(9.99E+307,Axis!$B:$B)
Name LastRow: MATCH(9.99E+307,Bajaj!$B:$B)
Name LastRow: MATCH(9.99E+307,Citi!$B:$B)
Name LastRow: MATCH(9.99E+307,CLIX!$B:$B)
Name LastRow: MATCH(9.99E+307,Edelwise!$B:$B)
Name LastRow: MATCH(9.99E+307,Fullerton!$B:$B)

Sheet Loan Calculator
B1: Simple Loan Calculator
B3: Loan Values | F3: Loan Summary
B4: Loan amount | D4: 1650000 | F4: Monthly payment | H4: =IFERROR(IF(LoanIsGood,MonthlyPayment,""), "") -> 23959.384
B5: Annual interest rate | D5: 0.0875 | F5: Number of payments | H5: 96
B6: Loan period in years | D6: 5 | F6: Total interest | H6: =IFERROR(IF(LoanIsGood,TotalLoanCost-LoanAmount,""), "") -> 650100.86
B7: Start date of loan | D7: 43893 | F7: Total cost of loan | H7: =IFERROR(IF(LoanIsGood,MonthlyPayment*NumberOfPayments,""), "") -> 2300100.9
B9: Pmt No. | C9: Payment Date | D9: Beginning Balance | E9: Payment | F9: Principal | G9: Interest | H9: Ending Balance
B10: =IFERROR(IF(LoanIsNotPaid*LoanIsGood,PaymentNumber,""), "") -> 1 | C10: =IFERROR(IF(LoanIsNotPaid*LoanIsGood,PaymentDate,""), "") -> 43924 | D10: =IFERROR(IF(LoanIsNotPaid*LoanIsGood,LoanValue,""), "") -> 1650000 | E10: =IFERROR(IF(LoanIsNotPaid*LoanIsGood,MonthlyPayment,""), "") -> 23959.384 | F10: =IFERROR(IF(LoanIsNotPaid*LoanIsGood,Principal,""), "") -> 11928.134 | G10: =IFERROR(IF(LoanIsNotPaid*LoanIsGood,InterestAmt,""), "") -> 12031.25 | H10: =IFERROR(IF(LoanIsNotPaid*LoanIsGood,EndingBalance,""), "") -> 1638071.9
B11: =IFERROR(IF(LoanIsNotPaid*LoanIsGood,PaymentNumber,""), "") -> 2 | C11: =IFERROR(IF(LoanIsNotPaid*LoanIsGood,PaymentDate,""), "") -> 43954 | D11: =IFERROR(IF(LoanIsNotPaid*LoanIsGood,LoanValue,""), "") -> 1638071.9 | E11: =IFERROR(IF(LoanIsNotPaid*LoanIsGood,MonthlyPayment,""), "") -> 23959.384 | F11: =IFERROR(IF(LoanIsNotPaid*LoanIsGood,Principal,""), "") -> 12015.11 | G11: =IFERROR(IF(LoanIsNotPaid*LoanIsGood,InterestAmt,""), "") -> 11944.274 | H11: =IFERROR(IF(LoanIsNotPaid*LoanIsGood,EndingBalance,""), "") -> 1626056.8
B12: =IFERROR(IF(LoanIsNotPaid*LoanIsGood,PaymentNumber,""), "") -> 3 | C12: =IFERROR(IF(LoanIsNotPaid*LoanIsGood,PaymentDate,""), "") -> 43985 | D12: =IFERROR(IF(LoanIsNotPaid*LoanIsGood,LoanValue,""), "") -> 1626056.8 | E12: =IFERROR(IF(LoanIsNotPaid*LoanIsGood,MonthlyPayment,""), "") -> 23959.384 | F12: =IFERROR(IF(LoanIsNotPaid*LoanIsGood,Principal,""), "") -> 12102.72 | G12: =IFERROR(IF(LoanIsNotPaid*LoanIsGood,InterestAmt,""), "") -> 11856.664 | H12: =IFERROR(IF(LoanIsNotPaid*LoanIsGood,EndingBalance,""), "") -> 1613954
B13: =IFERROR(IF(LoanIsNotPaid*LoanIsGood,PaymentNumber,""), "") -> 4 | C13: =IFERROR(IF(LoanIsNotPaid*LoanIsGood,PaymentDate,""), "") -> 44015 | D13: =IFERROR(IF(LoanIsNotPaid*LoanIsGood,LoanValue,""), "") -> 1613954 | E13: =IFERROR(IF(LoanIsNotPaid*LoanIsGood,MonthlyPayment,""), "") -> 23959.384 | F13: =IFERROR(IF(LoanIsNotPaid*LoanIsGood,Principal,""), "") -> 12190.969 | G13: =IFERROR(IF(LoanIsNotPaid*LoanIsGood,InterestAmt,""), "") -> 11768.415 | H13: =IFERROR(IF(LoanIsNotPaid*LoanIsGood,EndingBalance,""), "") -> 1601763.1
B14: =IFERROR(IF(LoanIsNotPaid*LoanIsGood,PaymentNumber,""), "") -> 5 | C14: =IFERROR(IF(LoanIsNotPaid*LoanIsGood,PaymentDate,""), "") -> 44046 | D14: =IFERROR(IF(LoanIsNotPaid*LoanIsGood,LoanValue,""), "") -> 1601763.1 | E14: =IFERROR(IF(LoanIsNotPaid*LoanIsGood,MonthlyPayment,""), "") -> 23959.384 | F14: =IFERROR(IF(LoanIsNotPaid*LoanIsGood,Principal,""), "") -> 12279.862 | G14: =IFERROR(IF(LoanIsNotPaid*LoanIsGood,InterestAmt,""), "") -> 11679.522 | H14: =IFERROR(IF(LoanIsNotPaid*LoanIsGood,EndingBalance,""), "") -> 1589483.2
B15: =IFERROR(IF(LoanIsNotPaid*LoanIsGood,PaymentNumber,""), "") -> 6 | C15: =IFERROR(IF(LoanIsNotPaid*LoanIsGood,PaymentDate,""), "") -> 44077 | D15: =IFERROR(IF(LoanIsNotPaid*LoanIsGood,LoanValue,""), "") -> 1589483.2 | E15: =IFERROR(IF(LoanIsNotPaid*LoanIsGood,MonthlyPayment,""), "") -> 23959.384 | F15: =IFERROR(IF(LoanIsNotPaid*LoanIsGood,Principal,""), "") -> 12369.402 | G15: =IFERROR(IF(LoanIsNotPaid*LoanIsGood,InterestAmt,""), "") -> 11589.982 | H15: =IFERROR(IF(LoanIsNotPaid*LoanIsGood,EndingBalance,""), "") -> 1577113.8
B16: =IFERROR(IF(LoanIsNotPaid*LoanIsGood,PaymentNumber,""), "") -> 7 | C16: =IFERROR(IF(LoanIsNotPaid*LoanIsGood,PaymentDate,""), "") -> 44107 | D16: =IFERROR(IF(LoanIsNotPaid*LoanIsGood,LoanValue,""), "") -> 1577113.8 | E16: =IFERROR(IF(LoanIsNotPaid*LoanIsGood,MonthlyPayment,""), "") -> 23959.384 | F16: =IFERROR(IF(LoanIsNotPaid*LoanIsGood,Principal,""), "") -> 12459.596 | G16: =IFERROR(IF(LoanIsNotPaid*LoanIsGood,InterestAmt,""), "") -> 11499.788 | H16: =IFERROR(IF(LoanIsNotPaid*LoanIsGood,EndingBalance,""), "") -> 1564654.2
B17: =IFERROR(IF(LoanIsNotPaid*LoanIsGood,PaymentNumber,""), "") -> 8 | C17: =IFERROR(IF(LoanIsNotPaid*LoanIsGood,PaymentDate,""), "") -> 44138 | D17: =IFERROR(IF(LoanIsNotPaid*LoanIsGood,LoanValue,""), "") -> 1564654.2 | E17: =IFERROR(IF(LoanIsNotPaid*LoanIsGood,MonthlyPayment,""), "") -> 23959.384 | F17: =IFERROR(IF(LoanIsNotPaid*LoanIsGood,Principal,""), "") -> 12550.447 | G17: =IFERROR(IF(LoanIsNotPaid*LoanIsGood,InterestAmt,""), "") -> 11408.937 | H17: =IFERROR(IF(LoanIsNotPaid*LoanIsGood,EndingBalance,""), "") -> 1552103.8
B18: =IFERROR(IF(LoanIsNotPaid*LoanIsGood,PaymentNumber,""), "") -> 9 | C18: =IFERROR(IF(LoanIsNotPaid*LoanIsGood,PaymentDate,""), "") -> 44168 | D18: =IFERROR(IF(LoanIsNotPaid*LoanIsGood,LoanValue,""), "") -> 1552103.8 | E18: =IFERROR(IF(LoanIsNotPaid*LoanIsGood,MonthlyPayment,""), "") -> 23959.384 | F18: =IFERROR(IF(LoanIsNotPaid*LoanIsGood,Principal,""), "") -> 12641.961 | G18: =IFERROR(IF(LoanIsNotPaid*LoanIsGood,InterestAmt,""), "") -> 11317.423 | H18: =IFERROR(IF(LoanIsNotPaid*LoanIsGood,EndingBalance,""), "") -> 1539461.8
B19: =IFERROR(IF(LoanIsNotPaid*LoanIsGood,PaymentNumber,""), "") -> 10 | C19: =IFERROR(IF(LoanIsNotPaid*LoanIsGood,PaymentDate,""), "") -> 44199 | D19: =IFERROR(IF(LoanIsNotPaid*LoanIsGood,LoanValue,""), "") -> 1539461.8 | E19: =IFERROR(IF(LoanIsNotPaid*LoanIsGood,MonthlyPayment,""), "") -> 23959.384 | F19: =IFERROR(IF(LoanIsNotPaid*LoanIsGood,Principal,""), "") -> 12734.142 | G19: =IFERROR(IF(LoanIsNotPaid*LoanIsGood,InterestAmt,""), "") -> 11225.242 | H19: =IFERROR(IF(LoanIsNotPaid*LoanIsGood,EndingBalance,""), "") -> 1526727.7
B20: =IFERROR(IF(LoanIsNotPaid*LoanIsGood,PaymentNumber,""), "") -> 11 | C20: =IFERROR(IF(LoanIsNotPaid*LoanIsGood,PaymentDate,""), "") -> 44230 | D20: =IFERROR(IF(LoanIsNotPaid*LoanIsGood,LoanValue,""), "") -> 1526727.7 | E20: =IFERROR(IF(LoanIsNotPaid*LoanIsGood,MonthlyPayment,""), "") -> 23959.384 | F20: =IFERROR(IF(LoanIsNotPaid*LoanIsGood,Principal,""), "") -> 12826.995 | G20: =IFERROR(IF(LoanIsNotPaid*LoanIsGood,InterestAmt,""), "") -> 11132.389 | H20: =IFERROR(IF(LoanIsNotPaid*LoanIsGood,EndingBalance,""), "") -> 1513900.7
B21: =IFERROR(IF(LoanIsNotPaid*LoanIsGood,PaymentNumber,""), "") -> 12 | C21: =IFERROR(IF(LoanIsNotPaid*LoanIsGood,PaymentDate,""), "") -> 44258 | D21: =IFERROR(IF(LoanIsNotPaid*LoanIsGood,LoanValue,""), "") -> 1513900.7 | E21: =IFERROR(IF(LoanIsNotPaid*LoanIsGood,MonthlyPayment,""), "") -> 23959.384 | F21: =IFERROR(IF(LoanIsNotPaid*LoanIsGood,Principal,""), "") -> 12920.525 | G21: =IFERROR(IF(LoanIsNotPaid*LoanIsGood,InterestAmt,""), "") -> 11038.859 | H21: =IFERROR(IF(LoanIsNotPaid*LoanIsGood,EndingBalance,""), "") -> 1500980.1
... B369: =IFERROR(IF(LoanIsNotPaid*LoanIsGood,PaymentNumber,""), "") | C369: =IFERROR(IF(LoanIsNotPaid*LoanIsGood,PaymentDate,""), "") | D369: =IFERROR(IF(LoanIsNotPaid*LoanIsGood,LoanValue,""), "") | E369: =IFERROR(IF(LoanIsNotPaid*LoanIsGood,MonthlyPayment,""), "") | F369: =IFERROR(IF(LoanIsNotPaid*LoanIsGood,Principal,""), "") | G369: =IFERROR(IF(LoanIsNotPaid*LoanIsGood,InterestAmt,""), "") | H369: =IFERROR(IF(LoanIsNotPaid*LoanIsGood,EndingBalance,""), "")

Sheet HDFC
B1: Simple Loan Calculator
B3: Loan Values | F3: Loan Summary
B4: Loan amount | D4: 3016059 | F4: Monthly payment | H4: =IFERROR(IF(LoanIsGood,MonthlyPayment,""), "") -> 65201.024
B5: Annual interest rate | D5: 0.1075 | F5: Number of payments | H5: 60
B6: Loan period in years | D6: 5 | F6: Total interest | H6: =IFERROR(IF(LoanIsGood,TotalLoanCost-LoanAmount,""), "") -> 896002.43
B7: Start date of loan | D7: 44015 | F7: Total cost of loan | H7: =IFERROR(IF(LoanIsGood,MonthlyPayment*NumberOfPayments,""), "") -> 3912061.4
B9: Pmt No. | C9: Payment Date | D9: Beginning Balance | E9: Payment | F9: Principal | G9: Interest | H9: Ending Balance
B10: =IFERROR(IF(LoanIsNotPaid*LoanIsGood,PaymentNumber,""), "") -> 1 | C10: =IFERROR(IF(LoanIsNotPaid*LoanIsGood,PaymentDate,""), "") -> 44046 | D10: =IFERROR(IF(LoanIsNotPaid*LoanIsGood,LoanValue,""), "") -> 3016059 | E10: =IFERROR(IF(LoanIsNotPaid*LoanIsGood,MonthlyPayment,""), "") -> 65201.024 | F10: =IFERROR(IF(LoanIsNotPaid*LoanIsGood,Principal,""), "") -> 38182.162 | G10: =IFERROR(IF(LoanIsNotPaid*LoanIsGood,InterestAmt,""), "") -> 27018.862 | H10: =IFERROR(IF(LoanIsNotPaid*LoanIsGood,EndingBalance,""), "") -> 2977876.8
B11: =IFERROR(IF(LoanIsNotPaid*LoanIsGood,PaymentNumber,""), "") -> 2 | C11: =IFERROR(IF(LoanIsNotPaid*LoanIsGood,PaymentDate,""), "") -> 44077 | D11: =IFERROR(IF(LoanIsNotPaid*LoanIsGood,LoanValue,""), "") -> 2977876.8 | E11: =IFERROR(IF(LoanIsNotPaid*LoanIsGood,MonthlyPayment,""), "") -> 65201.024 | F11: =IFERROR(IF(LoanIsNotPaid*LoanIsGood,Principal,""), "") -> 38524.21 | G11: =IFERROR(IF(LoanIsNotPaid*LoanIsGood,InterestAmt,""), "") -> 26676.813 | H11: =IFERROR(IF(LoanIsNotPaid*LoanIsGood,EndingBalance,""), "") -> 2939352.6
B12: =IFERROR(IF(LoanIsNotPaid*LoanIsGood,PaymentNumber,""), "") -> 3 | C12: =IFERROR(IF(LoanIsNotPaid*LoanIsGood,PaymentDate,""), "") -> 44107 | D12: =IFERROR(IF(LoanIsNotPaid*LoanIsGood,LoanValue,""), "") -> 2939352.6 | E12: =IFERROR(IF(LoanIsNotPaid*LoanIsGood,MonthlyPayment,""), "") -> 65201.024 | F12: =IFERROR(IF(LoanIsNotPaid*LoanIsGood,Principal,""), "") -> 38869.323 | G12: =IFERROR(IF(LoanIsNotPaid*LoanIsGood,InterestAmt,""), "") -> 26331.701 | H12: =IFERROR(IF(LoanIsNotPaid*LoanIsGood,EndingBalance,""), "") -> 2900483.3
B13: =IFERROR(IF(LoanIsNotPaid*LoanIsGood,PaymentNumber,""), "") -> 4 | C13: =IFERROR(IF(LoanIsNotPaid*LoanIsGood,PaymentDate,""), "") -> 44138 | D13: =IFERROR(IF(LoanIsNotPaid*LoanIsGood,LoanValue,""), "") -> 2900483.3 | E13: =IFERROR(IF(LoanIsNotPaid*LoanIsGood,MonthlyPayment,""), "") -> 65201.024 | F13: =IFERROR(IF(LoanIsNotPaid*LoanIsGood,Principal,""), "") -> 39217.527 | G13: =IFERROR(IF(LoanIsNotPaid*LoanIsGood,InterestAmt,""), "") -> 25983.496 | H13: =IFERROR(IF(LoanIsNotPaid*LoanIsGood,EndingBalance,""), "") -> 2861265.8
B14: =IFERROR(IF(LoanIsNotPaid*LoanIsGood,PaymentNumber,""), "") -> 5 | C14: =IFERROR(IF(LoanIsNotPaid*LoanIsGood,PaymentDate,""), "") -> 44168 | D14: =IFERROR(IF(LoanIsNotPaid*LoanIsGood,LoanValue,""), "") -> 2861265.8 | E14: =IFERROR(IF(LoanIsNotPaid*LoanIsGood,MonthlyPayment,""), "") -> 65201.024 | F14: =IFERROR(IF(LoanIsNotPaid*LoanIsGood,Principal,""), "") -> 39568.851 | G14: =IFERROR(IF(LoanIsNotPaid*LoanIsGood,InterestAmt,""), "") -> 25632.173 | H14: =IFERROR(IF(LoanIsNotPaid*LoanIsGood,EndingBalance,""), "") -> 2821696.9
B15: =IFERROR(IF(LoanIsNotPaid*LoanIsGood,PaymentNumber,""), "") -> 6 | C15: =IFERROR(IF(LoanIsNotPaid*LoanIsGood,PaymentDate,""), "") -> 44199 | D15: =IFERROR(IF(LoanIsNotPaid*LoanIsGood,LoanValue,""), "") -> 2821696.9 | E15: =IFERROR(IF(LoanIsNotPaid*LoanIsGood,MonthlyPayment,""), "") -> 65201.024 | F15: =IFERROR(IF(LoanIsNotPaid*LoanIsGood,Principal,""), "") -> 39923.322 | G15: =IFERROR(IF(LoanIsNotPaid*LoanIsGood,InterestAmt,""), "") -> 25277.702 | H15: =IFERROR(IF(LoanIsNotPaid*LoanIsGood,EndingBalance,""), "") -> 2781773.6
B16: =IFERROR(IF(LoanIsNotPaid*LoanIsGood,PaymentNumber,""), "") -> 7 | C16: =IFERROR(IF(LoanIsNotPaid*LoanIsGood,PaymentDate,""), "") -> 44230 | D16: =IFERROR(IF(LoanIsNotPaid*LoanIsGood,LoanValue,""), "") -> 2781773.6 | E16: =IFERROR(IF(LoanIsNotPaid*LoanIsGood,MonthlyPayment,""), "") -> 65201.024 | F16: =IFERROR(IF(LoanIsNotPaid*LoanIsGood,Principal,""), "") -> 40280.969 | G16: =IFERROR(IF(LoanIsNotPaid*LoanIsGood,InterestAmt,""), "") -> 24920.055 | H16: =IFERROR(IF(LoanIsNotPaid*LoanIsGood,EndingBalance,""), "") -> 2741492.6
B17: =IFERROR(IF(LoanIsNotPaid*LoanIsGood,PaymentNumber,""), "") -> 8 | C17: =IFERROR(IF(LoanIsNotPaid*LoanIsGood,PaymentDate,""), "") -> 44258 | D17: =IFERROR(IF(LoanIsNotPaid*LoanIsGood,LoanValue,""), "") -> 2741492.6 | E17: =IFERROR(IF(LoanIsNotPaid*LoanIsGood,MonthlyPayment,""), "") -> 65201.024 | F17: =IFERROR(IF(LoanIsNotPaid*LoanIsGood,Principal,""), "") -> 40641.819 | G17: =IFERROR(IF(LoanIsNotPaid*LoanIsGood,InterestAmt,""), "") -> 24559.205 | H17: =IFERROR(IF(LoanIsNotPaid*LoanIsGood,EndingBalance,""), "") -> 2700850.8
B18: =IFERROR(IF(LoanIsNotPaid*LoanIsGood,PaymentNumber,""), "") -> 9 | C18: =IFERROR(IF(LoanIsNotPaid*LoanIsGood,PaymentDate,""), "") -> 44289 | D18: =IFERROR(IF(LoanIsNotPaid*LoanIsGood,LoanValue,""), "") -> 2700850.8 | E18: =IFERROR(IF(LoanIsNotPaid*LoanIsGood,MonthlyPayment,""), "") -> 65201.024 | F18: =IFERROR(IF(LoanIsNotPaid*LoanIsGood,Principal,""), "") -> 41005.902 | G18: =IFERROR(IF(LoanIsNotPaid*LoanIsGood,InterestAmt,""), "") -> 24195.122 | H18: =IFERROR(IF(LoanIsNotPaid*LoanIsGood,EndingBalance,""), "") -> 2659844.9
B19: =IFERROR(IF(LoanIsNotPaid*LoanIsGood,PaymentNumber,""), "") -> 10 | C19: =IFERROR(IF(LoanIsNotPaid*LoanIsGood,PaymentDate,""), "") -> 44319 | D19: =IFERROR(IF(LoanIsNotPaid*LoanIsGood,LoanValue,""), "") -> 2659844.9 | E19: =IFERROR(IF(LoanIsNotPaid*LoanIsGood,MonthlyPayment,""), "") -> 65201.024 | F19: =IFERROR(IF(LoanIsNotPaid*LoanIsGood,Principal,""), "") -> 41373.246 | G19: =IFERROR(IF(LoanIsNotPaid*LoanIsGood,InterestAmt,""), "") -> 23827.777 | H19: =IFERROR(IF(LoanIsNotPaid*LoanIsGood,EndingBalance,""), "") -> 2618471.7
B20: =IFERROR(IF(LoanIsNotPaid*LoanIsGood,PaymentNumber,""), "") -> 11 | C20: =IFERROR(IF(LoanIsNotPaid*LoanIsGood,PaymentDate,""), "") -> 44350 | D20: =IFERROR(IF(LoanIsNotPaid*LoanIsGood,LoanValue,""), "") -> 2618471.7 | E20: =IFERROR(IF(LoanIsNotPaid*LoanIsGood,MonthlyPayment,""), "") -> 65201.024 | F20: =IFERROR(IF(LoanIsNotPaid*LoanIsGood,Principal,""), "") -> 41743.882 | G20: =IFERROR(IF(LoanIsNotPaid*LoanIsGood,InterestAmt,""), "") -> 23457.142 | H20: =IFERROR(IF(LoanIsNotPaid*LoanIsGood,EndingBalance,""), "") -> 2576727.8
B21: =IFERROR(IF(LoanIsNotPaid*LoanIsGood,PaymentNumber,""), "") -> 12 | C21: =IFERROR(IF(LoanIsNotPaid*LoanIsGood,PaymentDate,""), "") -> 44380 | D21: =IFERROR(IF(LoanIsNotPaid*LoanIsGood,LoanValue,""), "") -> 2576727.8 | E21: =IFERROR(IF(LoanIsNotPaid*LoanIsGood,MonthlyPayment,""), "") -> 65201.024 | F21: =IFERROR(IF(LoanIsNotPaid*LoanIsGood,Principal,""), "") -> 42117.837 | G21: =IFERROR(IF(LoanIsNotPaid*LoanIsGood,InterestAmt,""), "") -> 23083.186 | H21: =IFERROR(IF(LoanIsNotPaid*LoanIsGood,EndingBalance,""), "") -> 2534609.9
... B369: =IFERROR(IF(LoanIsNotPaid*LoanIsGood,PaymentNumber,""), "") | C369: =IFERROR(IF(LoanIsNotPaid*LoanIsGood,PaymentDate,""), "") | D369: =IFERROR(IF(LoanIsNotPaid*LoanIsGood,LoanValue,""), "") | E369: =IFERROR(IF(LoanIsNotPaid*LoanIsGood,MonthlyPayment,""), "") | F369: =IFERROR(IF(LoanIsNotPaid*LoanIsGood,Principal,""), "") | G369: =IFERROR(IF(LoanIsNotPaid*LoanIsGood,InterestAmt,""), "") | H369: =IFERROR(IF(LoanIsNotPaid*LoanIsGood,EndingBalance,""), "")

Sheet Fullerton
B1: Simple Loan Calculator
B3: Loan Values | F3: Loan Summary
B4: Loan amount | D4: 1744000 | F4: Monthly payment | H4: =IFERROR(IF(LoanIsGood,MonthlyPayment,""), "") -> 41948.765
B5: Annual interest rate | D5: 0.155 | F5: Number of payments | H5: 60
B6: Loan period in years | D6: 5 | F6: Total interest | H6: =IFERROR(IF(LoanIsGood,TotalLoanCost-LoanAmount,""), "") -> 772925.91
B7: Start date of loan | D7: 43954 | F7: Total cost of loan | H7: =IFERROR(IF(LoanIsGood,MonthlyPayment*NumberOfPayments,""), "") -> 2516925.9
B9: Pmt No. | C9: Payment Date | D9: Beginning Balance | E9: Payment | F9: Principal | G9: Interest | H9: Ending Balance
B10: =IFERROR(IF(LoanIsNotPaid*LoanIsGood,PaymentNumber,""), "") -> 1 | C10: =IFERROR(IF(LoanIsNotPaid*LoanIsGood,PaymentDate,""), "") -> 43985 | D10: =IFERROR(IF(LoanIsNotPaid*LoanIsGood,LoanValue,""), "") -> 1744000 | E10: =IFERROR(IF(LoanIsNotPaid*LoanIsGood,MonthlyPayment,""), "") -> 41948.765 | F10: =IFERROR(IF(LoanIsNotPaid*LoanIsGood,Principal,""), "") -> 19422.099 | G10: =IFERROR(IF(LoanIsNotPaid*LoanIsGood,InterestAmt,""), "") -> 22526.667 | H10: =IFERROR(IF(LoanIsNotPaid*LoanIsGood,EndingBalance,""), "") -> 1724577.9
B11: =IFERROR(IF(LoanIsNotPaid*LoanIsGood,PaymentNumber,""), "") -> 2 | C11: =IFERROR(IF(LoanIsNotPaid*LoanIsGood,PaymentDate,""), "") -> 44015 | D11: =IFERROR(IF(LoanIsNotPaid*LoanIsGood,LoanValue,""), "") -> 1724577.9 | E11: =IFERROR(IF(LoanIsNotPaid*LoanIsGood,MonthlyPayment,""), "") -> 41948.765 | F11: =IFERROR(IF(LoanIsNotPaid*LoanIsGood,Principal,""), "") -> 19672.967 | G11: =IFERROR(IF(LoanIsNotPaid*LoanIsGood,InterestAmt,""), "") -> 22275.798 | H11: =IFERROR(IF(LoanIsNotPaid*LoanIsGood,EndingBalance,""), "") -> 1704904.9
B12: =IFERROR(IF(LoanIsNotPaid*LoanIsGood,PaymentNumber,""), "") -> 3 | C12: =IFERROR(IF(LoanIsNotPaid*LoanIsGood,PaymentDate,""), "") -> 44046 | D12: =IFERROR(IF(LoanIsNotPaid*LoanIsGood,LoanValue,""), "") -> 1704904.9 | E12: =IFERROR(IF(LoanIsNotPaid*LoanIsGood,MonthlyPayment,""), "") -> 41948.765 | F12: =IFERROR(IF(LoanIsNotPaid*LoanIsGood,Principal,""), "") -> 19927.077 | G12: =IFERROR(IF(LoanIsNotPaid*LoanIsGood,InterestAmt,""), "") -> 22021.689 | H12: =IFERROR(IF(LoanIsNotPaid*LoanIsGood,EndingBalance,""), "") -> 1684977.9
B13: =IFERROR(IF(LoanIsNotPaid*LoanIsGood,PaymentNumber,""), "") -> 4 | C13: =IFERROR(IF(LoanIsNotPaid*LoanIsGood,PaymentDate,""), "") -> 44077 | D13: =IFERROR(IF(LoanIsNotPaid*LoanIsGood,LoanValue,""), "") -> 1684977.9 | E13: =IFERROR(IF(LoanIsNotPaid*LoanIsGood,MonthlyPayment,""), "") -> 41948.765 | F13: =IFERROR(IF(LoanIsNotPaid*LoanIsGood,Principal,""), "") -> 20184.468 | G13: =IFERROR(IF(LoanIsNotPaid*LoanIsGood,InterestAmt,""), "") -> 21764.297 | H13: =IFERROR(IF(LoanIsNotPaid*LoanIsGood,EndingBalance,""), "") -> 1664793.4
B14: =IFERROR(IF(LoanIsNotPaid*LoanIsGood,PaymentNumber,""), "") -> 5 | C14: =IFERROR(IF(LoanIsNotPaid*LoanIsGood,PaymentDate,""), "") -> 44107 | D14: =IFERROR(IF(LoanIsNotPaid*LoanIsGood,LoanValue,""), "") -> 1664793.4 | E14: =IFERROR(IF(LoanIsNotPaid*LoanIsGood,MonthlyPayment,""), "") -> 41948.765 | F14: =IFERROR(IF(LoanIsNotPaid*LoanIsGood,Principal,""), "") -> 20445.184 | G14: =IFERROR(IF(LoanIsNotPaid*LoanIsGood,InterestAmt,""), "") -> 21503.581 | H14: =IFERROR(IF(LoanIsNotPaid*LoanIsGood,EndingBalance,""), "") -> 1644348.2
B15: =IFERROR(IF(LoanIsNotPaid*LoanIsGood,PaymentNumber,""), "") -> 6 | C15: =IFERROR(IF(LoanIsNotPaid*LoanIsGood,PaymentDate,""), "") -> 44138 | D15: =IFERROR(IF(LoanIsNotPaid*LoanIsGood,LoanValue,""), "") -> 1644348.2 | E15: =IFERROR(IF(LoanIsNotPaid*LoanIsGood,MonthlyPayment,""), "") -> 41948.765 | F15: =IFERROR(IF(LoanIsNotPaid*LoanIsGood,Principal,""), "") -> 20709.268 | G15: =IFERROR(IF(LoanIsNotPaid*LoanIsGood,InterestAmt,""), "") -> 21239.498 | H15: =IFERROR(IF(LoanIsNotPaid*LoanIsGood,EndingBalance,""), "") -> 1623638.9
B16: =IFERROR(IF(LoanIsNotPaid*LoanIsGood,PaymentNumber,""), "") -> 7 | C16: =IFERROR(IF(LoanIsNotPaid*LoanIsGood,PaymentDate,""), "") -> 44168 | D16: =IFERROR(IF(LoanIsNotPaid*LoanIsGood,LoanValue,""), "") -> 1623638.9 | E16: =IFERROR(IF(LoanIsNotPaid*LoanIsGood,MonthlyPayment,""), "") -> 41948.765 | F16: =IFERROR(IF(LoanIsNotPaid*LoanIsGood,Principal,""), "") -> 20976.762 | G16: =IFERROR(IF(LoanIsNotPaid*LoanIsGood,InterestAmt,""), "") -> 20972.003 | H16: =IFERROR(IF(LoanIsNotPaid*LoanIsGood,EndingBalance,""), "") -> 1602662.2
B17: =IFERROR(IF(LoanIsNotPaid*LoanIsGood,PaymentNumber,""), "") -> 8 | C17: =IFERROR(IF(LoanIsNotPaid*LoanIsGood,PaymentDate,""), "") -> 44199 | D17: =IFERROR(IF(LoanIsNotPaid*LoanIsGood,LoanValue,""), "") -> 1602662.2 | E17: =IFERROR(IF(LoanIsNotPaid*LoanIsGood,MonthlyPayment,""), "") -> 41948.765 | F17: =IFERROR(IF(LoanIsNotPaid*LoanIsGood,Principal,""), "") -> 21247.712 | G17: =IFERROR(IF(LoanIsNotPaid*LoanIsGood,InterestAmt,""), "") -> 20701.053 | H17: =IFERROR(IF(LoanIsNotPaid*LoanIsGood,EndingBalance,""), "") -> 1581414.5
B18: =IFERROR(IF(LoanIsNotPaid*LoanIsGood,PaymentNumber,""), "") -> 9 | C18: =IFERROR(IF(LoanIsNotPaid*LoanIsGood,PaymentDate,""), "") -> 44230 | D18: =IFERROR(IF(LoanIsNotPaid*LoanIsGood,LoanValue,""), "") -> 1581414.5 | E18: =IFERROR(IF(LoanIsNotPaid*LoanIsGood,MonthlyPayment,""), "") -> 41948.765 | F18: =IFERROR(IF(LoanIsNotPaid*LoanIsGood,Principal,""), "") -> 21522.162 | G18: =IFERROR(IF(LoanIsNotPaid*LoanIsGood,InterestAmt,""), "") -> 20426.603 | H18: =IFERROR(IF(LoanIsNotPaid*LoanIsGood,EndingBalance,""), "") -> 1559892.3
B19: =IFERROR(IF(LoanIsNotPaid*LoanIsGood,PaymentNumber,""), "") -> 10 | C19: =IFERROR(IF(LoanIsNotPaid*LoanIsGood,PaymentDate,""), "") -> 44258 | D19: =IFERROR(IF(LoanIsNotPaid*LoanIsGood,LoanValue,""), "") -> 1559892.3 | E19: =IFERROR(IF(LoanIsNotPaid*LoanIsGood,MonthlyPayment,""), "") -> 41948.765 | F19: =IFERROR(IF(LoanIsNotPaid*LoanIsGood,Principal,""), "") -> 21800.156 | G19: =IFERROR(IF(LoanIsNotPaid*LoanIsGood,InterestAmt,""), "") -> 20148.609 | H19: =IFERROR(IF(LoanIsNotPaid*LoanIsGood,EndingBalance,""), "") -> 1538092.1
B20: =IFERROR(IF(LoanIsNotPaid*LoanIsGood,PaymentNumber,""), "") -> 11 | C20: =IFERROR(IF(LoanIsNotPaid*LoanIsGood,PaymentDate,""), "") -> 44289 | D20: =IFERROR(IF(LoanIsNotPaid*LoanIsGood,LoanValue,""), "") -> 1538092.1 | E20: =IFERROR(IF(LoanIsNotPaid*LoanIsGood,MonthlyPayment,""), "") -> 41948.765 | F20: =IFERROR(IF(LoanIsNotPaid*LoanIsGood,Principal,""), "") -> 22081.742 | G20: =IFERROR(IF(LoanIsNotPaid*LoanIsGood,InterestAmt,""), "") -> 19867.024 | H20: =IFERROR(IF(LoanIsNotPaid*LoanIsGood,EndingBalance,""), "") -> 1516010.4
B21: =IFERROR(IF(LoanIsNotPaid*LoanIsGood,PaymentNumber,""), "") -> 12 | C21: =IFERROR(IF(LoanIsNotPaid*LoanIsGood,PaymentDate,""), "") -> 44319 | D21: =IFERROR(IF(LoanIsNotPaid*LoanIsGood,LoanValue,""), "") -> 1516010.4 | E21: =IFERROR(IF(LoanIsNotPaid*LoanIsGood,MonthlyPayment,""), "") -> 41948.765 | F21: =IFERROR(IF(LoanIsNotPaid*LoanIsGood,Principal,""), "") -> 22366.964 | G21: =IFERROR(IF(LoanIsNotPaid*LoanIsGood,InterestAmt,""), "") -> 19581.801 | H21: =IFERROR(IF(LoanIsNotPaid*LoanIsGood,EndingBalance,""), "") -> 1493643.4
... B369: =IFERROR(IF(LoanIsNotPaid*LoanIsGood,PaymentNumber,""), "") | C369: =IFERROR(IF(LoanIsNotPaid*LoanIsGood,PaymentDate,""), "") | D369: =IFERROR(IF(LoanIsNotPaid*LoanIsGood,LoanValue,""), "") | E369: =IFERROR(IF(LoanIsNotPaid*LoanIsGood,MonthlyPayment,""), "") | F369: =IFERROR(IF(LoanIsNotPaid*LoanIsGood,Principal,""), "") | G369: =IFERROR(IF(LoanIsNotPaid*LoanIsGood,InterestAmt,""), "") | H369: =IFERROR(IF(LoanIsNotPaid*LoanIsGood,EndingBalance,""), "")

Sheet Edelwise
B1: Simple Loan Calculator
B3: Loan Values | F3: Loan Summary
B4: Loan amount | D4: 1015080 | F4: Monthly payment | H4: =IFERROR(IF(LoanIsGood,MonthlyPayment,""), "") -> 29290.176
B5: Annual interest rate | D5: 0.17 | F5: Number of payments | H5: 48
B6: Loan period in years | D6: 4 | F6: Total interest | H6: =IFERROR(IF(LoanIsGood,TotalLoanCost-LoanAmount,""), "") -> 390848.46
B7: Start date of loan | D7: 43954 | F7: Total cost of loan | H7: =IFERROR(IF(LoanIsGood,MonthlyPayment*NumberOfPayments,""), "") -> 1405928.5
B9: Pmt No. | C9: Payment Date | D9: Beginning Balance | E9: Payment | F9: Principal | G9: Interest | H9: Ending Balance
B10: =IFERROR(IF(LoanIsNotPaid*LoanIsGood,PaymentNumber,""), "") -> 1 | C10: =IFERROR(IF(LoanIsNotPaid*LoanIsGood,PaymentDate,""), "") -> 43985 | D10: =IFERROR(IF(LoanIsNotPaid*LoanIsGood,LoanValue,""), "") -> 1015080 | E10: =IFERROR(IF(LoanIsNotPaid*LoanIsGood,MonthlyPayment,""), "") -> 29290.176 | F10: =IFERROR(IF(LoanIsNotPaid*LoanIsGood,Principal,""), "") -> 14909.876 | G10: =IFERROR(IF(LoanIsNotPaid*LoanIsGood,InterestAmt,""), "") -> 14380.3 | H10: =IFERROR(IF(LoanIsNotPaid*LoanIsGood,EndingBalance,""), "") -> 1000170.1
B11: =IFERROR(IF(LoanIsNotPaid*LoanIsGood,PaymentNumber,""), "") -> 2 | C11: =IFERROR(IF(LoanIsNotPaid*LoanIsGood,PaymentDate,""), "") -> 44015 | D11: =IFERROR(IF(LoanIsNotPaid*LoanIsGood,LoanValue,""), "") -> 1000170.1 | E11: =IFERROR(IF(LoanIsNotPaid*LoanIsGood,MonthlyPayment,""), "") -> 29290.176 | F11: =IFERROR(IF(LoanIsNotPaid*LoanIsGood,Principal,""), "") -> 15121.1 | G11: =IFERROR(IF(LoanIsNotPaid*LoanIsGood,InterestAmt,""), "") -> 14169.077 | H11: =IFERROR(IF(LoanIsNotPaid*LoanIsGood,EndingBalance,""), "") -> 985049.02
B12: =IFERROR(IF(LoanIsNotPaid*LoanIsGood,PaymentNumber,""), "") -> 3 | C12: =IFERROR(IF(LoanIsNotPaid*LoanIsGood,PaymentDate,""), "") -> 44046 | D12: =IFERROR(IF(LoanIsNotPaid*LoanIsGood,LoanValue,""), "") -> 985049.02 | E12: =IFERROR(IF(LoanIsNotPaid*LoanIsGood,MonthlyPayment,""), "") -> 29290.176 | F12: =IFERROR(IF(LoanIsNotPaid*LoanIsGood,Principal,""), "") -> 15335.315 | G12: =IFERROR(IF(LoanIsNotPaid*LoanIsGood,InterestAmt,""), "") -> 13954.861 | H12: =IFERROR(IF(LoanIsNotPaid*LoanIsGood,EndingBalance,""), "") -> 969713.71
B13: =IFERROR(IF(LoanIsNotPaid*LoanIsGood,PaymentNumber,""), "") -> 4 | C13: =IFERROR(IF(LoanIsNotPaid*LoanIsGood,PaymentDate,""), "") -> 44077 | D13: =IFERROR(IF(LoanIsNotPaid*LoanIsGood,LoanValue,""), "") -> 969713.71 | E13: =IFERROR(IF(LoanIsNotPaid*LoanIsGood,MonthlyPayment,""), "") -> 29290.176 | F13: =IFERROR(IF(LoanIsNotPaid*LoanIsGood,Principal,""), "") -> 15552.565 | G13: =IFERROR(IF(LoanIsNotPaid*LoanIsGood,InterestAmt,""), "") -> 13737.611 | H13: =IFERROR(IF(LoanIsNotPaid*LoanIsGood,EndingBalance,""), "") -> 954161.14
B14: =IFERROR(IF(LoanIsNotPaid*LoanIsGood,PaymentNumber,""), "") -> 5 | C14: =IFERROR(IF(LoanIsNotPaid*LoanIsGood,PaymentDate,""), "") -> 44107 | D14: =IFERROR(IF(LoanIsNotPaid*LoanIsGood,LoanValue,""), "") -> 954161.14 | E14: =IFERROR(IF(LoanIsNotPaid*LoanIsGood,MonthlyPayment,""), "") -> 29290.176 | F14: =IFERROR(IF(LoanIsNotPaid*LoanIsGood,Principal,""), "") -> 15772.893 | G14: =IFERROR(IF(LoanIsNotPaid*LoanIsGood,InterestAmt,""), "") -> 13517.283 | H14: =IFERROR(IF(LoanIsNotPaid*LoanIsGood,EndingBalance,""), "") -> 938388.25
B15: =IFERROR(IF(LoanIsNotPaid*LoanIsGood,PaymentNumber,""), "") -> 6 | C15: =IFERROR(IF(LoanIsNotPaid*LoanIsGood,PaymentDate,""), "") -> 44138 | D15: =IFERROR(IF(LoanIsNotPaid*LoanIsGood,LoanValue,""), "") -> 938388.25 | E15: =IFERROR(IF(LoanIsNotPaid*LoanIsGood,MonthlyPayment,""), "") -> 29290.176 | F15: =IFERROR(IF(LoanIsNotPaid*LoanIsGood,Principal,""), "") -> 15996.343 | G15: =IFERROR(IF(LoanIsNotPaid*LoanIsGood,InterestAmt,""), "") -> 13293.834 | H15: =IFERROR(IF(LoanIsNotPaid*LoanIsGood,EndingBalance,""), "") -> 922391.91
B16: =IFERROR(IF(LoanIsNotPaid*LoanIsGood,PaymentNumber,""), "") -> 7 | C16: =IFERROR(IF(LoanIsNotPaid*LoanIsGood,PaymentDate,""), "") -> 44168 | D16: =IFERROR(IF(LoanIsNotPaid*LoanIsGood,LoanValue,""), "") -> 922391.91 | E16: =IFERROR(IF(LoanIsNotPaid*LoanIsGood,MonthlyPayment,""), "") -> 29290.176 | F16: =IFERROR(IF(LoanIsNotPaid*LoanIsGood,Principal,""), "") -> 16222.958 | G16: =IFERROR(IF(LoanIsNotPaid*LoanIsGood,InterestAmt,""), "") -> 13067.219 | H16: =IFERROR(IF(LoanIsNotPaid*LoanIsGood,EndingBalance,""), "") -> 906168.95
B17: =IFERROR(IF(LoanIsNotPaid*LoanIsGood,PaymentNumber,""), "") -> 8 | C17: =IFERROR(IF(LoanIsNotPaid*LoanIsGood,PaymentDate,""), "") -> 44199 | D17: =IFERROR(IF(LoanIsNotPaid*LoanIsGood,LoanValue,""), "") -> 906168.95 | E17: =IFERROR(IF(LoanIsNotPaid*LoanIsGood,MonthlyPayment,""), "") -> 29290.176 | F17: =IFERROR(IF(LoanIsNotPaid*LoanIsGood,Principal,""), "") -> 16452.783 | G17: =IFERROR(IF(LoanIsNotPaid*LoanIsGood,InterestAmt,""), "") -> 12837.393 | H17: =IFERROR(IF(LoanIsNotPaid*LoanIsGood,EndingBalance,""), "") -> 889716.17
B18: =IFERROR(IF(LoanIsNotPaid*LoanIsGood,PaymentNumber,""), "") -> 9 | C18: =IFERROR(IF(LoanIsNotPaid*LoanIsGood,PaymentDate,""), "") -> 44230 | D18: =IFERROR(IF(LoanIsNotPaid*LoanIsGood,LoanValue,""), "") -> 889716.17 | E18: =IFERROR(IF(LoanIsNotPaid*LoanIsGood,MonthlyPayment,""), "") -> 29290.176 | F18: =IFERROR(IF(LoanIsNotPaid*LoanIsGood,Principal,""), "") -> 16685.864 | G18: =IFERROR(IF(LoanIsNotPaid*LoanIsGood,InterestAmt,""), "") -> 12604.312 | H18: =IFERROR(IF(LoanIsNotPaid*LoanIsGood,EndingBalance,""), "") -> 873030.3
B19: =IFERROR(IF(LoanIsNotPaid*LoanIsGood,PaymentNumber,""), "") -> 10 | C19: =IFERROR(IF(LoanIsNotPaid*LoanIsGood,PaymentDate,""), "") -> 44258 | D19: =IFERROR(IF(LoanIsNotPaid*LoanIsGood,LoanValue,""), "") -> 873030.3 | E19: =IFERROR(IF(LoanIsNotPaid*LoanIsGood,MonthlyPayment,""), "") -> 29290.176 | F19: =IFERROR(IF(LoanIsNotPaid*LoanIsGood,Principal,""), "") -> 16922.247 | G19: =IFERROR(IF(LoanIsNotPaid*LoanIsGood,InterestAmt,""), "") -> 12367.929 | H19: =IFERROR(IF(LoanIsNotPaid*LoanIsGood,EndingBalance,""), "") -> 856108.06
B20: =IFERROR(IF(LoanIsNotPaid*LoanIsGood,PaymentNumber,""), "") -> 11 | C20: =IFERROR(IF(LoanIsNotPaid*LoanIsGood,PaymentDate,""), "") -> 44289 | D20: =IFERROR(IF(LoanIsNotPaid*LoanIsGood,LoanValue,""), "") -> 856108.06 | E20: =IFERROR(IF(LoanIsNotPaid*LoanIsGood,MonthlyPayment,""), "") -> 29290.176 | F20: =IFERROR(IF(LoanIsNotPaid*LoanIsGood,Principal,""), "") -> 17161.979 | G20: =IFERROR(IF(LoanIsNotPaid*LoanIsGood,InterestAmt,""), "") -> 12128.197 | H20: =IFERROR(IF(LoanIsNotPaid*LoanIsGood,EndingBalance,""), "") -> 838946.08
B21: =IFERROR(IF(LoanIsNotPaid*LoanIsGood,PaymentNumber,""), "") -> 12 | C21: =IFERROR(IF(LoanIsNotPaid*LoanIsGood,PaymentDate,""), "") -> 44319 | D21: =IFERROR(IF(LoanIsNotPaid*LoanIsGood,LoanValue,""), "") -> 838946.08 | E21: =IFERROR(IF(LoanIsNotPaid*LoanIsGood,MonthlyPayment,""), "") -> 29290.176 | F21: =IFERROR(IF(LoanIsNotPaid*LoanIsGood,Principal,""), "") -> 17405.107 | G21: =IFERROR(IF(LoanIsNotPaid*LoanIsGood,InterestAmt,""), "") -> 11885.069 | H21: =IFERROR(IF(LoanIsNotPaid*LoanIsGood,EndingBalance,""), "") -> 821540.97
... B369: =IFERROR(IF(LoanIsNotPaid*LoanIsGood,PaymentNumber,""), "") | C369: =IFERROR(IF(LoanIsNotPaid*LoanIsGood,PaymentDate,""), "") | D369: =IFERROR(IF(LoanIsNotPaid*LoanIsGood,LoanValue,""), "") | E369: =IFERROR(IF(LoanIsNotPaid*LoanIsGood,MonthlyPayment,""), "") | F369: =IFERROR(IF(LoanIsNotPaid*LoanIsGood,Principal,""), "") | G369: =IFERROR(IF(LoanIsNotPaid*LoanIsGood,InterestAmt,""), "") | H369: =IFERROR(IF(LoanIsNotPaid*LoanIsGood,EndingBalance,""), "")

Sheet Bajaj
B1: Simple Loan Calculator
B3: Loan Values | F3: Loan Summary
B4: Loan amount | D4: 880000 | F4: Monthly payment | H4: =IFERROR(IF(LoanIsGood,MonthlyPayment,""), "") -> 21050.796
B5: Annual interest rate | D5: 0.1525 | F5: Number of payments | H5: 60
B6: Loan period in years | D6: 5 | F6: Total interest | H6: =IFERROR(IF(LoanIsGood,TotalLoanCost-LoanAmount,""), "") -> 383047.78
B7: Start date of loan | D7: 44015 | F7: Total cost of loan | H7: =IFERROR(IF(LoanIsGood,MonthlyPayment*NumberOfPayments,""), "") -> 1263047.8
B9: Pmt No. | C9: Payment Date | D9: Beginning Balance | E9: Payment | F9: Principal | G9: Interest | H9: Ending Balance
B10: =IFERROR(IF(LoanIsNotPaid*LoanIsGood,PaymentNumber,""), "") -> 1 | C10: =IFERROR(IF(LoanIsNotPaid*LoanIsGood,PaymentDate,""), "") -> 44046 | D10: =IFERROR(IF(LoanIsNotPaid*LoanIsGood,LoanValue,""), "") -> 880000 | E10: =IFERROR(IF(LoanIsNotPaid*LoanIsGood,MonthlyPayment,""), "") -> 21050.796 | F10: =IFERROR(IF(LoanIsNotPaid*LoanIsGood,Principal,""), "") -> 9867.463 | G10: =IFERROR(IF(LoanIsNotPaid*LoanIsGood,InterestAmt,""), "") -> 11183.333 | H10: =IFERROR(IF(LoanIsNotPaid*LoanIsGood,EndingBalance,""), "") -> 870132.54
B11: =IFERROR(IF(LoanIsNotPaid*LoanIsGood,PaymentNumber,""), "") -> 2 | C11: =IFERROR(IF(LoanIsNotPaid*LoanIsGood,PaymentDate,""), "") -> 44077 | D11: =IFERROR(IF(LoanIsNotPaid*LoanIsGood,LoanValue,""), "") -> 870132.54 | E11: =IFERROR(IF(LoanIsNotPaid*LoanIsGood,MonthlyPayment,""), "") -> 21050.796 | F11: =IFERROR(IF(LoanIsNotPaid*LoanIsGood,Principal,""), "") -> 9992.862 | G11: =IFERROR(IF(LoanIsNotPaid*LoanIsGood,InterestAmt,""), "") -> 11057.934 | H11: =IFERROR(IF(LoanIsNotPaid*LoanIsGood,EndingBalance,""), "") -> 860139.67
B12: =IFERROR(IF(LoanIsNotPaid*LoanIsGood,PaymentNumber,""), "") -> 3 | C12: =IFERROR(IF(LoanIsNotPaid*LoanIsGood,PaymentDate,""), "") -> 44107 | D12: =IFERROR(IF(LoanIsNotPaid*LoanIsGood,LoanValue,""), "") -> 860139.67 | E12: =IFERROR(IF(LoanIsNotPaid*LoanIsGood,MonthlyPayment,""), "") -> 21050.796 | F12: =IFERROR(IF(LoanIsNotPaid*LoanIsGood,Principal,""), "") -> 10119.855 | G12: =IFERROR(IF(LoanIsNotPaid*LoanIsGood,InterestAmt,""), "") -> 10930.942 | H12: =IFERROR(IF(LoanIsNotPaid*LoanIsGood,EndingBalance,""), "") -> 850019.82
B13: =IFERROR(IF(LoanIsNotPaid*LoanIsGood,PaymentNumber,""), "") -> 4 | C13: =IFERROR(IF(LoanIsNotPaid*LoanIsGood,PaymentDate,""), "") -> 44138 | D13: =IFERROR(IF(LoanIsNotPaid*LoanIsGood,LoanValue,""), "") -> 850019.82 | E13: =IFERROR(IF(LoanIsNotPaid*LoanIsGood,MonthlyPayment,""), "") -> 21050.796 | F13: =IFERROR(IF(LoanIsNotPaid*LoanIsGood,Principal,""), "") -> 10248.461 | G13: =IFERROR(IF(LoanIsNotPaid*LoanIsGood,InterestAmt,""), "") -> 10802.335 | H13: =IFERROR(IF(LoanIsNotPaid*LoanIsGood,EndingBalance,""), "") -> 839771.36
B14: =IFERROR(IF(LoanIsNotPaid*LoanIsGood,PaymentNumber,""), "") -> 5 | C14: =IFERROR(IF(LoanIsNotPaid*LoanIsGood,PaymentDate,""), "") -> 44168 | D14: =IFERROR(IF(LoanIsNotPaid*LoanIsGood,LoanValue,""), "") -> 839771.36 | E14: =IFERROR(IF(LoanIsNotPaid*LoanIsGood,MonthlyPayment,""), "") -> 21050.796 | F14: =IFERROR(IF(LoanIsNotPaid*LoanIsGood,Principal,""), "") -> 10378.702 | G14: =IFERROR(IF(LoanIsNotPaid*LoanIsGood,InterestAmt,""), "") -> 10672.094 | H14: =IFERROR(IF(LoanIsNotPaid*LoanIsGood,EndingBalance,""), "") -> 829392.66
B15: =IFERROR(IF(LoanIsNotPaid*LoanIsGood,PaymentNumber,""), "") -> 6 | C15: =IFERROR(IF(LoanIsNotPaid*LoanIsGood,PaymentDate,""), "") -> 44199 | D15: =IFERROR(IF(LoanIsNotPaid*LoanIsGood,LoanValue,""), "") -> 829392.66 | E15: =IFERROR(IF(LoanIsNotPaid*LoanIsGood,MonthlyPayment,""), "") -> 21050.796 | F15: =IFERROR(IF(LoanIsNotPaid*LoanIsGood,Principal,""), "") -> 10510.598 | G15: =IFERROR(IF(LoanIsNotPaid*LoanIsGood,InterestAmt,""), "") -> 10540.198 | H15: =IFERROR(IF(LoanIsNotPaid*LoanIsGood,EndingBalance,""), "") -> 818882.06
B16: =IFERROR(IF(LoanIsNotPaid*LoanIsGood,PaymentNumber,""), "") -> 7 | C16: =IFERROR(IF(LoanIsNotPaid*LoanIsGood,PaymentDate,""), "") -> 44230 | D16: =IFERROR(IF(LoanIsNotPaid*LoanIsGood,LoanValue,""), "") -> 818882.06 | E16: =IFERROR(IF(LoanIsNotPaid*LoanIsGood,MonthlyPayment,""), "") -> 21050.796 | F16: =IFERROR(IF(LoanIsNotPaid*LoanIsGood,Principal,""), "") -> 10644.17 | G16: =IFERROR(IF(LoanIsNotPaid*LoanIsGood,InterestAmt,""), "") -> 10406.626 | H16: =IFERROR(IF(LoanIsNotPaid*LoanIsGood,EndingBalance,""), "") -> 808237.89
B17: =IFERROR(IF(LoanIsNotPaid*LoanIsGood,PaymentNumber,""), "") -> 8 | C17: =IFERROR(IF(LoanIsNotPaid*LoanIsGood,PaymentDate,""), "") -> 44258 | D17: =IFERROR(IF(LoanIsNotPaid*LoanIsGood,LoanValue,""), "") -> 808237.89 | E17: =IFERROR(IF(LoanIsNotPaid*LoanIsGood,MonthlyPayment,""), "") -> 21050.796 | F17: =IFERROR(IF(LoanIsNotPaid*LoanIsGood,Principal,""), "") -> 10779.44 | G17: =IFERROR(IF(LoanIsNotPaid*LoanIsGood,InterestAmt,""), "") -> 10271.357 | H17: =IFERROR(IF(LoanIsNotPaid*LoanIsGood,EndingBalance,""), "") -> 797458.45
B18: =IFERROR(IF(LoanIsNotPaid*LoanIsGood,PaymentNumber,""), "") -> 9 | C18: =IFERROR(IF(LoanIsNotPaid*LoanIsGood,PaymentDate,""), "") -> 44289 | D18: =IFERROR(IF(LoanIsNotPaid*LoanIsGood,LoanValue,""), "") -> 797458.45 | E18: =IFERROR(IF(LoanIsNotPaid*LoanIsGood,MonthlyPayment,""), "") -> 21050.796 | F18: =IFERROR(IF(LoanIsNotPaid*LoanIsGood,Principal,""), "") -> 10916.429 | G18: =IFERROR(IF(LoanIsNotPaid*LoanIsGood,InterestAmt,""), "") -> 10134.368 | H18: =IFERROR(IF(LoanIsNotPaid*LoanIsGood,EndingBalance,""), "") -> 786542.02
B19: =IFERROR(IF(LoanIsNotPaid*LoanIsGood,PaymentNumber,""), "") -> 10 | C19: =IFERROR(IF(LoanIsNotPaid*LoanIsGood,PaymentDate,""), "") -> 44319 | D19: =IFERROR(IF(LoanIsNotPaid*LoanIsGood,LoanValue,""), "") -> 786542.02 | E19: =IFERROR(IF(LoanIsNotPaid*LoanIsGood,MonthlyPayment,""), "") -> 21050.796 | F19: =IFERROR(IF(LoanIsNotPaid*LoanIsGood,Principal,""), "") -> 11055.158 | G19: =IFERROR(IF(LoanIsNotPaid*LoanIsGood,InterestAmt,""), "") -> 9995.6382 | H19: =IFERROR(IF(LoanIsNotPaid*LoanIsGood,EndingBalance,""), "") -> 775486.86
B20: =IFERROR(IF(LoanIsNotPaid*LoanIsGood,PaymentNumber,""), "") -> 11 | C20: =IFERROR(IF(LoanIsNotPaid*LoanIsGood,PaymentDate,""), "") -> 44350 | D20: =IFERROR(IF(LoanIsNotPaid*LoanIsGood,LoanValue,""), "") -> 775486.86 | E20: =IFERROR(IF(LoanIsNotPaid*LoanIsGood,MonthlyPayment,""), "") -> 21050.796 | F20: =IFERROR(IF(LoanIsNotPaid*LoanIsGood,Principal,""), "") -> 11195.651 | G20: =IFERROR(IF(LoanIsNotPaid*LoanIsGood,InterestAmt,""), "") -> 9855.1455 | H20: =IFERROR(IF(LoanIsNotPaid*LoanIsGood,EndingBalance,""), "") -> 764291.21
B21: =IFERROR(IF(LoanIsNotPaid*LoanIsGood,PaymentNumber,""), "") -> 12 | C21: =IFERROR(IF(LoanIsNotPaid*LoanIsGood,PaymentDate,""), "") -> 44380 | D21: =IFERROR(IF(LoanIsNotPaid*LoanIsGood,LoanValue,""), "") -> 764291.21 | E21: =IFERROR(IF(LoanIsNotPaid*LoanIsGood,MonthlyPayment,""), "") -> 21050.796 | F21: =IFERROR(IF(LoanIsNotPaid*LoanIsGood,Principal,""), "") -> 11337.929 | G21: =IFERROR(IF(LoanIsNotPaid*LoanIsGood,InterestAmt,""), "") -> 9712.8675 | H21: =IFERROR(IF(LoanIsNotPaid*LoanIsGood,EndingBalance,""), "") -> 752953.28
... B369: =IFERROR(IF(LoanIsNotPaid*LoanIsGood,PaymentNumber,""), "") | C369: =IFERROR(IF(LoanIsNotPaid*LoanIsGood,PaymentDate,""), "") | D369: =IFERROR(IF(LoanIsNotPaid*LoanIsGood,LoanValue,""), "") | E369: =IFERROR(IF(LoanIsNotPaid*LoanIsGood,MonthlyPayment,""), "") | F369: =IFERROR(IF(LoanIsNotPaid*LoanIsGood,Principal,""), "") | G369: =IFERROR(IF(LoanIsNotPaid*LoanIsGood,InterestAmt,""), "") | H369: =IFERROR(IF(LoanIsNotPaid*LoanIsGood,EndingBalance,""), "")

Sheet IndusIn
B1: Simple Loan Calculator
B3: Loan Values | F3: Loan Summary
B4: Loan amount | D4: 2000000 | F4: Monthly payment | H4: =IFERROR(IF(LoanIsGood,MonthlyPayment,""), "") -> 43484.846
B5: Annual interest rate | D5: 0.11 | F5: Number of payments | H5: 60
B6: Loan period in years | D6: 5 | F6: Total interest | H6: =IFERROR(IF(LoanIsGood,TotalLoanCost-LoanAmount,""), "") -> 609090.77
B7: Start date of loan | D7: 44015 | F7: Total cost of loan | H7: =IFERROR(IF(LoanIsGood,MonthlyPayment*NumberOfPayments,""), "") -> 2609090.8
B9: Pmt No. | C9: Payment Date | D9: Beginning Balance | E9: Payment | F9: Principal | G9: Interest | H9: Ending Balance
B10: =IFERROR(IF(LoanIsNotPaid*LoanIsGood,PaymentNumber,""), "") -> 1 | C10: =IFERROR(IF(LoanIsNotPaid*LoanIsGood,PaymentDate,""), "") -> 44046 | D10: =IFERROR(IF(LoanIsNotPaid*LoanIsGood,LoanValue,""), "") -> 2000000 | E10: =IFERROR(IF(LoanIsNotPaid*LoanIsGood,MonthlyPayment,""), "") -> 43484.846 | F10: =IFERROR(IF(LoanIsNotPaid*LoanIsGood,Principal,""), "") -> 25151.513 | G10: =IFERROR(IF(LoanIsNotPaid*LoanIsGood,InterestAmt,""), "") -> 18333.333 | H10: =IFERROR(IF(LoanIsNotPaid*LoanIsGood,EndingBalance,""), "") -> 1974848.5
B11: =IFERROR(IF(LoanIsNotPaid*LoanIsGood,PaymentNumber,""), "") -> 2 | C11: =IFERROR(IF(LoanIsNotPaid*LoanIsGood,PaymentDate,""), "") -> 44077 | D11: =IFERROR(IF(LoanIsNotPaid*LoanIsGood,LoanValue,""), "") -> 1974848.5 | E11: =IFERROR(IF(LoanIsNotPaid*LoanIsGood,MonthlyPayment,""), "") -> 43484.846 | F11: =IFERROR(IF(LoanIsNotPaid*LoanIsGood,Principal,""), "") -> 25382.068 | G11: =IFERROR(IF(LoanIsNotPaid*LoanIsGood,InterestAmt,""), "") -> 18102.778 | H11: =IFERROR(IF(LoanIsNotPaid*LoanIsGood,EndingBalance,""), "") -> 1949466.4
B12: =IFERROR(IF(LoanIsNotPaid*LoanIsGood,PaymentNumber,""), "") -> 3 | C12: =IFERROR(IF(LoanIsNotPaid*LoanIsGood,PaymentDate,""), "") -> 44107 | D12: =IFERROR(IF(LoanIsNotPaid*LoanIsGood,LoanValue,""), "") -> 1949466.4 | E12: =IFERROR(IF(LoanIsNotPaid*LoanIsGood,MonthlyPayment,""), "") -> 43484.846 | F12: =IFERROR(IF(LoanIsNotPaid*LoanIsGood,Principal,""), "") -> 25614.737 | G12: =IFERROR(IF(LoanIsNotPaid*LoanIsGood,InterestAmt,""), "") -> 17870.109 | H12: =IFERROR(IF(LoanIsNotPaid*LoanIsGood,EndingBalance,""), "") -> 1923851.7
B13: =IFERROR(IF(LoanIsNotPaid*LoanIsGood,PaymentNumber,""), "") -> 4 | C13: =IFERROR(IF(LoanIsNotPaid*LoanIsGood,PaymentDate,""), "") -> 44138 | D13: =IFERROR(IF(LoanIsNotPaid*LoanIsGood,LoanValue,""), "") -> 1923851.7 | E13: =IFERROR(IF(LoanIsNotPaid*LoanIsGood,MonthlyPayment,""), "") -> 43484.846 | F13: =IFERROR(IF(LoanIsNotPaid*LoanIsGood,Principal,""), "") -> 25849.539 | G13: =IFERROR(IF(LoanIsNotPaid*LoanIsGood,InterestAmt,""), "") -> 17635.307 | H13: =IFERROR(IF(LoanIsNotPaid*LoanIsGood,EndingBalance,""), "") -> 1898002.1
B14: =IFERROR(IF(LoanIsNotPaid*LoanIsGood,PaymentNumber,""), "") -> 5 | C14: =IFERROR(IF(LoanIsNotPaid*LoanIsGood,PaymentDate,""), "") -> 44168 | D14: =IFERROR(IF(LoanIsNotPaid*LoanIsGood,LoanValue,""), "") -> 1898002.1 | E14: =IFERROR(IF(LoanIsNotPaid*LoanIsGood,MonthlyPayment,""), "") -> 43484.846 | F14: =IFERROR(IF(LoanIsNotPaid*LoanIsGood,Principal,""), "") -> 26086.493 | G14: =IFERROR(IF(LoanIsNotPaid*LoanIsGood,InterestAmt,""), "") -> 17398.353 | H14: =IFERROR(IF(LoanIsNotPaid*LoanIsGood,EndingBalance,""), "") -> 1871915.6
B15: =IFERROR(IF(LoanIsNotPaid*LoanIsGood,PaymentNumber,""), "") -> 6 | C15: =IFERROR(IF(LoanIsNotPaid*LoanIsGood,PaymentDate,""), "") -> 44199 | D15: =IFERROR(IF(LoanIsNotPaid*LoanIsGood,LoanValue,""), "") -> 1871915.6 | E15: =IFERROR(IF(LoanIsNotPaid*LoanIsGood,MonthlyPayment,""), "") -> 43484.846 | F15: =IFERROR(IF(LoanIsNotPaid*LoanIsGood,Principal,""), "") -> 26325.619 | G15: =IFERROR(IF(LoanIsNotPaid*LoanIsGood,InterestAmt,""), "") -> 17159.227 | H15: =IFERROR(IF(LoanIsNotPaid*LoanIsGood,EndingBalance,""), "") -> 1845590
B16: =IFERROR(IF(LoanIsNotPaid*LoanIsGood,PaymentNumber,""), "") -> 7 | C16: =IFERROR(IF(LoanIsNotPaid*LoanIsGood,PaymentDate,""), "") -> 44230 | D16: =IFERROR(IF(LoanIsNotPaid*LoanIsGood,LoanValue,""), "") -> 1845590 | E16: =IFERROR(IF(LoanIsNotPaid*LoanIsGood,MonthlyPayment,""), "") -> 43484.846 | F16: =IFERROR(IF(LoanIsNotPaid*LoanIsGood,Principal,""), "") -> 26566.938 | G16: =IFERROR(IF(LoanIsNotPaid*LoanIsGood,InterestAmt,""), "") -> 16917.909 | H16: =IFERROR(IF(LoanIsNotPaid*LoanIsGood,EndingBalance,""), "") -> 1819023.1
B17: =IFERROR(IF(LoanIsNotPaid*LoanIsGood,PaymentNumber,""), "") -> 8 | C17: =IFERROR(IF(LoanIsNotPaid*LoanIsGood,PaymentDate,""), "") -> 44258 | D17: =IFERROR(IF(LoanIsNotPaid*LoanIsGood,LoanValue,""), "") -> 1819023.1 | E17: =IFERROR(IF(LoanIsNotPaid*LoanIsGood,MonthlyPayment,""), "") -> 43484.846 | F17: =IFERROR(IF(LoanIsNotPaid*LoanIsGood,Principal,""), "") -> 26810.468 | G17: =IFERROR(IF(LoanIsNotPaid*LoanIsGood,InterestAmt,""), "") -> 16674.378 | H17: =IFERROR(IF(LoanIsNotPaid*LoanIsGood,EndingBalance,""), "") -> 1792212.6
B18: =IFERROR(IF(LoanIsNotPaid*LoanIsGood,PaymentNumber,""), "") -> 9 | C18: =IFERROR(IF(LoanIsNotPaid*LoanIsGood,PaymentDate,""), "") -> 44289 | D18: =IFERROR(IF(LoanIsNotPaid*LoanIsGood,LoanValue,""), "") -> 1792212.6 | E18: =IFERROR(IF(LoanIsNotPaid*LoanIsGood,MonthlyPayment,""), "") -> 43484.846 | F18: =IFERROR(IF(LoanIsNotPaid*LoanIsGood,Principal,""), "") -> 27056.23 | G18: =IFERROR(IF(LoanIsNotPaid*LoanIsGood,InterestAmt,""), "") -> 16428.616 | H18: =IFERROR(IF(LoanIsNotPaid*LoanIsGood,EndingBalance,""), "") -> 1765156.4
B19: =IFERROR(IF(LoanIsNotPaid*LoanIsGood,PaymentNumber,""), "") -> 10 | C19: =IFERROR(IF(LoanIsNotPaid*LoanIsGood,PaymentDate,""), "") -> 44319 | D19: =IFERROR(IF(LoanIsNotPaid*LoanIsGood,LoanValue,""), "") -> 1765156.4 | E19: =IFERROR(IF(LoanIsNotPaid*LoanIsGood,MonthlyPayment,""), "") -> 43484.846 | F19: =IFERROR(IF(LoanIsNotPaid*LoanIsGood,Principal,""), "") -> 27304.246 | G19: =IFERROR(IF(LoanIsNotPaid*LoanIsGood,InterestAmt,""), "") -> 16180.6 | H19: =IFERROR(IF(LoanIsNotPaid*LoanIsGood,EndingBalance,""), "") -> 1737852.1
B20: =IFERROR(IF(LoanIsNotPaid*LoanIsGood,PaymentNumber,""), "") -> 11 | C20: =IFERROR(IF(LoanIsNotPaid*LoanIsGood,PaymentDate,""), "") -> 44350 | D20: =IFERROR(IF(LoanIsNotPaid*LoanIsGood,LoanValue,""), "") -> 1737852.1 | E20: =IFERROR(IF(LoanIsNotPaid*LoanIsGood,MonthlyPayment,""), "") -> 43484.846 | F20: =IFERROR(IF(LoanIsNotPaid*LoanIsGood,Principal,""), "") -> 27554.535 | G20: =IFERROR(IF(LoanIsNotPaid*LoanIsGood,InterestAmt,""), "") -> 15930.311 | H20: =IFERROR(IF(LoanIsNotPaid*LoanIsGood,EndingBalance,""), "") -> 1710297.6
B21: =IFERROR(IF(LoanIsNotPaid*LoanIsGood,PaymentNumber,""), "") -> 12 | C21: =IFERROR(IF(LoanIsNotPaid*LoanIsGood,PaymentDate,""), "") -> 44380 | D21: =IFERROR(IF(LoanIsNotPaid*LoanIsGood,LoanValue,""), "") -> 1710297.6 | E21: =IFERROR(IF(LoanIsNotPaid*LoanIsGood,MonthlyPayment,""), "") -> 43484.846 | F21: =IFERROR(IF(LoanIsNotPaid*LoanIsGood,Principal,""), "") -> 27807.118 | G21: =IFERROR(IF(LoanIsNotPaid*LoanIsGood,InterestAmt,""), "") -> 15677.728 | H21: =IFERROR(IF(LoanIsNotPaid*LoanIsGood,EndingBalance,""), "") -> 1682490.5
... B369: =IFERROR(IF(LoanIsNotPaid*LoanIsGood,PaymentNumber,""), "") | C369: =IFERROR(IF(LoanIsNotPaid*LoanIsGood,PaymentDate,""), "") | D369: =IFERROR(IF(LoanIsNotPaid*LoanIsGood,LoanValue,""), "") | E369: =IFERROR(IF(LoanIsNotPaid*LoanIsGood,MonthlyPayment,""), "") | F369: =IFERROR(IF(LoanIsNotPaid*LoanIsGood,Principal,""), "") | G369: =IFERROR(IF(LoanIsNotPaid*LoanIsGood,InterestAmt,""), "") | H369: =IFERROR(IF(LoanIsNotPaid*LoanIsGood,EndingBalance,""), "")

Sheet Axis
B1: Simple Loan Calculator
B3: Loan Values | F3: Loan Summary
B4: Loan amount | D4: 1500000 | F4: Monthly payment | H4: =IFERROR(IF(LoanIsGood,MonthlyPayment,""), "") -> 32426.931
B5: Annual interest rate | D5: 0.1075 | F5: Number of payments | H5: 60
B6: Loan period in years | D6: 5 | F6: Total interest | H6: =IFERROR(IF(LoanIsGood,TotalLoanCost-LoanAmount,""), "") -> 445615.83
B7: Start date of loan | D7: 44107 | F7: Total cost of loan | H7: =IFERROR(IF(LoanIsGood,MonthlyPayment*NumberOfPayments,""), "") -> 1945615.8
B9: Pmt No. | C9: Payment Date | D9: Beginning Balance | E9: Payment | F9: Principal | G9: Interest | H9: Ending Balance
B10: =IFERROR(IF(LoanIsNotPaid*LoanIsGood,PaymentNumber,""), "") -> 1 | C10: =IFERROR(IF(LoanIsNotPaid*LoanIsGood,PaymentDate,""), "") -> 44138 | D10: =IFERROR(IF(LoanIsNotPaid*LoanIsGood,LoanValue,""), "") -> 1500000 | E10: =IFERROR(IF(LoanIsNotPaid*LoanIsGood,MonthlyPayment,""), "") -> 32426.931 | F10: =IFERROR(IF(LoanIsNotPaid*LoanIsGood,Principal,""), "") -> 18989.431 | G10: =IFERROR(IF(LoanIsNotPaid*LoanIsGood,InterestAmt,""), "") -> 13437.5 | H10: =IFERROR(IF(LoanIsNotPaid*LoanIsGood,EndingBalance,""), "") -> 1481010.6
B11: =IFERROR(IF(LoanIsNotPaid*LoanIsGood,PaymentNumber,""), "") -> 2 | C11: =IFERROR(IF(LoanIsNotPaid*LoanIsGood,PaymentDate,""), "") -> 44168 | D11: =IFERROR(IF(LoanIsNotPaid*LoanIsGood,LoanValue,""), "") -> 1481010.6 | E11: =IFERROR(IF(LoanIsNotPaid*LoanIsGood,MonthlyPayment,""), "") -> 32426.931 | F11: =IFERROR(IF(LoanIsNotPaid*LoanIsGood,Principal,""), "") -> 19159.544 | G11: =IFERROR(IF(LoanIsNotPaid*LoanIsGood,InterestAmt,""), "") -> 13267.386 | H11: =IFERROR(IF(LoanIsNotPaid*LoanIsGood,EndingBalance,""), "") -> 1461851
B12: =IFERROR(IF(LoanIsNotPaid*LoanIsGood,PaymentNumber,""), "") -> 3 | C12: =IFERROR(IF(LoanIsNotPaid*LoanIsGood,PaymentDate,""), "") -> 44199 | D12: =IFERROR(IF(LoanIsNotPaid*LoanIsGood,LoanValue,""), "") -> 1461851 | E12: =IFERROR(IF(LoanIsNotPaid*LoanIsGood,MonthlyPayment,""), "") -> 32426.931 | F12: =IFERROR(IF(LoanIsNotPaid*LoanIsGood,Principal,""), "") -> 19331.182 | G12: =IFERROR(IF(LoanIsNotPaid*LoanIsGood,InterestAmt,""), "") -> 13095.749 | H12: =IFERROR(IF(LoanIsNotPaid*LoanIsGood,EndingBalance,""), "") -> 1442519.8
B13: =IFERROR(IF(LoanIsNotPaid*LoanIsGood,PaymentNumber,""), "") -> 4 | C13: =IFERROR(IF(LoanIsNotPaid*LoanIsGood,PaymentDate,""), "") -> 44230 | D13: =IFERROR(IF(LoanIsNotPaid*LoanIsGood,LoanValue,""), "") -> 1442519.8 | E13: =IFERROR(IF(LoanIsNotPaid*LoanIsGood,MonthlyPayment,""), "") -> 32426.931 | F13: =IFERROR(IF(LoanIsNotPaid*LoanIsGood,Principal,""), "") -> 19504.357 | G13: =IFERROR(IF(LoanIsNotPaid*LoanIsGood,InterestAmt,""), "") -> 12922.574 | H13: =IFERROR(IF(LoanIsNotPaid*LoanIsGood,EndingBalance,""), "") -> 1423015.5
B14: =IFERROR(IF(LoanIsNotPaid*LoanIsGood,PaymentNumber,""), "") -> 5 | C14: =IFERROR(IF(LoanIsNotPaid*LoanIsGood,PaymentDate,""), "") -> 44258 | D14: =IFERROR(IF(LoanIsNotPaid*LoanIsGood,LoanValue,""), "") -> 1423015.5 | E14: =IFERROR(IF(LoanIsNotPaid*LoanIsGood,MonthlyPayment,""), "") -> 32426.931 | F14: =IFERROR(IF(LoanIsNotPaid*LoanIsGood,Principal,""), "") -> 19679.083 | G14: =IFERROR(IF(LoanIsNotPaid*LoanIsGood,InterestAmt,""), "") -> 12747.847 | H14: =IFERROR(IF(LoanIsNotPaid*LoanIsGood,EndingBalance,""), "") -> 1403336.4
B15: =IFERROR(IF(LoanIsNotPaid*LoanIsGood,PaymentNumber,""), "") -> 6 | C15: =IFERROR(IF(LoanIsNotPaid*LoanIsGood,PaymentDate,""), "") -> 44289 | D15: =IFERROR(IF(LoanIsNotPaid*LoanIsGood,LoanValue,""), "") -> 1403336.4 | E15: =IFERROR(IF(LoanIsNotPaid*LoanIsGood,MonthlyPayment,""), "") -> 32426.931 | F15: =IFERROR(IF(LoanIsNotPaid*LoanIsGood,Principal,""), "") -> 19855.375 | G15: =IFERROR(IF(LoanIsNotPaid*LoanIsGood,InterestAmt,""), "") -> 12571.555 | H15: =IFERROR(IF(LoanIsNotPaid*LoanIsGood,EndingBalance,""), "") -> 1383481
B16: =IFERROR(IF(LoanIsNotPaid*LoanIsGood,PaymentNumber,""), "") -> 7 | C16: =IFERROR(IF(LoanIsNotPaid*LoanIsGood,PaymentDate,""), "") -> 44319 | D16: =IFERROR(IF(LoanIsNotPaid*LoanIsGood,LoanValue,""), "") -> 1383481 | E16: =IFERROR(IF(LoanIsNotPaid*LoanIsGood,MonthlyPayment,""), "") -> 32426.931 | F16: =IFERROR(IF(LoanIsNotPaid*LoanIsGood,Principal,""), "") -> 20033.246 | G16: =IFERROR(IF(LoanIsNotPaid*LoanIsGood,InterestAmt,""), "") -> 12393.684 | H16: =IFERROR(IF(LoanIsNotPaid*LoanIsGood,EndingBalance,""), "") -> 1363447.8
B17: =IFERROR(IF(LoanIsNotPaid*LoanIsGood,PaymentNumber,""), "") -> 8 | C17: =IFERROR(IF(LoanIsNotPaid*LoanIsGood,PaymentDate,""), "") -> 44350 | D17: =IFERROR(IF(LoanIsNotPaid*LoanIsGood,LoanValue,""), "") -> 1363447.8 | E17: =IFERROR(IF(LoanIsNotPaid*LoanIsGood,MonthlyPayment,""), "") -> 32426.931 | F17: =IFERROR(IF(LoanIsNotPaid*LoanIsGood,Principal,""), "") -> 20212.711 | G17: =IFERROR(IF(LoanIsNotPaid*LoanIsGood,InterestAmt,""), "") -> 12214.22 | H17: =IFERROR(IF(LoanIsNotPaid*LoanIsGood,EndingBalance,""), "") -> 1343235.1
B18: =IFERROR(IF(LoanIsNotPaid*LoanIsGood,PaymentNumber,""), "") -> 9 | C18: =IFERROR(IF(LoanIsNotPaid*LoanIsGood,PaymentDate,""), "") -> 44380 | D18: =IFERROR(IF(LoanIsNotPaid*LoanIsGood,LoanValue,""), "") -> 1343235.1 | E18: =IFERROR(IF(LoanIsNotPaid*LoanIsGood,MonthlyPayment,""), "") -> 32426.931 | F18: =IFERROR(IF(LoanIsNotPaid*LoanIsGood,Principal,""), "") -> 20393.783 | G18: =IFERROR(IF(LoanIsNotPaid*LoanIsGood,InterestAmt,""), "") -> 12033.148 | H18: =IFERROR(IF(LoanIsNotPaid*LoanIsGood,EndingBalance,""), "") -> 1322841.3
B19: =IFERROR(IF(LoanIsNotPaid*LoanIsGood,PaymentNumber,""), "") -> 10 | C19: =IFERROR(IF(LoanIsNotPaid*LoanIsGood,PaymentDate,""), "") -> 44411 | D19: =IFERROR(IF(LoanIsNotPaid*LoanIsGood,LoanValue,""), "") -> 1322841.3 | E19: =IFERROR(IF(LoanIsNotPaid*LoanIsGood,MonthlyPayment,""), "") -> 32426.931 | F19: =IFERROR(IF(LoanIsNotPaid*LoanIsGood,Principal,""), "") -> 20576.477 | G19: =IFERROR(IF(LoanIsNotPaid*LoanIsGood,InterestAmt,""), "") -> 11850.453 | H19: =IFERROR(IF(LoanIsNotPaid*LoanIsGood,EndingBalance,""), "") -> 1302264.8
B20: =IFERROR(IF(LoanIsNotPaid*LoanIsGood,PaymentNumber,""), "") -> 11 | C20: =IFERROR(IF(LoanIsNotPaid*LoanIsGood,PaymentDate,""), "") -> 44442 | D20: =IFERROR(IF(LoanIsNotPaid*LoanIsGood,LoanValue,""), "") -> 1302264.8 | E20: =IFERROR(IF(LoanIsNotPaid*LoanIsGood,MonthlyPayment,""), "") -> 32426.931 | F20: =IFERROR(IF(LoanIsNotPaid*LoanIsGood,Principal,""), "") -> 20760.808 | G20: =IFERROR(IF(LoanIsNotPaid*LoanIsGood,InterestAmt,""), "") -> 11666.122 | H20: =IFERROR(IF(LoanIsNotPaid*LoanIsGood,EndingBalance,""), "") -> 1281504
B21: =IFERROR(IF(LoanIsNotPaid*LoanIsGood,PaymentNumber,""), "") -> 12 | C21: =IFERROR(IF(LoanIsNotPaid*LoanIsGood,PaymentDate,""), "") -> 44472 | D21: =IFERROR(IF(LoanIsNotPaid*LoanIsGood,LoanValue,""), "") -> 1281504 | E21: =IFERROR(IF(LoanIsNotPaid*LoanIsGood,MonthlyPayment,""), "") -> 32426.931 | F21: =IFERROR(IF(LoanIsNotPaid*LoanIsGood,Principal,""), "") -> 20946.791 | G21: =IFERROR(IF(LoanIsNotPaid*LoanIsGood,InterestAmt,""), "") -> 11480.14 | H21: =IFERROR(IF(LoanIsNotPaid*LoanIsGood,EndingBalance,""), "") -> 1260557.2
... B369: =IFERROR(IF(LoanIsNotPaid*LoanIsGood,PaymentNumber,""), "") | C369: =IFERROR(IF(LoanIsNotPaid*LoanIsGood,PaymentDate,""), "") | D369: =IFERROR(IF(LoanIsNotPaid*LoanIsGood,LoanValue,""), "") | E369: =IFERROR(IF(LoanIsNotPaid*LoanIsGood,MonthlyPayment,""), "") | F369: =IFERROR(IF(LoanIsNotPaid*LoanIsGood,Principal,""), "") | G369: =IFERROR(IF(LoanIsNotPaid*LoanIsGood,InterestAmt,""), "") | H369: =IFERROR(IF(LoanIsNotPaid*LoanIsGood,EndingBalance,""), "")

Sheet CLIX
B1: Simple Loan Calculator
B3: Loan Values | F3: Loan Summary
B4: Loan amount | D4: 1081652 | F4: Monthly payment | H4: =IFERROR(IF(LoanIsGood,MonthlyPayment,""), "") -> 24230.062
B5: Annual interest rate | D5: 0.166147 | F5: Number of payments | H5: 70
B6: Loan period in years | D6: 5 | F6: Total interest | H6: =IFERROR(IF(LoanIsGood,TotalLoanCost-LoanAmount,""), "") -> 614452.34
B7: Start date of loan | D7: 43893 | F7: Total cost of loan | H7: =IFERROR(IF(LoanIsGood,MonthlyPayment*NumberOfPayments,""), "") -> 1696104.3
B9: Pmt No. | C9: Payment Date | D9: Beginning Balance | E9: Payment | F9: Principal | G9: Interest | H9: Ending Balance
B10: =IFERROR(IF(LoanIsNotPaid*LoanIsGood,PaymentNumber,""), "") -> 1 | C10: =IFERROR(IF(LoanIsNotPaid*LoanIsGood,PaymentDate,""), "") -> 43924 | D10: =IFERROR(IF(LoanIsNotPaid*LoanIsGood,LoanValue,""), "") -> 1081652 | E10: =IFERROR(IF(LoanIsNotPaid*LoanIsGood,MonthlyPayment,""), "") -> 24230.062 | F10: =IFERROR(IF(LoanIsNotPaid*LoanIsGood,Principal,""), "") -> 9253.9591 | G10: =IFERROR(IF(LoanIsNotPaid*LoanIsGood,InterestAmt,""), "") -> 14976.103 | H10: =IFERROR(IF(LoanIsNotPaid*LoanIsGood,EndingBalance,""), "") -> 1072398
B11: =IFERROR(IF(LoanIsNotPaid*LoanIsGood,PaymentNumber,""), "") -> 2 | C11: =IFERROR(IF(LoanIsNotPaid*LoanIsGood,PaymentDate,""), "") -> 43954 | D11: =IFERROR(IF(LoanIsNotPaid*LoanIsGood,LoanValue,""), "") -> 1072398 | E11: =IFERROR(IF(LoanIsNotPaid*LoanIsGood,MonthlyPayment,""), "") -> 24230.062 | F11: =IFERROR(IF(LoanIsNotPaid*LoanIsGood,Principal,""), "") -> 9382.0856 | G11: =IFERROR(IF(LoanIsNotPaid*LoanIsGood,InterestAmt,""), "") -> 14847.976 | H11: =IFERROR(IF(LoanIsNotPaid*LoanIsGood,EndingBalance,""), "") -> 1063016
B12: =IFERROR(IF(LoanIsNotPaid*LoanIsGood,PaymentNumber,""), "") -> 3 | C12: =IFERROR(IF(LoanIsNotPaid*LoanIsGood,PaymentDate,""), "") -> 43985 | D12: =IFERROR(IF(LoanIsNotPaid*LoanIsGood,LoanValue,""), "") -> 1063016 | E12: =IFERROR(IF(LoanIsNotPaid*LoanIsGood,MonthlyPayment,""), "") -> 24230.062 | F12: =IFERROR(IF(LoanIsNotPaid*LoanIsGood,Principal,""), "") -> 9511.986 | G12: =IFERROR(IF(LoanIsNotPaid*LoanIsGood,InterestAmt,""), "") -> 14718.076 | H12: =IFERROR(IF(LoanIsNotPaid*LoanIsGood,EndingBalance,""), "") -> 1053504
B13: =IFERROR(IF(LoanIsNotPaid*LoanIsGood,PaymentNumber,""), "") -> 4 | C13: =IFERROR(IF(LoanIsNotPaid*LoanIsGood,PaymentDate,""), "") -> 44015 | D13: =IFERROR(IF(LoanIsNotPaid*LoanIsGood,LoanValue,""), "") -> 1053504 | E13: =IFERROR(IF(LoanIsNotPaid*LoanIsGood,MonthlyPayment,""), "") -> 24230.062 | F13: =IFERROR(IF(LoanIsNotPaid*LoanIsGood,Principal,""), "") -> 9643.685 | G13: =IFERROR(IF(LoanIsNotPaid*LoanIsGood,InterestAmt,""), "") -> 14586.377 | H13: =IFERROR(IF(LoanIsNotPaid*LoanIsGood,EndingBalance,""), "") -> 1043860.3
B14: =IFERROR(IF(LoanIsNotPaid*LoanIsGood,PaymentNumber,""), "") -> 5 | C14: =IFERROR(IF(LoanIsNotPaid*LoanIsGood,PaymentDate,""), "") -> 44046 | D14: =IFERROR(IF(LoanIsNotPaid*LoanIsGood,LoanValue,""), "") -> 1043860.3 | E14: =IFERROR(IF(LoanIsNotPaid*LoanIsGood,MonthlyPayment,""), "") -> 24230.062 | F14: =IFERROR(IF(LoanIsNotPaid*LoanIsGood,Principal,""), "") -> 9777.2075 | G14: =IFERROR(IF(LoanIsNotPaid*LoanIsGood,InterestAmt,""), "") -> 14452.855 | H14: =IFERROR(IF(LoanIsNotPaid*LoanIsGood,EndingBalance,""), "") -> 1034083.1
