Workbook

Sheet PREETI TO SADHANA
A1: Preeti Devaliya
A2: Loan to Sadhana Craft LLP
A3: Ledger Account
A4: 1-Mar-20 to 30-Nov-21
A5: Date | B5: Particulars | D5: Vch Type | E5: Vch No. | F5: Debit | G5: Credit
A6: 43920 | B6: To | C6: Hdfc Bank | D6: Payment | E6: 226 | F6: 500000 | G6: =+F6 -> 500000 | H6: =+F6+F7 -> 560000
A7: 44285 | B7: To | C7: Int From Parties | D7: Journal | E7: 1 | F7: 60000 | G7: =+G6+F7 -> 560000 | H7: =+H6*12% -> 67200
A8: 44650 | B8: To | C8: Int From Parties | D8: Journal | E8: 1 | F8: 67200 | G8: =+G7+F8 -> 627200 | H8: =+H7+H6 -> 627200
A9: 45015 | C9: Int From Parties | D9: Journal | F9: 75264 | G9: =+G8+F9 -> 702464 | H9: =+H8*12% -> 75264
A10: 45381 | C10: Int From Parties | D10: Journal | F10: =+H10*12% -> 84295.68 | G10: =+G9+F10 -> 786759.68 | H10: =+H9+H8 -> 702464
A11: 45746 | C11: Int From Parties | D11: Journal | F11: =+H11*12% -> 94411.162 | G11: =+G10+F11 -> 881170.84 | H11: =+H10+F10 -> 786759.68
A12: 46022 | C12: Int From Parties | D12: Journal | F12: 70808 | G12: =+G11+F12 -> 951978.84 | H12: =+H11*9% -> 70808.371
A13: =SUM(F6:F12) -> 951978.84
B14: By | C14: Closing Balance | G14: =A13-G13 -> 951978.84
A15: =G14 -> 951978.84 | G15: =G14 -> 951978.84
H67: ='RAHUL TO DHARMESHBHAI'!G46*9% -> 178391.25
A69: =G69 -> 6209925 | G69: ='RAHUL TO DHARMESHBHAI'!G46+'RAHUL TO DHARMESHBHAI'!G45 -> 6209925
D75: DHARMESH BHAI | E75: SADHANA CRAFT | G75: TOTAL
C76: RAHUL | D76: ='RAHUL TO DHARMESHBHAI'!G46 -> 1982125 | G76: =SUM(D76:F76) -> 1982125
C77: PREETI | E77: =G14 -> 951978.84 | G77: =SUM(E77:F77) -> 951978.84
C78: TOTAL | D78: =SUM(D76:D77) -> 1982125 | E78: =SUM(E76:E77) -> 951978.84 | F78: =SUM(F76:F77) -> 0 | G78: =SUM(G76:G77) -> 2934103.8
C80: ICICI BANK LOAN | G80: 3000000
C81: HDFC BANK LOAN | G81: 572300
C82: RAHUL FUND - BORROWED FROM SISTER | G82: 800000
C83: RAHUL OWN FUND | G83: =G78-G80-G81-G82 -> -1438196.2
G84: =SUM(G80:G83) -> 2934103.8

Sheet RAHUL FRIEND
A1: RAHUL FRIEND | C1: 44962 | D1: NET 3.80 GIVEN | F1: 500000
A2: RAHUL TO DHARMESH BHAI | C2: ADD: | D2: INT ( 05/02/24 TO 17/11/24) | F2: 90000
F3: =F1+F2 -> 590000
C4: 45613 | D4: REPAYMENT | E4: RECD | F4: 500000
E5: NET | F5: =F3-F4 -> 90000

Sheet RAHUL TO DHARMESHBHAI
A1: R R JETHWA & CO
A2: 11TH FLOOR,Remi Commercio
A3: Shah Industrial Estate,
A4: Andheri West.
A5: Dharmeshbhai
A6: Ledger Account
A7: 1-Apr-19 to 30-Nov-21
A8: Date | B8: Particulars | D8: Vch Type | E8: Vch No. | F8: Debit | G8: Credit
A9: 43585 | B9: To | C9: ICICI BANK | D9: Payment | E9: 28 | F9: 1000000 | M9: Value Date | N9: Transaction Remarks | O9: Withdrawal Amount (INR )
A10: 43832 | B10: To | C10: ICICI BANK | D10: Payment | E10: 200 | F10: 1500000 | M10: 43892 | N10: BIL/INFT/001934547748/Rahul/ | O10: 77800
A11: 43833 | B11: To | C11: ICICI BANK | D11: Payment | E11: 202 | F11: 500000 | M11: 44076 | N11: BIL/INFT/002065718878/Rahul Jethwa/ | O11: 100000
A12: 43843 | B12: To | C12: ICICI BANK | D12: Payment | E12: 208 | F12: 400000 | M12: 44109 | N12: BIL/INFT/002090705847/RAHUL emi oct 2/ | O12: 100000
A13: 43844 | B13: To | C13: Hdfc Bank-Saving | D13: Payment | E13: 214 | F13: 500000 | M13: 44110 | N13: BIL/INFT/002091694688/Rahul/ | O13: 22470
A14: 43847 | B14: To | C14: ICICI BANK | D14: Payment | E14: 215 | F14: 100000 | H14: =SUM(F9:F14) -> 4000000 | M14: 44134 | N14: BIL/INFT/002109006116/Rahul emi/ | O14: 100000
A15: 43892 | B15: By | C15: ICICI BANK | D15: Receipt | E15: 132 | G15: 77800 | H15: =SUM(F9:F14)-G15 -> 3922200 | M15: 44169 | N15: BIL/INFT/002136652303/Rahul emi/ | O15: 59800
A16: 43921 | B16: To | C16: Interest From Advance | D16: Journal | E16: 107 | F16: 194717 | H16: =H15+F16 -> 4116917 | M16: 44198 | N16: BIL/INFT/000010788111/Rahul emi/ | O16: 100000
A17: 44076 | B17: By | C17: ICICI BANK | D17: Receipt | E17: 67 | G17: 100000 | M17: 44231 | N17: BIL/INFT/000036528529/Rahul icici/ | O17: 100000
A18: 44109 | B18: By | C18: ICICI BANK | D18: Receipt | E18: 83 | G18: 100000 | M18: 44258 | N18: Dr Icici Bank | O18: 100000
A19: 44134 | B19: By | C19: ICICI BANK | D19: Receipt | E19: 96 | G19: 100000 | M19: 44474 | N19: BIL/INFT/000224846032/Rahul/ | O19: 100000
A20: 44198 | B20: By | C20: ICICI BANK | D20: Receipt | E20: 125 | G20: 100000 | M20: 44507 | N20: BIL/INFT/000250925208/Rahul emi/ | O20: 100000
A21: 44231 | B21: By | C21: ICICI BANK | D21: Receipt | E21: 140 | G21: 100000 | M21: 44747 | N21: BIL/INFT/000438006277/Rahul/ | O21: 50000
A22: 44258 | B22: By | C22: ICICI BANK | D22: Receipt | E22: 153 | G22: 100000 | H22: =H16-(SUM(G17:G22)) -> 3516917 | I22: =F23/H22 -> 0.1337791 | M22: 44750 | N22: BIL/INFT/000440358920/Rahul jj/ | O22: 50000
A23: 44286 | B23: To | C23: Interest From Advance | D23: Journal | E23: 65 | F23: 470490 | H23: =H22+F23 -> 3987407 | M23: 44779 | N23: Dr Icici Bank | O23: 50000
A24: 44474 | B24: By | C24: ICICI BANK | D24: Receipt | E24: 36 | G24: 100000 | M24: 44781 | N24: BIL/INFT/000463349518/Rahul icici/ | O24: 50000
A25: 44508 | B25: By | C25: ICICI BANK | D25: Receipt | E25: 41 | F25: BIL/INFT/000605996311/Rahul ICICI/ | G25: 100000 | H25: =H23-(SUM(G24:G25)) -> 3787407 | I25: =F26/H25 -> 0.12354178 | M25: 44849 | N25: BIL/INFT/000514817713/Rahul eemmii/ | O25: 100000
A26: 44651 | B26: To | C26: Interest From Advance | D26: Journal | E26: 65 | F26: 467903 | H26: =H25+F26 -> 4255310 | M26: 44875 | N26: BIL/INFT/000534394642/Rahul e/ | O26: 50000
A27: 44747 | B27: Dr | C27: ICICI BANK | D27: Receipt | E27: 41 | G27: 50000 | M27: 44905 | N27: BIL/INFT/000556119317/Rahul ICICI/ | O27: 50000
A28: 44750 | B28: Dr | C28: ICICI BANK | D28: Receipt | E28: 44 | G28: 50000 | M28: 44946 | N28: BIL/INFT/000585598595/Rahul/ | O28: 50000
A29: 44779 | B29: Dr | C29: ICICI BANK | D29: Receipt | E29: 66 | G29: 50000 | M29: 44974 | O29: 1000000
A30: 44781 | B30: Dr | C30: ICICI BANK | D30: Receipt | E30: 67 | G30: 50000 | M30: 44978 | N30: BIL/INFT/000608657090/Rahul jethwa/ | O30: 700000
A31: 44849 | B31: Dr | C31: ICICI BANK | D31: Receipt | E31: 100 | G31: 100000 | M31: 44979 | N31: BIL/INFT/000609080079/Rahul/ | O31: 1000000
A32: 44875 | B32: Dr | C32: ICICI BANK | D32: Receipt | E32: 113 | G32: 50000 | M32: 44979 | N32: BIL/INFT/000609091081/Rahul/ | O32: 200000
A33: 44905 | B33: Dr | C33: ICICI BANK | D33: Receipt | E33: 130 | G33: 50000 | M33: 45016 | N33: BIL/INFT/000636755599/Rahul return/ | O33: 150000
A34: 44946 | B34: Dr | C34: ICICI BANK | D34: Receipt | E34: 162 | G34: 50000 | I34: =SUM(G27:G34) -> 450000 | J34: =H26-I34 -> 3805310 | K34: =J34*9% -> 342477.9
A35: 44974 | B35: Dr | C35: ICICI BANK | D35: Receipt | E35: 185 | G35: 1000000 | J35: =J34+K34 -> 4147787.9
A36: 44978 | B36: Dr | C36: ICICI BANK | D36: Receipt | E36: 186 | G36: 700000
A37: 44979 | B37: Dr | C37: ICICI BANK | D37: Receipt | E37: 187 | G37: 1000000 | J37: =J35-(SUM(G35:G38)) -> 1247787.9 | K37: =J37*3% -> 37433.637
A38: 44979 | B38: Dr | C38: ICICI BANK | D38: Receipt | E38: 188 | G38: 200000 | H38: =H26-(SUM(G27:G38)) -> 905310 | I38: =F39/H38 -> 0.49159735 | J38: =J37+K37 -> 1285221.5
A39: 45016 | B39: Cr | C39: Interest From Advance | D39: Journal | E39: 24 | F39: 445048 | J39: =J38+K38 -> 1285221.5 | O39: =SUM(O10:O38) -> 4460070
A40: 45055 | B40: Dr | C40: ICICI BANK | D40: Payment | F40: 50000 | J40: =J39+F40 -> 1335221.5
...

Sheet SUMMARY
B1: DHARMESH BHAI | C1: SADHANA CRAFT | D1: Friend | E1: TOTAL
A2: RAHUL | B2: 1982125 | D2: =+'RAHUL FRIEND'!F5 -> 90000 | E2: =SUM(B2:D2) -> 2072125
A3: PREETI | C3: =+'PREETI TO SADHANA'!G14 -> 951978.84 | E3: =SUM(B3:D3) -> 951978.84
A4: TOTAL | B4: =SUM(B2:B3) -> 1982125 | C4: =SUM(C2:C3) -> 951978.84 | D4: =SUM(D2:D3) -> 90000 | E4: =SUM(E2:E3) -> 3024103.8
